Workbook
Name _ccVersion: 1.41
Name _HJAppendixVersion: 2
Name _kd01: #REF!
Name _kd02: #REF!
Name _kd03: #REF!
Name _kd04: #REF!
Name _kd05: #REF!
Name _kd06: #REF!
Name _kd07: #REF!
Name _kd08: #REF!
Name _kd09: #REF!
Name _kd10: #REF!
Name _kd11: #REF!
Name _kd12: #REF!
Name _kd13: #REF!
Name _kd14: #REF!
Name _kd15: #REF!
Name _kd16: #REF!
Name _kd17: #REF!
Name _kd18: #REF!
Name _kd19: #REF!
Name _kd20: #REF!
Name _kd21: #REF!
Name _kd22: #REF!
Name _kd23: #REF!
Name _kd24: #REF!
Name _kd25: #REF!
Name _Model_Path: "\\Ubsprod.msad.ubs.net\groupshares\GLOBAL\IB_RESEARCH_HKG\POWER\Models\Archives\Dongfang Electric Model 9.xlsx"
Name _pc01: #REF!
Name _pc02: #REF!
Name _pc03: #REF!
Name _pc04: #REF!
Name _pr05: #REF!
Name A: #REF!
Name AA: #REF!
Name aca: #REF!
Name acl: #REF!
Name ad00_: #REF!
Name ad01_: #REF!
Name ad02_: #REF!
Name ad03_: #REF!
Name ad04_: #REF!
Name ad05_: #REF!
Name ad06_: #REF!
Name ad07_: #REF!
Name ad08_: #REF!
Name ad09_: #REF!
Name Add__Cash: #REF!
Name Add__Listed_Investments: #REF!
Name Add__Other_Investments: #REF!
Name afa: #REF!
Name afc: #REF!
Name agd: #REF!
Name aie: #REF!
Name AK_ASAT: "F"
Name AK_BRKR: "XXX"
Name AK_CCY: "Raw"
Name AK_CDAT: "T-1WD"
Name AK_FDAT: "T-0Y-FWD"
Name AK_FSRC: "FX"

Sheet VA-Disclaimer

Sheet Fair Value - H
A2: P/E multiple valuation | D2: Forecast returns and rating | L2: 2025E | M2: 2026E | N2: 2027E | O2: 2028E | P2: 2029E
A3: Valuation date | B3: =+TODAY()
A4: 2027 forward target PE multiple | B4: 28 | D4: Current share price (HKD) | G4: 44.5 | K4: EPS | L4: =Model!U35 | M4: =Model!V35 | N4: =Model!W35 | O4: =Model!X35 | P4: =Model!Y35
A5: 2027E EPS (Rmb) | B5: =+Model!W35 | D5: Price target (HKD) | G5: =B10 | K5: BPS | L5: =Model!U37 | M5: =Model!V37 | N5: =Model!W37 | O5: =Model!X37 | P5: =Model!Y37
A6: Implied value per share (Rmb) | B6: =B4*B5 | D6: Upside/(Downside) | G6: =G5/G4-1 | K6: DPS | L6: =Model!U39 | M6: =Model!V39 | N6: =Model!W39 | O6: =Model!X39 | P6: =Model!Y39
A7: Roll forward at cost of equity | B7: =B6*(1+B16)^(((B3+365)-DATE(2026,12,31))/365) | D7: Forecast dividend yield | G7: =+Model!U39/G4
A8: Less: Dividends per share (Rmb) | B8: =-Model!V39*(((B3+365)-DATE(2026,12,31))/365) | D8: Market return assumption | G8: =5%+$B$13 | K8: P/E (current) | L8: =+$G$4/L4*$B$11 | M8: =+$G$4/M4*$B$11 | N8: =+$G$4/N4*$B$11 | O8: =+$G$4/O4*$B$11 | P8: =+$G$4/P4*$B$11
A9: Price target (Rmb) | B9: =SUM(B7:B8) | D9: Forecast excess return | G9: =G6+G7-G8 | K9: P/B (current) | L9: =+$G$4/L5*$B$11 | M9: =+$G$4/M5*$B$11 | N9: =+$G$4/N5*$B$11 | O9: =+$G$4/O5*$B$11 | P9: =+$G$4/P5*$B$11
A10: Price target (HKD) | B10: =ROUND(B9/B11,0) | D10: 12-month rating (UBS) | G10: =IF(G9>=6%, "BUY", IF(G9>=-6%,"NEUTRAL","SELL")) | K10: Dividend yield (current) | L10: =+L6/$G$4 | M10: =+M6/$G$4 | N10: =+N6/$G$4 | O10: =+O6/$G$4 | P10: =+P6/$G$4
A11: HKD/Rmb | B11: 0.91
A12: Valuation inputs | K12: P/E (Implied) | L12: =+$G$5/L4*$B$11 | M12: =+$G$5/M4*$B$11 | N12: =+$G$5/N4*$B$11 | O12: =+$G$5/O4*$B$11 | P12: =+$G$5/P4*$B$11
A13: Risk-free rate | B13: 0.035 | K13: P/B (Implied) | L13: =+$G$5/L5*$B$11 | M13: =+$G$5/M5*$B$11 | N13: =+$G$5/N5*$B$11 | O13: =+$G$5/O5*$B$11 | P13: =+$G$5/P5*$B$11
A14: Equity market risk premium | B14: 0.05
A15: Beta | B15: 0.49
A16: Cost of equity | B16: =B13+B14*B15
A18: UBSe 2026-29 EPS CAGR | B18: =+(Model!Y28/Model!V28)^(1/3)-1
A19: A/H discount | B19: 0

Sheet Fair Value - A
A2: P/E multiple valuation | D2: Forecast returns and rating | L2: 2025E | M2: 2026E | N2: 2027E | O2: 2028E | P2: 2029E
A3: Valuation date | B3: =+TODAY()
A4: 2027 forward target PE multiple | B4: 28 | D4: Current share price | G4: 42.21 | K4: EPS | L4: =Model!U35 | M4: =Model!V35 | N4: =Model!W35 | O4: =Model!X35 | P4: =Model!Y35
A5: 2027E EPS (Rmb) | B5: =+Model!W35 | D5: Price target (Rmb) | G5: =+B9 | K5: BPS | L5: =Model!U37 | M5: =Model!V37 | N5: =Model!W37 | O5: =Model!X37 | P5: =Model!Y37
A6: Implied value per share (Rmb) | B6: =B4*B5 | D6: Upside/(Downside) | G6: =G5/G4-1 | K6: DPS | L6: =Model!U39 | M6: =Model!V39 | N6: =Model!W39 | O6: =Model!X39 | P6: =Model!Y39
A7: Roll forward at cost of equity | B7: =B6*(1+B15)^(((B3+365)-DATE(2026,12,31))/365) | D7: Forecast dividend yield | G7: =+Model!U39/G4
A8: Less: Dividends per share (Rmb) | B8: =-Model!V39*(((B3+365)-DATE(2026,12,31))/365) | D8: Market return assumption | G8: =5%+$B$12 | K8: P/E (current) | L8: =+$G$4/L4 | M8: =+$G$4/M4 | N8: =+$G$4/N4 | O8: =+$G$4/O4 | P8: =+$G$4/P4
A9: Price target (Rmb) | B9: =ROUND(SUM(B7:B8),0) | D9: Forecast excess return | G9: =G6+G7-G8 | K9: P/B (current) | L9: =+$G$4/L5 | M9: =+$G$4/M5 | N9: =+$G$4/N5 | O9: =+$G$4/O5 | P9: =+$G$4/P5
D10: 12-month rating (UBS) | G10: =IF(G9>=6%, "BUY", IF(G9>=-6%,"NEUTRAL","SELL")) | K10: Dividend yield (current) | L10: =+L6/$G$4 | M10: =+M6/$G$4 | N10: =+N6/$G$4 | O10: =+O6/$G$4 | P10: =+P6/$G$4
A11: Valuation inputs
A12: Risk-free rate | B12: 0.018 | K12: P/E (Implied) | L12: =+$G$5/L4 | M12: =+$G$5/M4 | N12: =+$G$5/N4 | O12: =+$G$5/O4 | P12: =+$G$5/P4
A13: Equity market risk premium | B13: 0.05 | K13: P/B (Implied) | L13: =+$G$5/L5 | M13: =+$G$5/M5 | N13: =+$G$5/N5 | O13: =+$G$5/O5 | P13: =+$G$5/P5
A14: Beta | B14: 1.02
A15: Cost of equity | B15: =B12+B13*B14
A17: UBSe 2020-24 EPS CAGR | B17: =+(Model!T28/Model!P28)^(1/4)-1
A18: UBSe 2024-29 EPS CAGR | B18: =+(Model!Y28/Model!T28)^(1/5)-1
A19: UBSe 2025-27 EPS CAGR | B19: =+(Model!W28/Model!U28)^(1/2)-1
A20: UBSe 2025-28 EPS CAGR | B20: =+(Model!X28/Model!U28)^(1/3)-1
A21: UBSe 2026-29 EPS CAGR | B21: =+(Model!Y28/Model!V28)^(1/3)-1

Sheet Model
A1: Rmb m | BU1: H225
B2: 2006 | C2: 2007 | D2: 2008 | E2: 2009 | F2: 2010 | G2: 2011 | H2: 2012 | I2: 2013 | J2: 2014 | K2: 2015 | L2: 2016 | M2: 2017 | N2: 2018 | O2: 2019 | P2: 2020 | Q2: =P2+1 | R2: =Q2+1 | S2: =R2+1 | T2: =S2+1 | U2: =T2+1 | V2: =U2+1 | W2: =V2+1 | X2: =W2+1 | ... Z2: =Y2+1 | AA2: Change | AB2: Change % | AC2: 2025E | AD2: Difference | AE2: Diff % | AG2: H106 | AH2: H206 | AI2: H107 | AJ2: H207 | AK2: H108 | AL2: H208 | AM2: H109 | AN2: H209 | AO2: H110 | AP2: H210 | AQ2: H111 | AR2: H211 | AS2: H112 | AT2: H212 | AU2: H113 | AV2: H213 | AW2: H114 | AX2: H214 | AY2: H115 | AZ2: H215 | BA2: H116 | BB2: H216 | BC2: H117 | BD2: H217 | BE2: H118 | BF2: H218 | BG2: H119 | BH2: H219 | BI2: H120 | BJ2: H220 | BK2: H121 | BL2: H221 | BM2: H122 | BN2: H222 | BO2: H123 | BP2: H223 | BQ2: H124 | BR2: H224 | BS2: H125 | BT2: H225E | BU2: Change | BV2: Change % | BW2: % of last year | BX2: % of FY | BZ2: Q106 | CA2: Q206 | CB2: Q306 | CC2: Q406 | CD2: Q107 | CE2: Q207 | CF2: Q307 | CG2: Q407 | CH2: Q108 | CI2: Q208 | CJ2: Q308 | CK2: Q408 | CL2: Q109 | CM2: Q209 | CN2: Q309 | CO2: Q409 | CP2: Q110 | CQ2: Q210 | CR2: Q310 | CS2: Q410 | CT2: Q111 | CU2: Q211 | CV2: Q311 | CW2: Q411 | CX2: Q112 | CY2: Q212 | CZ2: Q312 | DA2: Q412 | DB2: Q113 | DC2: Q213 | DD2: Q313 | DE2: Q413 | DF2: Q114 | DG2: Q214 | DH2: Q314 | DI2: Q414 | DJ2: Q115 | DK2: Q215 | DL2: Q315 | DM2: Q415 | DN2: Q116 | DO2: Q216 | DP2: Q316 | DQ2: Q416 | DR2: Q117 | DS2: Q217 | DT2: Q317 | DU2: Q417 | DV2: Q118 | DW2: Q218 | DX2: Q318 | DY2: Q418 | DZ2: Q119 | EA2: Q219 | EB2: Q319 | EC2: Q419 | ED2: Q120 | EE2: Q220 | EF2: Q320 | EG2: Q420 | EH2: Q121 | EI2: Q221 | EJ2: Q321 | EK2: Q421 | EL2: Q122 | EM2: Q222 | EN2: Q322 | EO2: Q422 | EP2: Q123 | EQ2: Q223 | ER2: Q323 | ES2: Q423 | ET2: Q124 | EU2: Q224 | EV2: Q324 | EW2: Q424 | EX2: Q125 | EY2: Q225 | EZ2: Q325 | FA2: Q425 | FB2: Change | FC2: Change % | FD2: % of FY24 | FE2: % of FY25
A3: P&L
A4: Revenue | B4: ='Raw financials'!B4 | C4: ='Raw financials'!C4 | D4: ='Raw financials'!D4 | E4: ='Raw financials'!E4 | F4: ='Raw financials'!F4 | G4: ='Raw financials'!G4 | H4: ='Raw financials'!H4 | I4: ='Raw financials'!I4 | ... T4: ='Raw financials'!T4 | U4: =Driver!J14 | V4: =Driver!K14 | W4: =Driver!L14 | X4: =Driver!M14 | Y4: =Driver!N14 | Z4: =Driver!O14 | AA4: =+U4-T4 | AB4: =+AA4/T4 | AC4: 81355.398 | AD4: =+U4-AC4 | AE4: =+AD4/AC4 | AG4: ='Raw financials'!AA4 | AH4: =B4-AG4 | AI4: ='Raw financials'!AB4 | AJ4: =C4-AI4 | AK4: ='Raw financials'!AC4 | AL4: =D4-AK4 | AM4: ='Raw financials'!AD4 | AN4: =E4-AM4 | AO4: ='Raw financials'!AE4 | AP4: =F4-AO4 | AQ4: ='Raw financials'!AF4 | AR4: =G4-AQ4 | AS4: ='Raw financials'!AG4 | AT4: =H4-AS4 | AU4: ='Raw financials'!AH4 | AV4: =I4-AU4 | AW4: ='Raw financials'!AI4 | AX4: =J4-AW4 | AY4: ='Raw financials'!AJ4 | AZ4: =K4-AY4 | BA4: ='Raw financials'!AK4 | BB4: =L4-BA4 | BC4: ='Raw financials'!AL4 | BD4: =M4-BC4 | BE4: ='Raw financials'!AM4 | BF4: =N4-BE4 | BG4: ='Raw financials'!AN4 | BH4: =O4-BG4 | BI4: ='Raw financials'!AO4 | BJ4: =P4-BI4 | BK4: ='Raw financials'!AP4 | BL4: =Q4-BK4 | BM4: ='Raw financials'!AQ4 | BN4: =R4-BM4 | BO4: ='Raw financials'!AR4 | BP4: =S4-BO4 | BQ4: ='Raw financials'!AS4 | BR4: =T4-BQ4 | BT4: =U4-BS4 | BU4: =BT4-BR4 | BV4: =BU4/BR4 | BW4: =BT4/T4 | BX4: =BT4/U4 | BZ4: ='Raw financials'!BN4 | CA4: ='Raw financials'!BO4 | CB4: ='Raw financials'!BP4 | CC4: ='Raw financials'!BQ4 | CD4: ='Raw financials'!BR4 | CE4: ='Raw financials'!BS4 | CF4: ='Raw financials'!BT4 | CG4: ='Raw financials'!BU4 | ... EY4: ='Raw financials'!EM4 | FB4: =+FA4-EW4 | FC4: =+FB4/EW4 | FD4: =+FA4/T4 | FE4: =+FA4/U4
A5: YoY | D5: =D4/C4-1 | E5: =E4/D4-1 | F5: =F4/E4-1 | G5: =G4/F4-1 | H5: =H4/G4-1 | I5: =I4/H4-1 | J5: =J4/I4-1 | K5: =K4/J4-1 | ... Z5: =Z4/Y4-1 | BM5: =BM4/BK4-1 | BN5: =BN4/BL4-1 | BO5: =BO4/BM4-1 | BP5: =BP4/BN4-1 | BQ5: =BQ4/BO4-1 | BR5: =BR4/BP4-1 | BT5: =BT4/BR4-1 | EX5: =EX4/ET4-1 | EY5: =EY4/EU4-1
A6: COGS | B6: =-'Raw financials'!B8 | C6: =-'Raw financials'!C8 | D6: =-'Raw financials'!D8 | E6: =-'Raw financials'!E8 | F6: =-'Raw financials'!F8 | G6: =-'Raw financials'!G8 | H6: =-'Raw financials'!H8 | I6: =-'Raw financials'!I8 | ... T6: =-'Raw financials'!T8 | U6: =Driver!J47 | V6: =Driver!K47 | W6: =Driver!L47 | X6: =Driver!M47 | Y6: =Driver!N47 | Z6: =Driver!O47 | AA6: =+U6-T6 | AB6: =+AA6/T6 | AC6: -68165.604 | AD6: =+U6-AC6 | AE6: =+AD6/AC6 | AG6: =-'Raw financials'!AA8 | AH6: =B6-AG6 | AI6: =-'Raw financials'!AB8 | AJ6: =C6-AI6 | AK6: =-'Raw financials'!AC8 | AL6: =D6-AK6 | AM6: =-'Raw financials'!AD8 | AN6: =E6-AM6 | AO6: =-'Raw financials'!AE8 | AP6: =F6-AO6 | AQ6: =-'Raw financials'!AF8 | AR6: =G6-AQ6 | AS6: =-'Raw financials'!AG8 | AT6: =H6-AS6 | AU6: =-'Raw financials'!AH8 | AV6: =I6-AU6 | AW6: =-'Raw financials'!AI8 | AX6: =J6-AW6 | AY6: =-'Raw financials'!AJ8 | AZ6: =K6-AY6 | BA6: =-'Raw financials'!AK8 | BB6: =L6-BA6 | BC6: =-'Raw financials'!AL8 | BD6: =M6-BC6 | BE6: =-'Raw financials'!AM8 | BF6: =N6-BE6 | BG6: =-'Raw financials'!AN8 | BH6: =O6-BG6 | BI6: =-'Raw financials'!AO8 | BJ6: =P6-BI6 | BK6: =-'Raw financials'!AP8 | BL6: =Q6-BK6 | BM6: =-'Raw financials'!AQ8 | BN6: =R6-BM6 | BO6: =-'Raw financials'!AR8 | BP6: =S6-BO6 | BQ6: =-'Raw financials'!AS8 | BR6: =T6-BQ6 | BT6: =U6-BS6 | BU6: =BT6-BR6 | BV6: =BU6/BR6 | BW6: =BT6/T6 | BX6: =BT6/U6 | BZ6: =-'Raw financials'!BN8 | CA6: =-'Raw financials'!BO8 | CB6: =-'Raw financials'!BP8 | CC6: =-'Raw financials'!BQ8 | CD6: =-'Raw financials'!BR8 | CE6: =-'Raw financials'!BS8 | CF6: =-'Raw financials'!BT8 | CG6: =-'Raw financials'!BU8 | ... EY6: =-'Raw financials'!EM8 | FB6: =+FA6-EW6 | FC6: =+FB6/EW6 | FD6: =+FA6/T6 | FE6: =+FA6/U6
A7: Gross Profit | B7: =B4+B6 | C7: =C4+C6 | D7: =D4+D6 | E7: =E4+E6 | F7: =F4+F6 | G7: =G4+G6 | H7: =H4+H6 | I7: =I4+I6 | ... Z7: =Z4+Z6 | AA7: =+U7-T7 | AB7: =+AA7/T7 | AC7: 13189.794 | AD7: =+U7-AC7 | AE7: =+AD7/AC7 | AG7: =AG4+AG6 | AH7: =AH4+AH6 | AI7: =AI4+AI6 | AJ7: =AJ4+AJ6 | AK7: =AK4+AK6 | AL7: =AL4+AL6 | AM7: =AM4+AM6 | AN7: =AN4+AN6 | ... BR7: =BR4+BR6 | BT7: =BT4+BT6 | BU7: =BT7-BR7 | BV7: =BU7/BR7 | BW7: =BT7/T7 | BX7: =BT7/U7 | BZ7: =BZ4+BZ6 | CA7: =CA4+CA6 | CB7: =CB4+CB6 | CC7: =CC4+CC6 | CD7: =CD4+CD6 | CE7: =CE4+CE6 | CF7: =CF4+CF6 | CG7: =CG4+CG6 | ... EY7: =EY4+EY6 | FB7: =+FA7-EW7 | FC7: =+FB7/EW7 | FD7: =+FA7/T7 | FE7: =+FA7/U7
A8: GPM | B8: =B7/B4 | C8: =C7/C4 | D8: =D7/D4 | E8: =E7/E4 | F8: =F7/F4 | G8: =G7/G4 | H8: =H7/H4 | I8: =I7/I4 | ... Z8: =Z7/Z4 | AG8: =AG7/AG4 | AH8: =AH7/AH4 | AI8: =AI7/AI4 | AJ8: =AJ7/AJ4 | AK8: =AK7/AK4 | AL8: =AL7/AL4 | AM8: =AM7/AM4 | AN8: =AN7/AN4 | ... BR8: =BR7/BR4 | BT8: =BT7/BT4 | BU8: =BT8-BR8 | BV8: =BU8/BR8 | BW8: =BT8/T8 | BX8: =BT8/U8 | BZ8: =BZ7/BZ4 | CA8: =CA7/CA4 | CB8: =CB7/CB4 | CC8: =CC7/CC4 | CD8: =CD7/CD4 | CE8: =CE7/CE4 | CF8: =CF7/CF4 | CG8: =CG7/CG4 | ... EY8: =EY7/EY4
A9: Business tax | B9: =-'Raw financials'!B9 | C9: =-'Raw financials'!C9 | D9: =-'Raw financials'!D9 | E9: =-'Raw financials'!E9 | F9: =-'Raw financials'!F9 | G9: =-'Raw financials'!G9 | H9: =-'Raw financials'!H9 | I9: =-'Raw financials'!I9 | ... T9: =-'Raw financials'!T9 | U9: =T9/T4*U4 | V9: =U9/U4*V4 | W9: =V9/V4*W4 | X9: =W9/W4*X4 | Y9: =X9/X4*Y4 | Z9: =Y9/Y4*Z4 | AA9: =+U9-T9 | AB9: =+AA9/T9 | AC9: -441.85949 | AD9: =+U9-AC9 | AE9: =+AD9/AC9 | AG9: =-'Raw financials'!AA9 | AH9: =B9-AG9 | AI9: =-'Raw financials'!AB9 | AJ9: =C9-AI9 | AK9: =-'Raw financials'!AC9 | AL9: =D9-AK9 | AM9: =-'Raw financials'!AD9 | AN9: =E9-AM9 | AO9: =-'Raw financials'!AE9 | AP9: =F9-AO9 | AQ9: =-'Raw financials'!AF9 | AR9: =G9-AQ9 | AS9: =-'Raw financials'!AG9 | AT9: =H9-AS9 | AU9: =-'Raw financials'!AH9 | AV9: =I9-AU9 | AW9: =-'Raw financials'!AI9 | AX9: =J9-AW9 | AY9: =-'Raw financials'!AJ9 | AZ9: =K9-AY9 | BA9: =-'Raw financials'!AK9 | BB9: =L9-BA9 | BC9: =-'Raw financials'!AL9 | BD9: =M9-BC9 | BE9: =-'Raw financials'!AM9 | BF9: =N9-BE9 | BG9: =-'Raw financials'!AN9 | BH9: =O9-BG9 | BI9: =-'Raw financials'!AO9 | BJ9: =P9-BI9 | BK9: =-'Raw financials'!AP9 | BL9: =Q9-BK9 | BM9: =-'Raw financials'!AQ9 | BN9: =R9-BM9 | BO9: =-'Raw financials'!AR9 | BP9: =S9-BO9 | BQ9: =-'Raw financials'!AS9 | BR9: =T9-BQ9 | BT9: =U9-BS9 | BU9: =BT9-BR9 | BV9: =BU9/BR9 | BW9: =BT9/T9 | BX9: =BT9/U9 | BZ9: =-'Raw financials'!BN9 | CA9: =-'Raw financials'!BO9 | CB9: =-'Raw financials'!BP9 | CC9: =-'Raw financials'!BQ9 | CD9: =-'Raw financials'!BR9 | CE9: =-'Raw financials'!BS9 | CF9: =-'Raw financials'!BT9 | CG9: =-'Raw financials'!BU9 | ... EY9: =-'Raw financials'!EM9 | FB9: =+FA9-EW9 | FC9: =+FB9/EW9 | FD9: =+FA9/T9 | FE9: =+FA9/U9
A10: Selling expense | B10: =-'Raw financials'!B10 | C10: =-'Raw financials'!C10 | D10: =-'Raw financials'!D10 | E10: =-'Raw financials'!E10 | F10: =-'Raw financials'!F10 | G10: =-'Raw financials'!G10 | H10: =-'Raw financials'!H10 | I10: =-'Raw financials'!I10 | ... T10: =-'Raw financials'!T10 | U10: =T10/T4*U4 | V10: =U10/U4*V4 | W10: =V10/V4*W4 | X10: =W10/W4*X4 | Y10: =X10/X4*Y4 | Z10: =Y10/Y4*Z4 | AA10: =+U10-T10 | AB10: =+AA10/T10 | AC10: -959.94391 | AD10: =+U10-AC10 | AE10: =+AD10/AC10 | AG10: =-'Raw financials'!AA10 | AH10: =B10-AG10 | AI10: =-'Raw financials'!AB10 | AJ10: =C10-AI10 | AK10: =-'Raw financials'!AC10 | AL10: =D10-AK10 | AM10: =-'Raw financials'!AD10 | AN10: =E10-AM10 | AO10: =-'Raw financials'!AE10 | AP10: =F10-AO10 | AQ10: =-'Raw financials'!AF10 | AR10: =G10-AQ10 | AS10: =-'Raw financials'!AG10 | AT10: =H10-AS10 | AU10: =-'Raw financials'!AH10 | AV10: =I10-AU10 | AW10: =-'Raw financials'!AI10 | AX10: =J10-AW10 | AY10: =-'Raw financials'!AJ10 | AZ10: =K10-AY10 | BA10: =-'Raw financials'!AK10 | BB10: =L10-BA10 | BC10: =-'Raw financials'!AL10 | BD10: =M10-BC10 | BE10: =-'Raw financials'!AM10 | BF10: =N10-BE10 | BG10: =-'Raw financials'!AN10 | BH10: =O10-BG10 | BI10: =-'Raw financials'!AO10 | BJ10: =P10-BI10 | BK10: =-'Raw financials'!AP10 | BL10: =Q10-BK10 | BM10: =-'Raw financials'!AQ10 | BN10: =R10-BM10 | BO10: =-'Raw financials'!AR10 | BP10: =S10-BO10 | BQ10: =-'Raw financials'!AS10 | BR10: =T10-BQ10 | BT10: =U10-BS10 | BU10: =BT10-BR10 | BV10: =BU10/BR10 | BW10: =BT10/T10 | BX10: =BT10/U10 | BZ10: =-'Raw financials'!BN10 | CA10: =-'Raw financials'!BO10 | CB10: =-'Raw financials'!BP10 | CC10: =-'Raw financials'!BQ10 | CD10: =-'Raw financials'!BR10 | CE10: =-'Raw financials'!BS10 | CF10: =-'Raw financials'!BT10 | CG10: =-'Raw financials'!BU10 | ... EY10: =-'Raw financials'!EM10 | FB10: =+FA10-EW10 | FC10: =+FB10/EW10 | FD10: =+FA10/T10 | FE10: =+FA10/U10
A11: Administrative & R&D expenses | B11: =B12+B13 | C11: =C12+C13 | D11: =D12+D13 | E11: =E12+E13 | F11: =F12+F13 | G11: =G12+G13 | H11: =H12+H13 | I11: =I12+I13 | ... T11: =T12+T13 | U11: =-U4*U14-U10 | V11: =-V4*V14-V10 | W11: =-W4*W14-W10 | X11: =-X4*X14-X10 | Y11: =-Y4*Y14-Y10 | Z11: =-Z4*Z14-Z10 | AA11: =+U11-T11 | AB11: =+AA11/T11 | AC11: -7624.8981 | AD11: =+U11-AC11 | AE11: =+AD11/AC11 | AG11: =AG12+AG13 | AH11: =B11-AG11 | AI11: =AI12+AI13 | AJ11: =C11-AI11 | AK11: =AK12+AK13 | AL11: =D11-AK11 | AM11: =AM12+AM13 | AN11: =E11-AM11 | AO11: =AO12+AO13 | AP11: =F11-AO11 | AQ11: =AQ12+AQ13 | AR11: =G11-AQ11 | AS11: =AS12+AS13 | AT11: =H11-AS11 | AU11: =AU12+AU13 | AV11: =I11-AU11 | AW11: =AW12+AW13 | AX11: =J11-AW11 | AY11: =AY12+AY13 | AZ11: =K11-AY11 | BA11: =BA12+BA13 | BB11: =L11-BA11 | BC11: =BC12+BC13 | BD11: =M11-BC11 | BE11: =BE12+BE13 | BF11: =N11-BE11 | BG11: =BG12+BG13 | BH11: =O11-BG11 | BI11: =BI12+BI13 | BJ11: =P11-BI11 | BK11: =BK12+BK13 | BL11: =Q11-BK11 | BM11: =BM12+BM13 | BN11: =R11-BM11 | BO11: =BO12+BO13 | BP11: =S11-BO11 | BQ11: =BQ12+BQ13 | BR11: =T11-BQ11 | BT11: =U11-BS11 | BU11: =BT11-BR11 | BV11: =BU11/BR11 | BW11: =BT11/T11 | BX11: =BT11/U11 | BZ11: =BZ12+BZ13 | CA11: =CA12+CA13 | CB11: =CB12+CB13 | CC11: =CC12+CC13 | CD11: =CD12+CD13 | CE11: =CE12+CE13 | CF11: =CF12+CF13 | CG11: =CG12+CG13 | ... EY11: =EY12+EY13 | FB11: =+FA11-EW11 | FC11: =+FB11/EW11 | FD11: =+FA11/T11 | FE11: =+FA11/U11
A12: Admin expense | B12: =-'Raw financials'!B11 | C12: =-'Raw financials'!C11 | D12: =-'Raw financials'!D11 | E12: =-'Raw financials'!E11 | F12: =-'Raw financials'!F11 | G12: =-'Raw financials'!G11 | H12: =-'Raw financials'!H11 | I12: =-'Raw financials'!I11 | ... T12: =-'Raw financials'!T11 | AA12: =+U12-T12 | AB12: =+AA12/T12 | AD12: =+U12-AC12 | AE12: =+AD12/AC12 | AG12: =-'Raw financials'!AA11 | AI12: =-'Raw financials'!AB11 | AK12: =-'Raw financials'!AC11 | AM12: =-'Raw financials'!AD11 | AO12: =-'Raw financials'!AE11 | AQ12: =-'Raw financials'!AF11 | AS12: =-'Raw financials'!AG11 | AU12: =-'Raw financials'!AH11 | AW12: =-'Raw financials'!AI11 | AY12: =-'Raw financials'!AJ11 | BA12: =-'Raw financials'!AK11 | BC12: =-'Raw financials'!AL11 | BE12: =-'Raw financials'!AM11 | BG12: =-'Raw financials'!AN11 | BI12: =-'Raw financials'!AO11 | BK12: =-'Raw financials'!AP11 | BM12: =-'Raw financials'!AQ11 | BO12: =-'Raw financials'!AR11 | BQ12: =-'Raw financials'!AS11 | BU12: =BT12-BR12 | BV12: =BU12/BR12 | BW12: =BT12/T12 | BX12: =BT12/U12 | BZ12: =-'Raw financials'!BN11 | CA12: =-'Raw financials'!BO11 | CB12: =-'Raw financials'!BP11 | CC12: =-'Raw financials'!BQ11 | CD12: =-'Raw financials'!BR11 | CE12: =-'Raw financials'!BS11 | CF12: =-'Raw financials'!BT11 | CG12: =-'Raw financials'!BU11 | ... EY12: =-'Raw financials'!EM11 | FB12: =+FA12-EW12 | FC12: =+FB12/EW12 | FD12: =+FA12/T12 | FE12: =+FA12/U12
A13: R&D expense | B13: =-'Raw financials'!B12 | C13: =-'Raw financials'!C12 | D13: =-'Raw financials'!D12 | E13: =-'Raw financials'!E12 | F13: =-'Raw financials'!F12 | G13: =-'Raw financials'!G12 | H13: =-'Raw financials'!H12 | I13: =-'Raw financials'!I12 | ... T13: =-'Raw financials'!T12 | AA13: =+U13-T13 | AB13: =+AA13/T13 | AD13: =+U13-AC13 | AE13: =+AD13/AC13 | AG13: =-'Raw financials'!AA12 | AI13: =-'Raw financials'!AB12 | AK13: =-'Raw financials'!AC12 | AM13: =-'Raw financials'!AD12 | AO13: =-'Raw financials'!AE12 | AQ13: =-'Raw financials'!AF12 | AS13: =-'Raw financials'!AG12 | AU13: =-'Raw financials'!AH12 | AW13: =-'Raw financials'!AI12 | AY13: =-'Raw financials'!AJ12 | BA13: =-'Raw financials'!AK12 | BC13: =-'Raw financials'!AL12 | BE13: =-'Raw financials'!AM12 | BG13: =-'Raw financials'!AN12 | BI13: =-'Raw financials'!AO12 | BK13: =-'Raw financials'!AP12 | BM13: =-'Raw financials'!AQ12 | BO13: =-'Raw financials'!AR12 | BQ13: =-'Raw financials'!AS12 | BU13: =BT13-BR13 | BV13: =BU13/BR13 | BW13: =BT13/T13 | BX13: =BT13/U13 | BZ13: =-'Raw financials'!BN12 | CA13: =-'Raw financials'!BO12 | CB13: =-'Raw financials'!BP12 | CC13: =-'Raw financials'!BQ12 | CD13: =-'Raw financials'!BR12 | CE13: =-'Raw financials'!BS12 | CF13: =-'Raw financials'!BT12 | CG13: =-'Raw financials'!BU12 | ... EY13: =-'Raw financials'!EM12 | FB13: =+FA13-EW13 | FC13: =+FB13/EW13 | FD13: =+FA13/T13 | FE13: =+FA13/U13
A14: SGA as % of revenue | B14: =-(B11+B10)/B4 | C14: =-(C11+C10)/C4 | D14: =-(D11+D10)/D4 | E14: =-(E11+E10)/E4 | F14: =-(F11+F10)/F4 | G14: =-(G11+G10)/G4 | H14: =-(H11+H10)/H4 | I14: =-(I11+I10)/I4 | ... T14: =-(T11+T10)/T4 | U14: =T14 | V14: =U14 | W14: =V14 | X14: =W14 | Y14: =X14 | Z14: =Y14 | AG14: =-(AG11+AG10)/AG4 | AH14: =-(AH11+AH10)/AH4 | AI14: =-(AI11+AI10)/AI4 | AJ14: =-(AJ11+AJ10)/AJ4 | AK14: =-(AK11+AK10)/AK4 | AL14: =-(AL11+AL10)/AL4 | AM14: =-(AM11+AM10)/AM4 | AN14: =-(AN11+AN10)/AN4 | ... BR14: =-(BR11+BR10)/BR4 | BT14: =-(BT11+BT10)/BT4 | BU14: =BT14-BR14 | BV14: =BU14/BR14 | BW14: =BT14/T14 | BX14: =BT14/U14 | BZ14: =-(BZ11+BZ10)/BZ4 | CA14: =-(CA11+CA10)/CA4 | CB14: =-(CB11+CB10)/CB4 | CC14: =-(CC11+CC10)/CC4 | CD14: =-(CD11+CD10)/CD4 | CE14: =-(CE11+CE10)/CE4 | CF14: =-(CF11+CF10)/CF4 | CG14: =-(CG11+CG10)/CG4 | ... EY14: =-(EY11+EY10)/EY4
A15: EBIT | B15: =B7+B10+B11+B9 | C15: =C7+C10+C11+C9 | D15: =D7+D10+D11+D9 | E15: =E7+E10+E11+E9 | F15: =F7+F10+F11+F9 | G15: =G7+G10+G11+G9 | H15: =H7+H10+H11+H9 | I15: =I7+I10+I11+I9 | ... Z15: =Z7+Z10+Z11+Z9 | AA15: =+U15-T15 | AB15: =+AA15/T15 | AC15: 4163.0923 | AD15: =+U15-AC15 | AE15: =+AD15/AC15 | AG15: =AG7+AG10+AG11+AG9 | AH15: =AH7+AH10+AH11+AH9 | AI15: =AI7+AI10+AI11+AI9 | AJ15: =AJ7+AJ10+AJ11+AJ9 | AK15: =AK7+AK10+AK11+AK9 | AL15: =AL7+AL10+AL11+AL9 | AM15: =AM7+AM10+AM11+AM9 | AN15: =AN7+AN10+AN11+AN9 | ... BR15: =BR7+BR10+BR11+BR9 | BT15: =BT7+BT10+BT11+BT9 | BU15: =BT15-BR15 | BV15: =BU15/BR15 | BW15: =BT15/T15 | BX15: =BT15/U15 | BZ15: =BZ7+BZ10+BZ11+BZ9 | CA15: =CA7+CA10+CA11+CA9 | CB15: =CB7+CB10+CB11+CB9 | CC15: =CC7+CC10+CC11+CC9 | CD15: =CD7+CD10+CD11+CD9 | CE15: =CE7+CE10+CE11+CE9 | CF15: =CF7+CF10+CF11+CF9 | CG15: =CG7+CG10+CG11+CG9 | ... EY15: =EY7+EY10+EY11+EY9 | FB15: =+FA15-EW15 | FC15: =+FB15/EW15 | FD15: =+FA15/T15 | FE15: =+FA15/U15
A16: EBIT margin | B16: =B15/B4 | C16: =C15/C4 | D16: =D15/D4 | E16: =E15/E4 | F16: =F15/F4 | G16: =G15/G4 | H16: =H15/H4 | I16: =I15/I4 | ... Z16: =Z15/Z4 | AG16: =AG15/AG4 | AH16: =AH15/AH4 | AI16: =AI15/AI4 | AJ16: =AJ15/AJ4 | AK16: =AK15/AK4 | AL16: =AL15/AL4 | AM16: =AM15/AM4 | AN16: =AN15/AN4 | ... BR16: =BR15/BR4 | BT16: =BT15/BT4 | BU16: =BT16-BR16 | BV16: =BU16/BR16 | BW16: =BT16/T16 | BX16: =BT16/U16 | BZ16: =BZ15/BZ4 | CA16: =CA15/CA4 | CB16: =CB15/CB4 | CC16: =CC15/CC4 | CD16: =CD15/CD4 | CE16: =CE15/CE4 | CF16: =CF15/CF4 | CG16: =CG15/CG4 | ... EY16: =EY15/EY4
A17: Finance gain (cost) | B17: =-'Raw financials'!B13 | C17: =-'Raw financials'!C13 | D17: =-'Raw financials'!D13 | E17: =-'Raw financials'!E13 | F17: =-'Raw financials'!F13 | G17: =-'Raw financials'!G13 | H17: =-'Raw financials'!H13 | I17: =-'Raw financials'!I13 | ... T17: =-'Raw financials'!T13 | U17: =Driver!J138 | V17: =Driver!K138 | W17: =Driver!L138 | X17: =Driver!M138 | Y17: =Driver!N138 | Z17: =Driver!O138 | AA17: =+U17-T17 | AB17: =+AA17/T17 | AC17: -28.840856 | AD17: =+U17-AC17 | AE17: =+AD17/AC17 | AG17: =-'Raw financials'!AA13 | AH17: =B17-AG17 | AI17: =-'Raw financials'!AB13 | AJ17: =C17-AI17 | AK17: =-'Raw financials'!AC13 | AL17: =D17-AK17 | AM17: =-'Raw financials'!AD13 | AN17: =E17-AM17 | AO17: =-'Raw financials'!AE13 | AP17: =F17-AO17 | AQ17: =-'Raw financials'!AF13 | AR17: =G17-AQ17 | AS17: =-'Raw financials'!AG13 | AT17: =H17-AS17 | AU17: =-'Raw financials'!AH13 | AV17: =I17-AU17 | AW17: =-'Raw financials'!AI13 | AX17: =J17-AW17 | AY17: =-'Raw financials'!AJ13 | AZ17: =K17-AY17 | BA17: =-'Raw financials'!AK13 | BB17: =L17-BA17 | BC17: =-'Raw financials'!AL13 | BD17: =M17-BC17 | BE17: =-'Raw financials'!AM13 | BF17: =N17-BE17 | BG17: =-'Raw financials'!AN13 | BH17: =O17-BG17 | BI17: =-'Raw financials'!AO13 | BJ17: =P17-BI17 | BK17: =-'Raw financials'!AP13 | BL17: =Q17-BK17 | BM17: =-'Raw financials'!AQ13 | BN17: =R17-BM17 | BO17: =-'Raw financials'!AR13 | BP17: =S17-BO17 | BQ17: =-'Raw financials'!AS13 | BR17: =T17-BQ17 | BT17: =U17-BS17 | BU17: =BT17-BR17 | BV17: =BU17/BR17 | BW17: =BT17/T17 | BX17: =BT17/U17 | BZ17: =-'Raw financials'!BN13 | CA17: =-'Raw financials'!BO13 | CB17: =-'Raw financials'!BP13 | CC17: =-'Raw financials'!BQ13 | CD17: =-'Raw financials'!BR13 | CE17: =-'Raw financials'!BS13 | CF17: =-'Raw financials'!BT13 | CG17: =-'Raw financials'!BU13 | ... EY17: =-'Raw financials'!EM13 | FB17: =+FA17-EW17 | FC17: =+FB17/EW17 | FD17: =+FA17/T17 | FE17: =+FA17/U17
A18: Investment income | B18: ='Raw financials'!B18 | C18: ='Raw financials'!C18 | D18: ='Raw financials'!D18 | E18: ='Raw financials'!E18 | F18: ='Raw financials'!F18 | G18: ='Raw financials'!G18 | H18: ='Raw financials'!H18 | I18: ='Raw financials'!I18 | ... T18: ='Raw financials'!T18 | U18: =+T18 | V18: =+U18 | W18: =+V18 | X18: =+W18 | Y18: =+X18 | Z18: =+Y18 | AA18: =+U18-T18 | AB18: =+AA18/T18 | AC18: 1577.06 | AD18: =+U18-AC18 | AE18: =+AD18/AC18 | AG18: ='Raw financials'!AA18 | AH18: =B18-AG18 | AI18: ='Raw financials'!AB18 | AJ18: =C18-AI18 | AK18: ='Raw financials'!AC18 | AL18: =D18-AK18 | AM18: ='Raw financials'!AD18 | AN18: =E18-AM18 | AO18: ='Raw financials'!AE18 | AP18: =F18-AO18 | AQ18: ='Raw financials'!AF18 | AR18: =G18-AQ18 | AS18: ='Raw financials'!AG18 | AT18: =H18-AS18 | AU18: ='Raw financials'!AH18 | AV18: =I18-AU18 | AW18: ='Raw financials'!AI18 | AX18: =J18-AW18 | AY18: ='Raw financials'!AJ18 | AZ18: =K18-AY18 | BA18: ='Raw financials'!AK18 | BB18: =L18-BA18 | BC18: ='Raw financials'!AL18 | BD18: =M18-BC18 | BE18: ='Raw financials'!AM18 | BF18: =N18-BE18 | BG18: ='Raw financials'!AN18 | BH18: =O18-BG18 | BI18: ='Raw financials'!AO18 | BJ18: =P18-BI18 | BK18: ='Raw financials'!AP18 | BL18: =Q18-BK18 | BM18: ='Raw financials'!AQ18 | BN18: =R18-BM18 | BO18: ='Raw financials'!AR18 | BP18: =S18-BO18 | BQ18: ='Raw financials'!AS18 | BR18: =T18-BQ18 | BT18: =U18-BS18 | BU18: =BT18-BR18 | BV18: =BU18/BR18 | BW18: =BT18/T18 | BX18: =BT18/U18 | BZ18: ='Raw financials'!BN18 | CA18: ='Raw financials'!BO18 | CB18: ='Raw financials'!BP18 | CC18: ='Raw financials'!BQ18 | CD18: ='Raw financials'!BR18 | CE18: ='Raw financials'!BS18 | CF18: ='Raw financials'!BT18 | CG18: ='Raw financials'!BU18 | ... EY18: ='Raw financials'!EM18 | FB18: =+FA18-EW18 | FC18: =+FB18/EW18 | FD18: =+FA18/T18 | FE18: =+FA18/U18
A19: Of which is JV and asso income | AA19: =+U19-T19 | AB19: =+AA19/T19 | AD19: =+U19-AC19 | AE19: =+AD19/AC19 | AH19: =B19-AG19 | AJ19: =C19-AI19 | AL19: =D19-AK19 | AN19: =E19-AM19 | AP19: =F19-AO19 | AR19: =G19-AQ19 | AT19: =H19-AS19 | AV19: =I19-AU19 | AX19: =J19-AW19 | AZ19: =K19-AY19 | BB19: =L19-BA19 | BD19: =M19-BC19 | BF19: =N19-BE19 | BH19: =O19-BG19 | BJ19: =P19-BI19 | BL19: =Q19-BK19 | BN19: =R19-BM19 | BP19: =S19-BO19 | BR19: =T19-BQ19 | BT19: =U19-BS19 | BU19: =BT19-BR19 | BV19: =BU19/BR19 | BW19: =BT19/T19 | BX19: =BT19/U19 | FB19: =+FA19-EW19 | FC19: =+FB19/EW19 | FD19: =+FA19/T19 | FE19: =+FA19/U19
A20: Impairment losses | B20: =SUM('Raw financials'!B23,'Raw financials'!B24) | C20: =SUM('Raw financials'!C23,'Raw financials'!C24) | D20: =SUM('Raw financials'!D23,'Raw financials'!D24) | E20: =SUM('Raw financials'!E23,'Raw financials'!E24) | F20: =SUM('Raw financials'!F23,'Raw financials'!F24) | G20: =SUM('Raw financials'!G23,'Raw financials'!G24) | H20: =SUM('Raw financials'!H23,'Raw financials'!H24) | I20: =SUM('Raw financials'!I23,'Raw financials'!I24) | ... T20: =SUM('Raw financials'!T23,'Raw financials'!T24) | U20: =4*EX20 | V20: =U20 | W20: =V20 | X20: =W20 | Y20: =X20 | Z20: =Y20 | AA20: =+U20-T20 | AB20: =+AA20/T20 | AC20: -574.3 | AD20: =+U20-AC20 | AE20: =+AD20/AC20 | AG20: =SUM('Raw financials'!AA23,'Raw financials'!AA24) | AH20: =B20-AG20 | AI20: =SUM('Raw financials'!AB23,'Raw financials'!AB24) | AJ20: =C20-AI20 | AK20: =SUM('Raw financials'!AC23,'Raw financials'!AC24) | AL20: =D20-AK20 | AM20: =SUM('Raw financials'!AD23,'Raw financials'!AD24) | AN20: =E20-AM20 | AO20: =SUM('Raw financials'!AE23,'Raw financials'!AE24) | AP20: =F20-AO20 | AQ20: =SUM('Raw financials'!AF23,'Raw financials'!AF24) | AR20: =G20-AQ20 | AS20: =SUM('Raw financials'!AG23,'Raw financials'!AG24) | AT20: =H20-AS20 | AU20: =SUM('Raw financials'!AH23,'Raw financials'!AH24) | AV20: =I20-AU20 | AW20: =SUM('Raw financials'!AI23,'Raw financials'!AI24) | AX20: =J20-AW20 | AY20: =SUM('Raw financials'!AJ23,'Raw financials'!AJ24) | AZ20: =K20-AY20 | BA20: =SUM('Raw financials'!AK23,'Raw financials'!AK24) | BB20: =L20-BA20 | BC20: =SUM('Raw financials'!AL23,'Raw financials'!AL24) | BD20: =M20-BC20 | BE20: =SUM('Raw financials'!AM23,'Raw financials'!AM24) | BF20: =N20-BE20 | BG20: =SUM('Raw financials'!AN23,'Raw financials'!AN24) | BH20: =O20-BG20 | BI20: =SUM('Raw financials'!AO23,'Raw financials'!AO24) | BJ20: =P20-BI20 | BK20: =SUM('Raw financials'!AP23,'Raw financials'!AP24) | BL20: =Q20-BK20 | BM20: =SUM('Raw financials'!AQ23,'Raw financials'!AQ24) | BN20: =R20-BM20 | BO20: =SUM('Raw financials'!AR23,'Raw financials'!AR24) | BP20: =S20-BO20 | BQ20: =SUM('Raw financials'!AS23,'Raw financials'!AS24) | BR20: =T20-BQ20 | BT20: =U20-BS20 | BU20: =BT20-BR20 | BV20: =BU20/BR20 | BW20: =BT20/T20 | BX20: =BT20/U20 | BZ20: =SUM('Raw financials'!BN23,'Raw financials'!BN24) | CA20: =SUM('Raw financials'!BO23,'Raw financials'!BO24) | CB20: =SUM('Raw financials'!BP23,'Raw financials'!BP24) | CC20: =SUM('Raw financials'!BQ23,'Raw financials'!BQ24) | CD20: =SUM('Raw financials'!BR23,'Raw financials'!BR24) | CE20: =SUM('Raw financials'!BS23,'Raw financials'!BS24) | CF20: =SUM('Raw financials'!BT23,'Raw financials'!BT24) | CG20: =SUM('Raw financials'!BU23,'Raw financials'!BU24) | ... EY20: =SUM('Raw financials'!EM23,'Raw financials'!EM24) | FB20: =+FA20-EW20 | FC20: =+FB20/EW20 | FD20: =+FA20/T20 | FE20: =+FA20/U20
A21: Other income and expenses | B21: =SUM('Raw financials'!B17,'Raw financials'!B22,'Raw financials'!B25,'Raw financials'!B30,-'Raw financials'!B31) | C21: =SUM('Raw financials'!C17,'Raw financials'!C22,'Raw financials'!C25,'Raw financials'!C30,-'Raw financials'!C31) | D21: =SUM('Raw financials'!D17,'Raw financials'!D22,'Raw financials'!D25,'Raw financials'!D30,-'Raw financials'!D31) | E21: =SUM('Raw financials'!E17,'Raw financials'!E22,'Raw financials'!E25,'Raw financials'!E30,-'Raw financials'!E31) | F21: =SUM('Raw financials'!F17,'Raw financials'!F22,'Raw financials'!F25,'Raw financials'!F30,-'Raw financials'!F31) | G21: =SUM('Raw financials'!G17,'Raw financials'!G22,'Raw financials'!G25,'Raw financials'!G30,-'Raw financials'!G31) | H21: =SUM('Raw financials'!H17,'Raw financials'!H22,'Raw financials'!H25,'Raw financials'!H30,-'Raw financials'!H31) | I21: =SUM('Raw financials'!I17,'Raw financials'!I22,'Raw financials'!I25,'Raw financials'!I30,-'Raw financials'!I31) | ... S21: =SUM('Raw financials'!S17,'Raw financials'!S22,'Raw financials'!S25,'Raw financials'!S30,-'Raw financials'!S31) | T21: =SUM(-'Raw financials'!T16,'Raw financials'!T17,'Raw financials'!T22,'Raw financials'!T25,'Raw financials'!T26,'Raw financials'!T30,-'Raw financials'!T31) | U21: =T21/T4*U4 | V21: =+V4/U4*U21 | W21: =+W4/V4*V21 | X21: =+X4/W4*W21 | Y21: =+Y4/X4*X21 | Z21: =+Z4/Y4*Y21 | AA21: =+U21-T21 | AB21: =+AA21/T21 | AC21: 653.33991 | AD21: =+U21-AC21 | AE21: =+AD21/AC21 | AG21: =SUM(-'Raw financials'!AA16,'Raw financials'!AA17,'Raw financials'!AA22,'Raw financials'!AA25,'Raw financials'!AA26,'Raw financials'!AA30,-'Raw financials'!AA31) | AH21: =B21-AG21 | AI21: =SUM(-'Raw financials'!AB16,'Raw financials'!AB17,'Raw financials'!AB22,'Raw financials'!AB25,'Raw financials'!AB26,'Raw financials'!AB30,-'Raw financials'!AB31) | AJ21: =C21-AI21 | AK21: =SUM(-'Raw financials'!AC16,'Raw financials'!AC17,'Raw financials'!AC22,'Raw financials'!AC25,'Raw financials'!AC26,'Raw financials'!AC30,-'Raw financials'!AC31) | AL21: =D21-AK21 | AM21: =SUM(-'Raw financials'!AD16,'Raw financials'!AD17,'Raw financials'!AD22,'Raw financials'!AD25,'Raw financials'!AD26,'Raw financials'!AD30,-'Raw financials'!AD31) | AN21: =E21-AM21 | AO21: =SUM(-'Raw financials'!AE16,'Raw financials'!AE17,'Raw financials'!AE22,'Raw financials'!AE25,'Raw financials'!AE26,'Raw financials'!AE30,-'Raw financials'!AE31) | AP21: =F21-AO21 | AQ21: =SUM(-'Raw financials'!AF16,'Raw financials'!AF17,'Raw financials'!AF22,'Raw financials'!AF25,'Raw financials'!AF26,'Raw financials'!AF30,-'Raw financials'!AF31) | AR21: =G21-AQ21 | AS21: =SUM(-'Raw financials'!AG16,'Raw financials'!AG17,'Raw financials'!AG22,'Raw financials'!AG25,'Raw financials'!AG26,'Raw financials'!AG30,-'Raw financials'!AG31) | AT21: =H21-AS21 | AU21: =SUM(-'Raw financials'!AH16,'Raw financials'!AH17,'Raw financials'!AH22,'Raw financials'!AH25,'Raw financials'!AH26,'Raw financials'!AH30,-'Raw financials'!AH31) | AV21: =I21-AU21 | AW21: =SUM(-'Raw financials'!AI16,'Raw financials'!AI17,'Raw financials'!AI22,'Raw financials'!AI25,'Raw financials'!AI26,'Raw financials'!AI30,-'Raw financials'!AI31) | AX21: =J21-AW21 | AY21: =SUM(-'Raw financials'!AJ16,'Raw financials'!AJ17,'Raw financials'!AJ22,'Raw financials'!AJ25,'Raw financials'!AJ26,'Raw financials'!AJ30,-'Raw financials'!AJ31) | AZ21: =K21-AY21 | BA21: =SUM(-'Raw financials'!AK16,'Raw financials'!AK17,'Raw financials'!AK22,'Raw financials'!AK25,'Raw financials'!AK26,'Raw financials'!AK30,-'Raw financials'!AK31) | BB21: =L21-BA21 | BC21: =SUM(-'Raw financials'!AL16,'Raw financials'!AL17,'Raw financials'!AL22,'Raw financials'!AL25,'Raw financials'!AL26,'Raw financials'!AL30,-'Raw financials'!AL31) | BD21: =M21-BC21 | BE21: =SUM(-'Raw financials'!AM16,'Raw financials'!AM17,'Raw financials'!AM22,'Raw financials'!AM25,'Raw financials'!AM26,'Raw financials'!AM30,-'Raw financials'!AM31) | BF21: =N21-BE21 | BG21: =SUM(-'Raw financials'!AN16,'Raw financials'!AN17,'Raw financials'!AN22,'Raw financials'!AN25,'Raw financials'!AN26,'Raw financials'!AN30,-'Raw financials'!AN31) | BH21: =O21-BG21 | BI21: =SUM(-'Raw financials'!AO16,'Raw financials'!AO17,'Raw financials'!AO22,'Raw financials'!AO25,'Raw financials'!AO26,'Raw financials'!AO30,-'Raw financials'!AO31) | BJ21: =P21-BI21 | BK21: =SUM(-'Raw financials'!AP16,'Raw financials'!AP17,'Raw financials'!AP22,'Raw financials'!AP25,'Raw financials'!AP26,'Raw financials'!AP30,-'Raw financials'!AP31) | BL21: =Q21-BK21 | BM21: =SUM(-'Raw financials'!AQ16,'Raw financials'!AQ17,'Raw financials'!AQ22,'Raw financials'!AQ25,'Raw financials'!AQ26,'Raw financials'!AQ30,-'Raw financials'!AQ31) | BN21: =R21-BM21 | BO21: =SUM(-'Raw financials'!AR16,'Raw financials'!AR17,'Raw financials'!AR22,'Raw financials'!AR25,'Raw financials'!AR26,'Raw financials'!AR30,-'Raw financials'!AR31) | BP21: =S21-BO21 | BQ21: =SUM(-'Raw financials'!AS16,'Raw financials'!AS17,'Raw financials'!AS22,'Raw financials'!AS25,'Raw financials'!AS26,'Raw financials'!AS30,-'Raw financials'!AS31)-705.08+289.34423726 | BR21: =T21-BQ21 | BT21: =U21-BS21 | BU21: =BT21-BR21 | BV21: =BU21/BR21 | BW21: =BT21/T21 | BX21: =BT21/U21 | BZ21: =SUM(-'Raw financials'!BN16,'Raw financials'!BN17,'Raw financials'!BN22,'Raw financials'!BN25,'Raw financials'!BN26,'Raw financials'!BN30,-'Raw financials'!BN31) | CA21: =SUM(-'Raw financials'!BO16,'Raw financials'!BO17,'Raw financials'!BO22,'Raw financials'!BO25,'Raw financials'!BO26,'Raw financials'!BO30,-'Raw financials'!BO31) | CB21: =SUM(-'Raw financials'!BP16,'Raw financials'!BP17,'Raw financials'!BP22,'Raw financials'!BP25,'Raw financials'!BP26,'Raw financials'!BP30,-'Raw financials'!BP31) | CC21: =SUM(-'Raw financials'!BQ16,'Raw financials'!BQ17,'Raw financials'!BQ22,'Raw financials'!BQ25,'Raw financials'!BQ26,'Raw financials'!BQ30,-'Raw financials'!BQ31) | CD21: =SUM(-'Raw financials'!BR16,'Raw financials'!BR17,'Raw financials'!BR22,'Raw financials'!BR25,'Raw financials'!BR26,'Raw financials'!BR30,-'Raw financials'!BR31) | CE21: =SUM(-'Raw financials'!BS16,'Raw financials'!BS17,'Raw financials'!BS22,'Raw financials'!BS25,'Raw financials'!BS26,'Raw financials'!BS30,-'Raw financials'!BS31) | CF21: =SUM(-'Raw financials'!BT16,'Raw financials'!BT17,'Raw financials'!BT22,'Raw financials'!BT25,'Raw financials'!BT26,'Raw financials'!BT30,-'Raw financials'!BT31) | CG21: =SUM(-'Raw financials'!BU16,'Raw financials'!BU17,'Raw financials'!BU22,'Raw financials'!BU25,'Raw financials'!BU26,'Raw financials'!BU30,-'Raw financials'!BU31) | ... EY21: =SUM(-'Raw financials'!EM16,'Raw financials'!EM17,'Raw financials'!EM22,'Raw financials'!EM25,'Raw financials'!EM26,'Raw financials'!EM30,-'Raw financials'!EM31) | FB21: =+FA21-EW21 | FC21: =+FB21/EW21 | FD21: =+FA21/T21 | FE21: =+FA21/U21
A22: Profit before tax | B22: =B15+B17+B18+B20+B21 | C22: =C15+C17+C18+C20+C21 | D22: =D15+D17+D18+D20+D21 | E22: =E15+E17+E18+E20+E21 | F22: =F15+F17+F18+F20+F21 | G22: =G15+G17+G18+G20+G21 | H22: =H15+H17+H18+H20+H21 | I22: =I15+I17+I18+I20+I21 | ... Z22: =Z15+Z17+Z18+Z20+Z21 | AA22: =+U22-T22 | AB22: =+AA22/T22 | AC22: 5790.3514 | AD22: =+U22-AC22 | AE22: =+AD22/AC22 | AG22: =AG15+AG17+AG18+AG20+AG21 | AH22: =AH15+AH17+AH18+AH20+AH21 | AI22: =AI15+AI17+AI18+AI20+AI21 | AJ22: =AJ15+AJ17+AJ18+AJ20+AJ21 | AK22: =AK15+AK17+AK18+AK20+AK21 | AL22: =AL15+AL17+AL18+AL20+AL21 | AM22: =AM15+AM17+AM18+AM20+AM21 | AN22: =AN15+AN17+AN18+AN20+AN21 | ... BR22: =BR15+BR17+BR18+BR20+BR21 | BT22: =BT15+BT17+BT18+BT20+BT21 | BU22: =BT22-BR22 | BV22: =BU22/BR22 | BW22: =BT22/T22 | BX22: =BT22/U22 | BZ22: =BZ15+BZ17+BZ18+BZ20+BZ21 | CA22: =CA15+CA17+CA18+CA20+CA21 | CB22: =CB15+CB17+CB18+CB20+CB21 | CC22: =CC15+CC17+CC18+CC20+CC21 | CD22: =CD15+CD17+CD18+CD20+CD21 | CE22: =CE15+CE17+CE18+CE20+CE21 | CF22: =CF15+CF17+CF18+CF20+CF21 | CG22: =CG15+CG17+CG18+CG20+CG21 | ... EY22: =EY15+EY17+EY18+EY20+EY21 | FB22: =+FA22-EW22 | FC22: =+FB22/EW22 | FD22: =+FA22/T22 | FE22: =+FA22/U22
A23: Tax | B23: =-'Raw financials'!B36 | C23: =-'Raw financials'!C36 | D23: =-'Raw financials'!D36 | E23: =-'Raw financials'!E36 | F23: =-'Raw financials'!F36 | G23: =-'Raw financials'!G36 | H23: =-'Raw financials'!H36 | I23: =-'Raw financials'!I36 | ... T23: =-'Raw financials'!T36 | U23: =U22*-U24 | V23: =V22*-V24 | W23: =W22*-W24 | X23: =X22*-X24 | Y23: =Y22*-Y24 | Z23: =Z22*-Z24 | AA23: =+U23-T23 | AB23: =+AA23/T23 | AC23: -889.54814 | AD23: =+U23-AC23 | AG23: =-'Raw financials'!AA36 | AH23: =B23-AG23 | AI23: =-'Raw financials'!AB36 | AJ23: =C23-AI23 | AK23: =-'Raw financials'!AC36 | AL23: =D23-AK23 | AM23: =-'Raw financials'!AD36 | AN23: =E23-AM23 | AO23: =-'Raw financials'!AE36 | AP23: =F23-AO23 | AQ23: =-'Raw financials'!AF36 | AR23: =G23-AQ23 | AS23: =-'Raw financials'!AG36 | AT23: =H23-AS23 | AU23: =-'Raw financials'!AH36 | AV23: =I23-AU23 | AW23: =-'Raw financials'!AI36 | AX23: =J23-AW23 | AY23: =-'Raw financials'!AJ36 | AZ23: =K23-AY23 | BA23: =-'Raw financials'!AK36 | BB23: =L23-BA23 | BC23: =-'Raw financials'!AL36 | BD23: =M23-BC23 | BE23: =-'Raw financials'!AM36 | BF23: =N23-BE23 | BG23: =-'Raw financials'!AN36 | BH23: =O23-BG23 | BI23: =-'Raw financials'!AO36 | BJ23: =P23-BI23 | BK23: =-'Raw financials'!AP36 | BL23: =Q23-BK23 | BM23: =-'Raw financials'!AQ36 | BN23: =R23-BM23 | BO23: =-'Raw financials'!AR36 | BP23: =S23-BO23 | BQ23: =-'Raw financials'!AS36 | BR23: =T23-BQ23 | BT23: =U23-BS23 | BU23: =BT23-BR23 | BV23: =BU23/BR23 | BW23: =BT23/T23 | BX23: =BT23/U23 | BZ23: =-'Raw financials'!BN36 | CA23: =-'Raw financials'!BO36 | CB23: =-'Raw financials'!BP36 | CC23: =-'Raw financials'!BQ36 | CD23: =-'Raw financials'!BR36 | CE23: =-'Raw financials'!BS36 | CF23: =-'Raw financials'!BT36 | CG23: =-'Raw financials'!BU36 | ... EY23: =-'Raw financials'!EM36 | FB23: =+FA23-EW23 | FC23: =+FB23/EW23 | FD23: =+FA23/T23 | FE23: =+FA23/U23
A24: Tax rate | B24: =-B23/B22 | C24: =-C23/C22 | D24: =-D23/D22 | E24: =-E23/E22 | F24: =-F23/F22 | G24: =-G23/G22 | H24: =-H23/H22 | I24: =-I23/I22 | ... T24: =-T23/T22 | U24: =T24 | V24: =U24 | W24: =V24 | X24: =W24 | Y24: =X24 | Z24: =Y24 | AG24: =-AG23/AG22 | AH24: =-AH23/AH22 | AI24: =-AI23/AI22 | AJ24: =-AJ23/AJ22 | AK24: =-AK23/AK22 | AL24: =-AL23/AL22 | AM24: =-AM23/AM22 | AN24: =-AN23/AN22 | ... BR24: =-BR23/BR22 | BT24: =-BT23/BT22 | BU24: =BT24-BR24 | BV24: =BU24/BR24 | BW24: =BT24/T24 | BX24: =BT24/U24 | BZ24: =-BZ23/BZ22 | CA24: =-CA23/CA22 | CB24: =-CB23/CB22 | CC24: =-CC23/CC22 | CD24: =-CD23/CD22 | CE24: =-CE23/CE22 | CF24: =-CF23/CF22 | CG24: =-CG23/CG22 | ... EY24: =-EY23/EY22
A25: Profit after tax | B25: =B22+B23 | C25: =C22+C23 | D25: =D22+D23 | E25: =E22+E23 | F25: =F22+F23 | G25: =G22+G23 | H25: =H22+H23 | I25: =I22+I23 | ... Z25: =Z22+Z23 | AA25: =+U25-T25 | AB25: =+AA25/T25 | AC25: 4900.8032 | AD25: =+U25-AC25 | AE25: =+AD25/AC25 | AG25: =AG22+AG23 | AH25: =AH22+AH23 | AI25: =AI22+AI23 | AJ25: =AJ22+AJ23 | AK25: =AK22+AK23 | AL25: =AL22+AL23 | AM25: =AM22+AM23 | AN25: =AN22+AN23 | ... BR25: =BR22+BR23 | BT25: =BT22+BT23 | BU25: =BT25-BR25 | BV25: =BU25/BR25 | BW25: =BT25/T25 | BX25: =BT25/U25 | BZ25: =BZ22+BZ23 | CA25: =CA22+CA23 | CB25: =CB22+CB23 | CC25: =CC22+CC23 | CD25: =CD22+CD23 | CE25: =CE22+CE23 | CF25: =CF22+CF23 | CG25: =CG22+CG23 | ... EY25: =EY22+EY23 | FB25: =+FA25-EW25 | FC25: =+FB25/EW25 | FD25: =+FA25/T25 | FE25: =+FA25/U25
A26: Minority interest | B26: =-'Raw financials'!B43 | C26: =-'Raw financials'!C43 | D26: =-'Raw financials'!D43 | E26: =-'Raw financials'!E43 | F26: =-'Raw financials'!F43 | G26: =-'Raw financials'!G43 | H26: =-'Raw financials'!H43 | I26: =-'Raw financials'!I43 | ... T26: =-'Raw financials'!T43 | U26: =U25*-U27 | V26: =V25*-V27 | W26: =W25*-W27 | X26: =X25*-X27 | Y26: =Y25*-Y27 | Z26: =Z25*-Z27 | AA26: =+U26-T26 | AB26: =+AA26/T26 | AC26: -544.74239 | AG26: =-'Raw financials'!AA43 | AH26: =B26-AG26 | AI26: =-'Raw financials'!AB43 | AJ26: =C26-AI26 | AK26: =-'Raw financials'!AC43 | AL26: =D26-AK26 | AM26: =-'Raw financials'!AD43 | AN26: =E26-AM26 | AO26: =-'Raw financials'!AE43 | AP26: =F26-AO26 | AQ26: =-'Raw financials'!AF43 | AR26: =G26-AQ26 | AS26: =-'Raw financials'!AG43 | AT26: =H26-AS26 | AU26: =-'Raw financials'!AH43 | AV26: =I26-AU26 | AW26: =-'Raw financials'!AI43 | AX26: =J26-AW26 | AY26: =-'Raw financials'!AJ43 | AZ26: =K26-AY26 | BA26: =-'Raw financials'!AK43 | BB26: =L26-BA26 | BC26: =-'Raw financials'!AL43 | BD26: =M26-BC26 | BE26: =-'Raw financials'!AM43 | BF26: =N26-BE26 | BG26: =-'Raw financials'!AN43 | BH26: =O26-BG26 | BI26: =-'Raw financials'!AO43 | BJ26: =P26-BI26 | BK26: =-'Raw financials'!AP43 | BL26: =Q26-BK26 | BM26: =-'Raw financials'!AQ43 | BN26: =R26-BM26 | BO26: =-'Raw financials'!AR43 | BP26: =S26-BO26 | BQ26: =-'Raw financials'!AS43 | BR26: =T26-BQ26 | BT26: =U26-BS26 | BU26: =BT26-BR26 | BV26: =BU26/BR26 | BW26: =BT26/T26 | BX26: =BT26/U26 | BZ26: =-'Raw financials'!BN43 | CA26: =-'Raw financials'!BO43 | CB26: =-'Raw financials'!BP43 | CC26: =-'Raw financials'!BQ43 | CD26: =-'Raw financials'!BR43 | CE26: =-'Raw financials'!BS43 | CF26: =-'Raw financials'!BT43 | CG26: =-'Raw financials'!BU43 | ... EY26: =-'Raw financials'!EM43 | FB26: =+FA26-EW26 | FC26: =+FB26/EW26 | FD26: =+FA26/T26 | FE26: =+FA26/U26
A27: % of PAT | B27: =-B26/B25 | C27: =-C26/C25 | D27: =-D26/D25 | E27: =-E26/E25 | F27: =-F26/F25 | G27: =-G26/G25 | H27: =-H26/H25 | I27: =-I26/I25 | ... T27: =-T26/T25 | U27: =T27 | V27: =U27 | W27: =V27 | X27: =W27 | Y27: =X27 | Z27: =Y27 | AG27: =-AG26/AG25 | AH27: =-AH26/AH25 | AI27: =-AI26/AI25 | AJ27: =-AJ26/AJ25 | AK27: =-AK26/AK25 | AL27: =-AL26/AL25 | AM27: =-AM26/AM25 | AN27: =-AN26/AN25 | ... BR27: =-BR26/BR25 | BT27: =-BT26/BT25 | BU27: =BT27-BR27 | BV27: =BU27/BR27 | BW27: =BT27/T27 | BX27: =BT27/U27 | BZ27: =-BZ26/BZ25 | CA27: =-CA26/CA25 | CB27: =-CB26/CB25 | CC27: =-CC26/CC25 | CD27: =-CD26/CD25 | CE27: =-CE26/CE25 | CF27: =-CF26/CF25 | CG27: =-CG26/CG25 | ... EY27: =-EY26/EY25 | FB27: =+FA27-EW27 | FC27: =+FB27/EW27 | FD27: =+FA27/T27 | FE27: =+FA27/U27
A28: Reported net profit | B28: =B25+B26 | C28: =C25+C26 | D28: =D25+D26 | E28: =E25+E26 | F28: =F25+F26 | G28: =G25+G26 | H28: =H25+H26 | I28: =I25+I26 | ... Z28: =Z25+Z26 | AA28: =+U28-T28 | AB28: =+AA28/T28 | AC28: 4356.0608 | AG28: =AG25+AG26 | AH28: =AH25+AH26 | AI28: =AI25+AI26 | AJ28: =AJ25+AJ26 | AK28: =AK25+AK26 | AL28: =AL25+AL26 | AM28: =AM25+AM26 | AN28: =AN25+AN26 | ... BR28: =BR25+BR26 | BT28: =BT25+BT26 | BU28: =BT28-BR28 | BV28: =BU28/BR28 | BW28: =BT28/T28 | BX28: =BT28/U28 | BZ28: =BZ25+BZ26 | CA28: =CA25+CA26 | CB28: =CB25+CB26 | CC28: =CC25+CC26 | CD28: =CD25+CD26 | CE28: =CE25+CE26 | CF28: =CF25+CF26 | CG28: =CG25+CG26 | ... EY28: =EY25+EY26 | FB28: =+FA28-EW28 | FC28: =+FB28/EW28 | FD28: =+FA28/T28 | FE28: =+FA28/U28
A29: YoY | Q29: =Q28/P28-1 | R29: =R28/Q28-1 | S29: =S28/R28-1 | T29: =T28/S28-1 | U29: =U28/T28-1 | V29: =V28/U28-1 | W29: =W28/V28-1 | X29: =X28/W28-1 | ... Z29: =Z28/Y28-1 | AC29: 0.49072955 | BM29: =BM28/BK28-1 | BN29: =BN28/BL28-1 | BO29: =BO28/BM28-1 | BP29: =BP28/BN28-1 | BQ29: =BQ28/BO28-1 | BR29: =BR28/BP28-1 | BT29: =BT28/BR28-1 | DX29: =DX28/DT28-1 | DY29: =DY28/DU28-1 | DZ29: =DZ28/DV28-1 | EA29: =EA28/DW28-1 | EB29: =EB28/DX28-1 | EC29: =EC28/DY28-1 | ED29: =ED28/DZ28-1 | EE29: =EE28/EA28-1 | ... EY29: =EY28/EU28-1
A30: NPM | B30: =+B28/B4 | C30: =+C28/C4 | D30: =+D28/D4 | E30: =+E28/E4 | F30: =+F28/F4 | G30: =+G28/G4 | H30: =+H28/H4 | I30: =+I28/I4 | ... Z30: =+Z28/Z4 | AC30: 0.053543599 | BM30: =+BM28/BM4 | BN30: =+BN28/BN4 | BO30: =+BO28/BO4 | BP30: =+BP28/BP4 | BQ30: =+BQ28/BQ4 | BR30: =+BR28/BR4 | BT30: =+BT28/BT4 | BZ30: =+BZ28/BZ4 | CA30: =+CA28/CA4 | CB30: =+CB28/CB4 | CC30: =+CC28/CC4 | CD30: =+CD28/CD4 | CE30: =+CE28/CE4 | CF30: =+CF28/CF4 | CG30: =+CG28/CG4 | ... EY30: =+EY28/EY4
A31: ESOP target
A32: YoY
A33: Diff vs. UBS-Se
A35: EPS - basic | B35: ='Raw financials'!B50 | C35: ='Raw financials'!C50 | D35: ='Raw financials'!D50 | E35: ='Raw financials'!E50 | F35: ='Raw financials'!F50 | G35: ='Raw financials'!G50 | H35: ='Raw financials'!H50 | I35: ='Raw financials'!I50 | ... T35: ='Raw financials'!T50 | U35: =U28/U43*U45 | V35: =V28/V43*V45 | W35: =W28/W43*W45 | X35: =X28/X43*X45 | Y35: =Y28/Y43*Y45 | Z35: =Z28/Z43*Z45 | AG35: ='Raw financials'!AA50 | AH35: =B35-AG35 | AI35: ='Raw financials'!AB50 | AJ35: =C35-AI35 | AK35: ='Raw financials'!AC50 | AL35: =D35-AK35 | AM35: ='Raw financials'!AD50 | AN35: =E35-AM35 | AO35: ='Raw financials'!AE50 | AP35: =F35-AO35 | AQ35: ='Raw financials'!AF50 | AR35: =G35-AQ35 | AS35: ='Raw financials'!AG50 | AT35: =H35-AS35 | AU35: ='Raw financials'!AH50 | AV35: =I35-AU35 | AW35: ='Raw financials'!AI50 | AX35: =J35-AW35 | AY35: ='Raw financials'!AJ50 | AZ35: =K35-AY35 | BA35: ='Raw financials'!AK50 | BB35: =L35-BA35 | BC35: ='Raw financials'!AL50 | BD35: =M35-BC35 | BE35: ='Raw financials'!AM50 | BF35: =N35-BE35 | BG35: ='Raw financials'!AN50 | BH35: =O35-BG35 | BI35: ='Raw financials'!AO50 | BJ35: =P35-BI35 | BK35: ='Raw financials'!AP50 | BL35: =Q35-BK35 | BM35: ='Raw financials'!AQ50 | BN35: =R35-BM35 | BO35: ='Raw financials'!AR50 | BP35: =S35-BO35 | BQ35: ='Raw financials'!AS50 | BR35: =T35-BQ35 | BT35: =U35-BS35
A36: EPS - diluted | B36: ='Raw financials'!B51 | C36: ='Raw financials'!C51 | D36: ='Raw financials'!D51 | E36: ='Raw financials'!E51 | F36: ='Raw financials'!F51 | G36: ='Raw financials'!G51 | H36: ='Raw financials'!H51 | I36: ='Raw financials'!I51 | ... T36: ='Raw financials'!T51 | U36: =U28/U44*U45 | V36: =V28/V44*V45 | W36: =W28/W44*W45 | X36: =X28/X44*X45 | Y36: =Y28/Y44*Y45 | Z36: =Z28/Z44*Z45 | AG36: ='Raw financials'!AA51 | AH36: =B36-AG36 | AI36: ='Raw financials'!AB51 | AJ36: =C36-AI36 | AK36: ='Raw financials'!AC51 | AL36: =D36-AK36 | AM36: ='Raw financials'!AD51 | AN36: =E36-AM36 | AO36: ='Raw financials'!AE51 | AP36: =F36-AO36 | AQ36: ='Raw financials'!AF51 | AR36: =G36-AQ36 | AS36: ='Raw financials'!AG51 | AT36: =H36-AS36 | AU36: ='Raw financials'!AH51 | AV36: =I36-AU36 | AW36: ='Raw financials'!AI51 | AX36: =J36-AW36 | AY36: ='Raw financials'!AJ51 | AZ36: =K36-AY36 | BA36: ='Raw financials'!AK51 | BB36: =L36-BA36 | BC36: ='Raw financials'!AL51 | BD36: =M36-BC36 | BE36: ='Raw financials'!AM51 | BF36: =N36-BE36 | BG36: ='Raw financials'!AN51 | BH36: =O36-BG36 | BI36: ='Raw financials'!AO51 | BJ36: =P36-BI36 | BK36: ='Raw financials'!AP51 | BL36: =Q36-BK36 | BM36: ='Raw financials'!AQ51 | BN36: =R36-BM36 | BO36: ='Raw financials'!AR51 | BP36: =S36-BO36 | BQ36: ='Raw financials'!AS51 | BR36: =T36-BQ36 | BT36: =U36-BS36
A37: BPS - YE | B37: =+B89/B42 | C37: =+C89/C42 | D37: =+D89/D42 | E37: =+E89/E42 | F37: =+F89/F42 | G37: =+G89/G42 | H37: =+H89/H42 | I37: =+I89/I42 | ... Z37: =+Z89/Z42
A38: Dividend 现金分红 | B38: 90 | C38: 196.08 | D38: 17.64 | E38: 160.31 | F38: 260.5 | G38: 320.62 | H38: 220.42 | I38: 360.69 | J38: 210.32 | K38: 140.21 | L38: 0 | M38: 0 | N38: 339.99 | O38: 639.35 | P38: 561.53 | Q38: 717.33 | R38: 1044.71 | S38: 1480.81 | T38: 1366.32 | U38: =U28*U40 | V38: =V28*V40 | W38: =W28*W40 | X38: =X28*X40 | Y38: =Y28*Y40 | Z38: =Z28*Z40
A39: DPS | B39: =B38/B42 | C39: =C38/C42 | D39: =D38/D42 | E39: =E38/E42 | F39: =F38/F42 | G39: =G38/G42 | H39: =H38/H42 | I39: =I38/I42 | ... Z39: =Z38/Z42
A40: Payout ratio | B40: =B38/B28 | C40: =C38/C28 | D40: =D38/D28 | E40: =E38/E28 | F40: =F38/F28 | G40: =G38/G28 | H40: =H38/H28 | I40: =I38/I28 | ... T40: =T38/T28 | U40: =T40+1% | V40: =U40+1% | W40: =V40+1% | X40: =+W40 | Y40: =+X40 | Z40: =+Y40
A42: Numbers of shares - YE | B42: =+B84 | C42: =+C84 | D42: =+D84 | E42: =+E84 | F42: =+F84 | G42: =+G84 | H42: =+H84 | I42: =+I84 | ... T42: =+T84 | U42: 3458 | V42: =U42 | W42: =V42 | X42: =W42 | Y42: =X42 | Z42: =Y42 | AG42: =+AG84 | AH42: =+AG42 | AI42: =+AI84 | AJ42: =+AI42 | AK42: =+AK84 | AL42: =+AK42 | AM42: =+AM84 | AN42: =+AM42 | AO42: =+AO84 | AP42: =+AO42 | AQ42: =+AQ84 | AR42: =+AQ42 | AS42: =+AS84 | AT42: =+AS42 | AU42: =+AU84 | AV42: =+AU42 | AW42: =+AW84 | AX42: =+AW42 | AY42: =+AY84 | AZ42: =+AY42 | BA42: =+BA84 | BB42: =+BA42 | BC42: =+BC84 | BD42: =+BC42 | BE42: =+BE84 | BF42: =+BE42 | BG42: =+BG84 | BH42: =+BG42 | BI42: =+BI84 | BJ42: =+BI42 | BK42: =+BK84 | BL42: =+BK42 | BM42: =+BM84 | BN42: =+BM42 | BO42: =+BO84 | BP42: =+BO42 | BQ42: =+BQ84 | BR42: =+BQ42 | BT42: =+BS42
...

Sheet Driver
AF1: H125
A2: Rmb m | B2: 2017 | C2: 2018 | D2: 2019 | E2: 2020 | F2: =E2+1 | G2: =F2+1 | H2: =G2+1 | I2: =H2+1 | J2: =I2+1 | K2: =J2+1 | L2: =K2+1 | M2: =L2+1 | ... O2: =N2+1 | P2: 25-28 | AB2: H124 | AC2: H224 | AD2: H125 | AE2: H225E | AF2: Change | AG2: Change % | AH2: % of last year | AI2: % of FY
A3: P&L drivers
A4: Revenue
A5: By product | L5: =+L7+4000 | M5: =+M7+6000 | N5: =7500+N7
A6: High-efficient clean energy equipment | E6: 11152.33 | F6: 12786.98 | G6: 14684.57 | H6: 20589.29 | I6: 28358.2 | J6: =+J7+J8+J9 | K6: =+K7+K8+K9 | L6: =+L7+L8+L9 | M6: =+M7+M8+M9 | N6: =+N7+N8+N9 | O6: =+O7+O8+O9 | P6: =(M6/J6)^(1/3)-1 | AB6: 14065.2 | AC6: =I6-AB6 | AE6: =J6-AD6 | AF6: =AD6-AB6 | AG6: =AF6/AB6 | AH6: =AB6/I6 | AI6: =AD6/J6
A7: Gas Turbine | E7: 2019 | F7: 1734 | G7: 1831 | H7: 3789.43 | I7: 7258 | J7: =+I7*(1+U18) | K7: =+J7*(1+V18) | L7: =+K7*(1+W18) | M7: =+L7*(1+X18) | N7: =+M7*(1+Y18) | O7: =+N7*(1+Z18) | P7: =(M7/J7)^(1/3)-1 | AB7: 3607.4332 | AC7: =I7-AB7 | AE7: =J7-AD7 | AF7: =AD7-AB7 | AG7: =AF7/AB7 | AH7: =AB7/I7 | AI7: =AD7/J7
A8: Nuclear power equipment | B8: 2695.7011 | C8: 2390.1025 | D8: 2080.4074 | E8: 1805 | F8: 2229 | G8: 2057 | H8: 2902.56 | I8: 4876.71 | J8: =+I8*(1+U19) | K8: =+J8*(1+V19) | L8: =+K8*(1+W19) | M8: =+L8*(1+X19) | N8: =+M8*(1+Y19) | O8: =+N8*(1+Z19) | P8: =(M8/J8)^(1/3)-1 | AB8: 1935.5381 | AC8: =I8-AB8 | AE8: =J8-AD8 | AF8: =AD8-AB8 | AG8: =AF8/AB8 | AH8: =AB8/I8 | AI8: =AD8/J8
A9: Thermal power equipment | E9: 7328 | F9: 8824 | G9: =G6-G7-G8 | H9: =H6-H7-H8 | I9: =I6-I7-I8 | J9: =+I9*(1+U20) | K9: =+J9*(1+V20) | L9: =+K9*(1+W20) | M9: =+L9*(1+X20) | N9: =+M9*(1+Y20) | O9: =+N9*(1+Z20) | P9: =(M9/J9)^(1/3)-1 | AB9: =AB6-AB7-AB8 | AC9: =I9-AB9 | AE9: =J9-AD9 | AF9: =AD9-AB9 | AG9: =AF9/AB9 | AH9: =AB9/I9 | AI9: =AD9/J9
A10: Wind | E10: =10085.17-E11 | F10: =15138.46-F11 | G10: =14913.93-G11 | H10: =13837.89-H11 | I10: =16602.97-I11 | J10: =+I10*(1+U21) | K10: =+J10*(1+V21) | L10: =+K10*(1+W21) | M10: =+L10*(1+X21) | N10: =+M10*(1+Y21) | O10: =+N10*(1+Z21) | P10: =(M10/J10)^(1/3)-1 | AB10: =8215.03185567-AB11 | AC10: =I10-AB10 | AE10: =J10-AD10 | AF10: =AD10-AB10 | AG10: =AF10/AB10 | AH10: =AB10/I10 | AI10: =AD10/J10
A11: Hydro | E11: 2481.193 | F11: 2476.2423 | G11: 2488.9778 | H11: 2310.8088 | I11: 2955.3657 | J11: =+I11*(1+U22) | K11: =+J11*(1+V22) | L11: =+K11*(1+W22) | M11: =+L11*(1+X22) | N11: =+M11*(1+Y22) | O11: =+N11*(1+Z22) | P11: =(M11/J11)^(1/3)-1 | AB11: 1295.8126 | AC11: =I11-AB11 | AE11: =J11-AD11 | AF11: =AD11-AB11 | AG11: =AF11/AB11 | AH11: =AB11/I11 | AI11: =AD11/J11
A12: Modern manufacturing service industry (mostly O&M maintenance services) | E12: 4910.2468 | F12: 3963.3286 | G12: 4238.0845 | H12: 5383.5413 | I12: 7564.4065 | J12: =+I12*(1+U23) | K12: =+J12*(1+V23) | L12: =+K12*(1+W23) | M12: =+L12*(1+X23) | N12: =+M12*(1+Y23) | O12: =+N12*(1+Z23) | P12: =(M12/J12)^(1/3)-1 | AB12: 3521.0525 | AC12: =I12-AB12 | AE12: =J12-AD12 | AF12: =AD12-AB12 | AG12: =AF12/AB12 | AH12: =AB12/I12 | AI12: =AD12/J12
A13: Others (Engineering and others) | E13: =+E14-SUM(E6,E10:E12) | F13: =+F14-SUM(F6,F10:F12) | G13: =+G14-SUM(G6,G10:G12) | H13: =+H14-SUM(H6,H10:H12) | I13: =+I14-SUM(I6,I10:I12) | J13: =+I13*(1+U24) | K13: =+J13*(1+V24) | L13: =+K13*(1+W24) | M13: =+L13*(1+X24) | N13: =+M13*(1+Y24) | O13: =+N13*(1+Z24) | P13: =(M13/J13)^(1/3)-1 | AB13: =+AB14-SUM(AB6,AB10:AB12) | AC13: =I13-AB13 | AE13: =J13-AD13 | AF13: =AD13-AB13 | AG13: =AF13/AB13 | AH13: =AB13/I13 | AI13: =AD13/J13
A14: Total | E14: =Model!P4 | F14: =Model!Q4 | G14: =Model!R4 | H14: =Model!S4 | I14: =Model!T4 | J14: =+SUM(J6,J10:J13) | K14: =+SUM(K6,K10:K13) | L14: =+SUM(L6,L10:L13) | M14: =+SUM(M6,M10:M13) | N14: =+SUM(N6,N10:N13) | O14: =+SUM(O6,O10:O13) | P14: =(M14/J14)^(1/3)-1 | AB14: =Model!BQ4 | AC14: =I14-AB14 | AE14: =J14-AD14 | AF14: =AD14-AB14 | AG14: =AF14/AB14 | AH14: =AB14/I14 | AI14: =AD14/J14
A16: YoY growth
A17: =+A6 | F17: =+F6/E6-1 | G17: =+G6/F6-1 | H17: =+H6/G6-1 | I17: =+I6/H6-1 | J17: =+J6/I6-1 | K17: =+K6/J6-1 | L17: =+L6/K6-1 | M17: =+M6/L6-1 | ... O17: =+O6/N6-1 | U17: do not delete | AE17: =+AE6/AC6-1
A18: =A7 | F18: =+F7/E7-1 | G18: =+G7/F7-1 | H18: =+H7/G7-1 | I18: =+I7/H7-1 | J18: 0.1 | K18: 0.1 | L18: 0.55546778 | M18: 0.21712689 | N18: 0.15413066 | O18: =++N18 | P18: refer to our power equipment database | R18: 0.1 | U18: =J18+Sensitvity!J26 | V18: =K18+Sensitvity!A30 | W18: =L18+Sensitvity!A33 | X18: =M18+Sensitvity!A36 | Y18: =N18+Sensitvity!A39 | Z18: =O18+Sensitvity!A42 | AE18: =+AE7/AC7-1
A19: =A8 | F19: =+F8/E8-1 | G19: =+G8/F8-1 | H19: =+H8/G8-1 | I19: =+I8/H8-1 | J19: 0.3 | K19: =J19 | L19: 0.25 | M19: =L19 | N19: =M19 | O19: =+N19 | U19: =J19+Sensitvity!J27 | V19: =K19+Sensitvity!J30 | W19: =L19+Sensitvity!J33 | X19: =M19+Sensitvity!J36 | Y19: =N19+Sensitvity!J39 | Z19: =O19+Sensitvity!J42 | AE19: =+AE8/AC8-1
A20: =A9 | F20: =+F9/E9-1 | G20: =+G9/F9-1 | H20: =+H9/G9-1 | I20: =+I9/H9-1 | J20: 0.05 | K20: 0.05 | L20: =K20 | M20: =L20 | N20: =M20 | O20: =+N20 | U20: =J20+Sensitvity!S27 | V20: =K20+Sensitvity!S30 | W20: =L20+Sensitvity!S33 | X20: =M20+Sensitvity!S36 | Y20: =N20+Sensitvity!S39 | Z20: =O20+Sensitvity!S42 | AE20: =+AE9/AC9-1
A21: =+A10 | F21: =+F10/E10-1 | G21: =+G10/F10-1 | H21: =+H10/G10-1 | I21: =+I10/H10-1 | J21: 0.4 | K21: 0.1 | L21: =K21+5% | M21: =L21 | N21: =M21 | O21: =+N21 | U21: =J21+Sensitvity!AB27 | V21: =K21+Sensitvity!AB30 | W21: =L21+Sensitvity!AB33 | X21: =M21+Sensitvity!AB36 | Y21: =N21+Sensitvity!AB39 | Z21: =O21+Sensitvity!AB42 | AE21: =+AE10/AC10-1
A22: =+A11 | F22: =+F11/E11-1 | G22: =+G11/F11-1 | H22: =+H11/G11-1 | I22: =+I11/H11-1 | J22: 0.1 | K22: =J22 | L22: =K22 | M22: =L22 | N22: =M22 | O22: =+N22 | P22: Yarlung Zangbo hydropower project start to contribute to revenue from 2030-35 | U22: =J22+Sensitvity!AK27 | V22: =K22+Sensitvity!AK30 | W22: =L22+Sensitvity!AK33 | X22: =M22+Sensitvity!AK36 | Y22: =N22+Sensitvity!AK39 | Z22: =O22+Sensitvity!AK42 | AE22: =+AE11/AC11-1
A23: =+A12 | F23: =+F12/E12-1 | G23: =+G12/F12-1 | H23: =+H12/G12-1 | I23: =+I12/H12-1 | J23: 0.31603342 | K23: 0.27583367 | L23: 0.25236963 | M23: 0.21974603 | N23: 0.19625775 | O23: =+N23 | P23: refer to our power equipment database | U23: =J23+Sensitvity!BC27 | V23: =K23+Sensitvity!BC30 | W23: =L23+Sensitvity!BC33 | X23: =M23+Sensitvity!BC36 | Y23: =N23+Sensitvity!BC39 | Z23: =O23+Sensitvity!BC42 | AE23: =+AE12/AC12-1
A24: =+A13 | F24: =+F13/E13-1 | G24: =+G13/F13-1 | H24: =+H13/G13-1 | I24: =+I13/H13-1 | J24: 0.03 | K24: =J24 | L24: =K24 | M24: =L24 | N24: =M24 | O24: =+N24 | P24: organic growth | U24: =J24+Sensitvity!AT27 | V24: =K24+Sensitvity!AT30 | W24: =L24+Sensitvity!AT33 | X24: =M24+Sensitvity!AT36 | Y24: =N24+Sensitvity!AT39 | Z24: =O24+Sensitvity!AT42 | AE24: =+AE13/AC13-1
A25: Total | F25: =F14/E14-1 | G25: =G14/F14-1 | H25: =H14/G14-1 | I25: =I14/H14-1 | J25: =J14/I14-1 | K25: =K14/J14-1 | L25: =L14/K14-1 | M25: =M14/L14-1 | ... O25: =O14/N14-1 | AE25: =AE14/AC14-1
A27: Rev % of total
A28: =A17 | E28: =E6/E$14 | F28: =F6/F$14 | G28: =G6/G$14 | H28: =H6/H$14 | I28: =I6/I$14 | J28: =J6/J$14 | K28: =K6/K$14 | L28: =L6/L$14 | ... O28: =O6/O$14 | AB28: =AB6/AB$14 | AC28: =AC6/AC$14 | AE28: =AE6/AE$14
A29: =A7 | E29: =E7/E$14 | F29: =F7/F$14 | G29: =G7/G$14 | H29: =H7/H$14 | I29: =I7/I$14 | J29: =J7/J$14 | K29: =K7/K$14 | L29: =L7/L$14 | ... O29: =O7/O$14 | AB29: =AB7/AB$14 | AC29: =AC7/AC$14 | AE29: =AE7/AE$14
A30: =A8 | E30: =E8/E$14 | F30: =F8/F$14 | G30: =G8/G$14 | H30: =H8/H$14 | I30: =I8/I$14 | J30: =J8/J$14 | K30: =K8/K$14 | L30: =L8/L$14 | ... O30: =O8/O$14 | AB30: =AB8/AB$14 | AC30: =AC8/AC$14 | AE30: =AE8/AE$14
A31: =A9 | E31: =E9/E$14 | F31: =F9/F$14 | G31: =G9/G$14 | H31: =H9/H$14 | I31: =I9/I$14 | J31: =J9/J$14 | K31: =K9/K$14 | L31: =L9/L$14 | ... O31: =O9/O$14 | AB31: =AB9/AB$14 | AC31: =AC9/AC$14 | AE31: =AE9/AE$14
A32: =A21 | E32: =E10/E$14 | F32: =F10/F$14 | G32: =G10/G$14 | H32: =H10/H$14 | I32: =I10/I$14 | J32: =J10/J$14 | K32: =K10/K$14 | L32: =L10/L$14 | ... O32: =O10/O$14 | AB32: =AB10/AB$14 | AC32: =AC10/AC$14 | AE32: =AE10/AE$14
A33: =A22 | E33: =E11/E$14 | F33: =F11/F$14 | G33: =G11/G$14 | H33: =H11/H$14 | I33: =I11/I$14 | J33: =J11/J$14 | K33: =K11/K$14 | L33: =L11/L$14 | ... O33: =O11/O$14 | AB33: =AB11/AB$14 | AC33: =AC11/AC$14 | AE33: =AE11/AE$14
A34: =A23 | E34: =E12/E$14 | F34: =F12/F$14 | G34: =G12/G$14 | H34: =H12/H$14 | I34: =I12/I$14 | J34: =J12/J$14 | K34: =K12/K$14 | L34: =L12/L$14 | ... O34: =O12/O$14 | AB34: =AB12/AB$14 | AC34: =AC12/AC$14 | AE34: =AE12/AE$14
A35: =A24 | E35: =E13/E$14 | F35: =F13/F$14 | G35: =G13/G$14 | H35: =H13/H$14 | I35: =I13/I$14 | J35: =J13/J$14 | K35: =K13/K$14 | L35: =L13/L$14 | ... O35: =O13/O$14 | AB35: =AB13/AB$14 | AC35: =AC13/AC$14 | AE35: =AE13/AE$14
A36: Total | E36: =SUM(E28,E32:E35) | F36: =SUM(F28,F32:F35) | G36: =SUM(G28,G32:G35) | H36: =SUM(H28,H32:H35) | I36: =SUM(I28,I32:I35) | J36: =SUM(J28,J32:J35) | K36: =SUM(K28,K32:K35) | L36: =SUM(L28,L32:L35) | ... O36: =SUM(O28,O32:O35) | AB36: =SUM(AB28,AB32:AB35) | AC36: =SUM(AC28,AC32:AC35) | AE36: =SUM(AE28,AE32:AE35)
A38: COGS
A39: =+A6 | E39: -8524.26 | F39: -10008.95 | G39: -11579.67 | H39: -16198.62 | I39: -23607.8 | J39: =J50-J6 | K39: =K50-K6 | L39: =L50-L6 | M39: =M50-M6 | N39: =N50-N6 | O39: =O50-O6 | AB39: -11892.396 | AC39: =I39-AB39 | AE39: =J39-AD39 | AF39: =AD39-AB39 | AG39: =AF39/AB39 | AH39: =AB39/I39 | AI39: =AD39/J39
A40: =A7 | E40: =E51-E7 | F40: =F51-F7 | G40: =G51-G7 | H40: -3329.07 | I40: -6592.66 | J40: =J51-J7 | K40: =K51-K7 | L40: =L51-L7 | M40: =M51-M7 | N40: =N51-N7 | O40: =O51-O7 | AB40: -3201.9569 | AC40: =I40-AB40 | AE40: =J40-AD40 | AF40: =AD40-AB40 | AG40: =AF40/AB40 | AH40: =AB40/I40 | AI40: =AD40/J40
