Workbook
Name \A: #REF!
Name _1_0cu08.PeriodMonthC: #REF!
Name _2_0cu12.PeriodT: #REF!
Name _3_0cu13.PeriodY: #REF!
Name _4_0cu14.FinancialY: #REF!
Name _5_0cu43.ActualForecast: #REF!
Name _6_0cu57.Prelim: #REF!
Name _Model_Path: "\\ubsprod.msad.ubs.net\GroupShares\GLOBAL\IB_RESEARCH_HKG\POWER\Models\Archives\CLP 84.xlsx"
Name a: #REF!
Name Additions: #REF!
Name ASSOCBAL: #REF!
Name Attributable_To_Ordinary_Shareholders: #REF!
Name Average_Shares_In_Issue: #REF!
Name b: #REF!
Name Bal_Sheet: #REF!
Name Capacity_Reserve: #REF!
Name capex: #REF!
Name capexf: #REF!
Name Capital_Employed: #REF!
Name Capital_Expenditure: #REF!
Name Cash_EPS: #REF!
Name Cash_Flow: #REF!
Name CastlePeak_Bal_Sht: #REF!
Name Combined_Bal_Sht: #REF!
Name COMPOUND_GROWTH: #REF!
Name costs: #REF!
Name cu20.ItemTypeCategory: #REF!
Name d: #REF!
Name DATES: #REF!
Name DB: "WIREHKPROD"
Name debt: #REF!
Name Depreciation_Adjustment: #REF!
Name Depreciation_Amortisation: #REF!
Name DES: #REF!
Name dev_fund: #REF!
Name Dividend_Declar: #REF!
Name Dividend_Tax_Credit: #REF!
Name Dividends_Paid: #REF!
Name earnings: #REF!
Name EPS_FRS3: #REF!
Name EPS_Fully_Diluted: #REF!
Name EPS_Pre_Exceptional: #REF!
Name Extraordinaries: #REF!
Name F.1990: #REF!
Name F.1990.09: #REF!
Name F.1990.12: #REF!
Name F.1991: #REF!
Name F.1991.09: #REF!
Name F.1991.12: #REF!
Name F.1992: #REF!
Name F.1992.12: #REF!
Name F.1993: #REF!
Name F.1993.12: #REF!
Name F.1994: #REF!
Name F.1994.12: #REF!
Name F.1995: #REF!
Name F.1995.12: #REF!
Name F.1996: #REF!
Name F.1996.12: #REF!
Name F.1997: #REF!

Sheet VA-Disclaimer

Sheet DCF
A2: Key Assumptions
A3: Hong Kong risk-free rate | B3: 0.0372 | D3: PT | E3: =S37 | R3: Terminal value and NPV
A4: Hong Kong equity risk premium | B4: 0.05 | D4: Current price | E4: 67.25 | R4: WACC | S4: =B11
A5: CLP beta (X) | B5: 0.56 | D5: Upside | E5: =E3/E4-1 | R5: Terminal return on capital | S5: =+B13
A6: CLP cost of equity (%) | B6: =B3+B4*B5 | R6: Terminal growth rate | S6: =B12
A7: CLP pre tax cost of debt (%) | B7: 0.03 | V7: Check
A8: Effective tax rate (%) | B8: 0.25 | R8: NOPAT Multiple | S8: =(S5-S6)/(S5*(S4-S6)) | V8: =+S8-S23
A9: CLP after tax cost of debt (%) | B9: =B7*(1-B8)
A10: L/T debt to total capital ratio (%) | B10: 0.175 | R10: In 2030 - Group
A11: Discount Rate (%) | B11: =B6*(1-B10)+B9*B10 | R11: EBIT, core | S11: =Final!AN15
A12: Long-term growth rate | B12: 0.02 | R12: Adjusted tax rate | S12: =-Final!AN23/(Final!AN22-Final!AN18-Final!AN19)
A13: Implied terminal ROIC | B13: =S21 | R13: NOPAT | S13: =+S11*(1-S12)
R14: Invested capital in 2029 | S14: =+N77
R15: Invested capital in 2030 | S15: =+O77
A16: Explicit cash flows forecasts | R16: Average invested capital | S16: =AVERAGE(S14:S15)
R17: Return on capital | S17: =S13/S16
A18: HK$ Million | B18: =Final!AA2 | C18: =Final!AB2 | D18: =Final!AC2 | E18: =Final!AD2 | F18: =Final!AE2 | G18: =Final!AF2 | H18: =Final!AG2 | I18: =Final!AH2 | ... O18: =Final!AN2
A19: Years ahead | B19: 0 | C19: 0 | D19: 0 | E19: 0 | F19: 0 | G19: 0 | H19: 0 | I19: 0 | J19: 0 | K19: 0 | L19: =K19+1 | M19: =L19+1 | N19: =M19+1 | O19: =N19+1 | R19: Terminal period - Group
A20: Discount factor | B20: =1/((1+$B11)^B19) | C20: =1/((1+$B11)^C19) | D20: =1/((1+$B11)^D19) | E20: =1/((1+$B11)^E19) | F20: =1/((1+$B11)^F19) | G20: =1/((1+$B11)^G19) | H20: =1/((1+$B11)^H19) | I20: =1/((1+$B11)^I19) | ... O20: =1/((1+$B11)^O19) | R20: 1st year avg invested capital | S20: =+AVERAGE(N77:O77)*(1+$B$12)
R21: Implied terminal return on capital | S21: =+S22/S20
A22: Net cash flows from operations | B22: =Final!AA121 | C22: =Final!AB121 | D22: =Final!AC121 | E22: =Final!AD121 | F22: =Final!AE121 | G22: =Final!AF121 | H22: =Final!AG121 | I22: =Final!AH121 | ... O22: =Final!AN121 | R22: 1st year NOPAT | S22: =+SUM(S65:U65)
A23: add back interest | B23: =-Final!AA119 | C23: =-Final!AB119 | D23: =-Final!AC119 | E23: =-Final!AD119 | F23: =-Final!AE119 | G23: =-Final!AF119 | H23: =-Final!AG119 | I23: =-Final!AH119 | ... O23: =-Final!AN119 | R23: Implied NOPAT multiple | S23: =+S24/S22
A24: less tax shield on interest | B24: =-$B$8*B23 | C24: =-$B$8*C23 | D24: =-$B$8*D23 | E24: =-$B$8*E23 | F24: =-$B$8*F23 | G24: =-$B$8*G23 | H24: =-$B$8*H23 | I24: =-$B$8*I23 | ... O24: =-$B$8*O23 | R24: Terminal value (undiscounted) | S24: =+SUM(S67:U67)
A25: Dividends received | B25: =Final!AA126 | C25: =Final!AB126 | D25: =Final!AC126 | E25: =Final!AD126 | F25: =Final!AE126 | G25: =Final!AF126 | H25: =Final!AG126 | I25: =Final!AH126 | ... O25: =Final!AN126 | R25: Discount rate | S25: =O20
A26: Investment in associates and investments | B26: =Final!AA125+Final!AA128 | C26: =Final!AB125+Final!AB128 | D26: =Final!AC125+Final!AC128 | E26: =Final!AD125+Final!AD128 | F26: =Final!AE125+Final!AE128 | G26: =Final!AF125+Final!AF128 | H26: =Final!AG125+Final!AG128 | I26: =Final!AH125+Final!AH128 | ... O26: =Final!AN125+Final!AN128 | R26: Terminal value | S26: =S24*S25
A27: Capital expenditure | B27: =Final!AA124 | C27: =Final!AB124 | D27: =Final!AC124 | E27: =Final!AD124 | F27: =Final!AE124 | G27: =Final!AF124 | H27: =Final!AG124 | I27: =Final!AH124 | ... O27: =Final!AN124 | R27: Dividends and interest received | S27: =S42+S43
A28: Other investing cash flows | B28: =Final!AA127 | C28: =Final!AB127 | D28: =Final!AC127 | E28: =Final!AD127 | F28: =Final!AE127 | G28: =Final!AF127 | H28: =Final!AG127 | I28: =Final!AH127 | ... O28: =Final!AN127 | R28: Explicit cash flows (2027-2030) | S28: =SUM(L30:O30)
A29: Net cash flow | B29: =SUM(B22:B28) | C29: =SUM(C22:C28) | D29: =SUM(D22:D28) | E29: =SUM(E22:E28) | F29: =SUM(F22:F28) | G29: =SUM(G22:G28) | H29: =SUM(H22:H28) | I29: =SUM(I22:I28) | ... O29: =SUM(O22:O28)
A30: Discounted cash flow | B30: =B29*B20 | C30: =C29*C20 | D30: =D29*D20 | E30: =E29*E20 | F30: =F29*F20 | G30: =G29*G20 | H30: =H29*H20 | I30: =I29*I20 | ... O30: =O29*O20 | R30: EV | S30: =SUM(S26:S28)
R31: Cash on hand and securities | S31: =Final!AI57+Final!AI58
A32: SOC component | R32: less finance lease obligations | S32: =-(Final!AI86+Final!AI77)
A33: Hong Kong EBITDA (CAPCO + CLP HK) | B33: =+SUM(SOC!AA4:AA8,SOC!AA11) | C33: =+SUM(SOC!AB4:AB8,SOC!AB11) | D33: =+SUM(SOC!AC4:AC8,SOC!AC11) | E33: =+SUM(SOC!AD4:AD8,SOC!AD11) | F33: =+SUM(SOC!AE4:AE8,SOC!AE11) | G33: =+SUM(SOC!AF4:AF8,SOC!AF11) | H33: =+SUM(SOC!AG4:AG8,SOC!AG11) | I33: =+SUM(SOC!AH4:AH8,SOC!AH11) | ... O33: =+SUM(SOC!AN4:AN8,SOC!AN11) | R33: less debt | S33: =-(Final!AI76+Final!AI85+Final!AI91+Final!AI79+Final!AI82+Final!AI89)
A34: less tax | B34: =+SOC!AA14 | C34: =+SOC!AB14 | D34: =+SOC!AC14 | E34: =+SOC!AD14 | F34: =+SOC!AE14 | G34: =+SOC!AF14 | H34: =+SOC!AG14 | I34: =+SOC!AH14 | ... O34: =+SOC!AN14 | R34: SOC liabilities | S34: =-(Final!AI90+Final!AI81+Final!AI87-Final!AI61)
A35: less SOC Capex | B35: =-Driver!AA84 | C35: =-Driver!AB84 | D35: =-Driver!AC84 | E35: =-Driver!AD84 | F35: =-Driver!AE84 | G35: =-Driver!AF84 | H35: =-Driver!AG84 | I35: =-Driver!AH84 | ... O35: =-Driver!AN84 | R35: less minority interest | S35: =-Final!AI97
A36: Add change in SOC accounts | B36: =+SUM(Final!AA110:AA116) | C36: =+SUM(Final!AB110:AB116) | D36: =+SUM(Final!AC110:AC116) | E36: =+SUM(Final!AD110:AD116) | F36: =+SUM(Final!AE110:AE116) | G36: =+SUM(Final!AF110:AF116) | H36: =+SUM(Final!AG110:AG116) | I36: =+SUM(Final!AH110:AH116) | ... O36: =+SUM(Final!AN110:AN116) | R36: NPV | S36: =SUM(S30:S35)
A37: Net SOC cash flows | B37: =SUM(B33:B36) | C37: =SUM(C33:C36) | D37: =SUM(D33:D36) | E37: =SUM(E33:E36) | F37: =SUM(F33:F36) | G37: =SUM(G33:G36) | H37: =SUM(H33:H36) | I37: =SUM(I33:I36) | ... O37: =SUM(O33:O36) | R37: NPV per share | S37: =ROUND(S36/Final!AI52,0) | T37: =S37/86-1 | U37: =S37/58-1
A38: Discounted cash flow | B38: =B37*B20 | C38: =C37*C20 | D38: =D37*D20 | E38: =E37*E20 | F38: =F37*F20 | G38: =G37*G20 | H38: =H37*H20 | I38: =I37*I20 | ... O38: =O37*O20 | R38: China IPPs and DayaBay
R39: Dividend received in 2030 | S39: =+O25
A40: Implied others consolidated net cash flow | B40: =+B29-B37-B58-B25 | C40: =+C29-C37-C58-C25 | D40: =+D29-D37-D58-D25 | E40: =+E29-E37-E58-E25 | F40: =+F29-F37-F58-F25 | G40: =+G29-G37-G58-G25 | H40: =+H29-H37-H58-H25 | I40: =+I29-I37-I58-I25 | ... O40: =+O29-O37-O58-O25 | R40: Terminal growth for div and int | S40: 0
A41: Add capex | B41: =+-(B27-B57-B35) | C41: =+-(C27-C57-C35) | D41: =+-(D27-D57-D35) | E41: =+-(E27-E57-E35) | F41: =+-(F27-F57-F35) | G41: =+-(G27-G57-G35) | H41: =+-(H27-H57-H35) | I41: =+-(I27-I57-I35) | ... O41: =+-(O27-O57-O35) | R41: Dividends Termina value | S41: =S39*(1+S40)/(S4-S40)
...

Sheet Final
I1: * = 15 months to 31 December 1999 | AC1: DCF | AD1: =DCF!E3 | AE1: =AE99 | AF1: =AF99 | AG1: =AG99 | AH1: =AH99 | AI1: =AI99 | AJ1: =AJ99 | AK1: =AK99 | AL1: =AL99 | ... AN1: =AN99
B2: 1992 | C2: 1993 | D2: 1994 | E2: 1995 | F2: 1996 | G2: 1997 | H2: 1998 | I2: 1999* | J2: 2000 | K2: 2001 | L2: 2002 | M2: 2003 | N2: 2004 | O2: 2005 | P2: 2006 | Q2: 2007 | R2: 2008 | S2: 2009 | T2: 2010 | U2: 2011 | V2: 2012 | W2: 2013 | X2: 2014 | Y2: 2015 | Z2: 2016 | AA2: 2017 | AB2: 2018 | AC2: 2019 | AD2: 2020 | AE2: 2021 | AF2: 2022 | AG2: 2023 | AH2: 2024 | AI2: 2025E | AJ2: 2026E | AK2: 2027E | AL2: 2028E | AM2: 2029E | AN2: 2030E
A3: Income Statement
A4: SOC revenue | B4: =Driver!B4+Driver!B5 | C4: =Driver!C4+Driver!C5 | D4: =Driver!D4+Driver!D5 | E4: =Driver!E4+Driver!E5 | F4: =Driver!F4+Driver!F5 | G4: =Driver!G4+Driver!G5 | H4: =Driver!H4+Driver!H5 | I4: =Driver!I4+Driver!I5 | ... AN4: =Driver!AN4+Driver!AN5
A5: Overseas power revenues | B5: =SUM(Driver!B6:B9) | C5: =SUM(Driver!C6:C9) | D5: =SUM(Driver!D6:D9) | E5: =SUM(Driver!E6:E9) | F5: =SUM(Driver!F6:F9) | G5: =SUM(Driver!G6:G9) | H5: =SUM(Driver!H6:H9) | I5: =SUM(Driver!I6:I9) | ... AN5: =SUM(Driver!AN6:AN9)
A6: Other non-SOC revenue | B6: =B7-SUM(B4:B5) | C6: =C7-SUM(C4:C5) | D6: =D7-SUM(D4:D5) | E6: =E7-SUM(E4:E5) | F6: =F7-SUM(F4:F5) | G6: =G7-SUM(G4:G5) | H6: =H7-SUM(H4:H5) | I6: =I7-SUM(I4:I5) | ... AC6: =AC7-SUM(AC4:AC5) | AD6: =Driver!AD10 | AE6: =Driver!AE10 | AF6: =Driver!AF10 | AG6: =Driver!AG10 | AH6: =Driver!AH10 | AI6: =Driver!AI10 | AJ6: =Driver!AJ10 | AK6: =Driver!AK10 | ... AN6: =Driver!AN10
A7: Total revenue | B7: 13402 | C7: 14745 | D7: 15345 | E7: 16960 | F7: 18534 | G7: 20900 | H7: 22869 | I7: 29035 | J7: 24451 | K7: 24999 | L7: 26134 | M7: 28248 | N7: 30784 | O7: 38584 | P7: 45702 | Q7: 50789 | R7: 54297 | S7: 50668 | T7: 58410 | U7: 91634 | V7: 104861 | W7: 104530 | X7: 92259 | Y7: 80700 | Z7: 79434 | AA7: 92073 | AB7: 91425 | AC7: 85689 | AD7: 79590 | AE7: 83959 | AF7: 100662 | AG7: 87169 | AH7: 90964 | AI7: =SUM(AI4:AI6) | AJ7: =SUM(AJ4:AJ6) | AK7: =SUM(AK4:AK6) | AL7: =SUM(AL4:AL6) | AM7: =SUM(AM4:AM6) | AN7: =SUM(AN4:AN6)
A9: Operating costs | B9: =B14-B13-B12 | C9: =C14-C13-C12 | D9: =D14-D13-D12 | E9: =E14-E13-E12 | F9: =F14-F13-F12 | G9: =G14-G13-G12 | H9: =H14-H13-H12 | I9: =I14-I13-I12 | ... AH9: =AH14-AH13-AH12 | AI9: =AI10-AI7 | AJ9: =AJ10-AJ7 | AK9: =AK10-AK7 | AL9: =AL10-AL7 | AM9: =AM10-AM7 | AN9: =AN10-AN7
A10: EBITDA | B10: =B7+B9 | C10: =C7+C9 | D10: =D7+D9 | E10: =E7+E9 | F10: =F7+F9 | G10: =G7+G9 | H10: =H7+H9 | I10: =I7+I9 | ... AH10: =AH7+AH9 | AI10: =AI15-AI12 | AJ10: =AJ15-AJ12 | AK10: =AK15-AK12 | AL10: =AL15-AL12 | AM10: =AM15-AM12 | AN10: =AN15-AN12
A12: Depreciation and amortisation | B12: -852 | C12: -953 | D12: -783 | E12: -888 | F12: -1002 | G12: -1155 | H12: -1270 | I12: -1704 | J12: -1474 | K12: -1624 | L12: -1749 | M12: -2357 | N12: =-2529-41 | O12: -2896 | P12: -4968 | Q12: -4650 | R12: -4055 | S12: -4332 | T12: -5065 | U12: -6353 | V12: -7021 | W12: -7592 | X12: -6791 | Y12: -6765 | Z12: -6909 | AA12: -7368 | AB12: -8005 | AC12: -8118 | AD12: -8476 | AE12: -9308 | AF12: -8904 | AG12: -8594 | AH12: -9276 | AI12: =Driver!AI26 | AJ12: =Driver!AJ26 | AK12: =Driver!AK26 | AL12: =Driver!AL26 | AM12: =Driver!AM26 | AN12: =Driver!AN26
A13: SOC adjustments (until 2004) | B13: -616 | C13: -908 | D13: 221 | E13: 310 | F13: 319 | G13: 186.501 | H13: -1714.2821 | I13: -1787 | J13: -2276 | K13: -1506 | L13: -1643 | M13: -835 | N13: -348 | O13: 0 | P13: 0 | Q13: 0 | R13: 0 | S13: 0 | T13: 0 | U13: 0 | V13: 0 | W13: 0 | X13: 0 | Y13: 0 | Z13: 0 | AA13: =Z13 | AB13: =AA13 | AC13: =AB13 | AD13: =AC13 | AE13: =AD13 | AF13: =AE13 | AG13: =AF13 | AH13: =AG13 | ... AN13: =AM13
A14: Total operating expenses | B14: -10591 | C14: -11554 | D14: -12089 | E14: -13611 | F14: -14805 | G14: -16909.499 | H14: -18331.282 | I14: -23200 | J14: -20406 | K14: -20557 | L14: -20941 | M14: -22471 | N14: -23028 | O14: -29889 | P14: -33590 | Q14: -39607 | R14: -41717 | S14: -39880 | T14: -46413 | U14: -76461 | V14: -91760 | W14: -95624 | X14: =-79389+2025 | Y14: -58680 | Z14: -62288 | AA14: -73375 | AB14: -73263 | AC14: -71659 | AD14: -64874 | AE14: -71748 | AF14: -95378 | AG14: -71985 | AH14: -76061 | AI14: =AI9+AI12 | AJ14: =AJ9+AJ12 | AK14: =AK9+AK12 | AL14: =AL9+AL12 | AM14: =AM9+AM12 | AN14: =AN9+AN12
A15: Net operating income | B15: =B10+B12+B13 | C15: =C10+C12+C13 | D15: =D10+D12+D13 | E15: =E10+E12+E13 | F15: =F10+F12+F13 | G15: =G10+G12+G13 | H15: =H10+H12+H13 | I15: =I10+I12+I13 | ... AH15: =AH10+AH12+AH13 | AI15: =AI20-AI16-AI17-AI18-AI19 | AJ15: =AJ20-AJ16-AJ17-AJ18-AJ19 | AK15: =AK20-AK16-AK17-AK18-AK19 | AL15: =AL20-AL16-AL17-AL18-AL19 | AM15: =AM20-AM16-AM17-AM18-AM19 | AN15: =AN20-AN16-AN17-AN18-AN19
A16: Other Income, net | B16: 67 | C16: 70 | D16: 116 | E16: 160 | F16: 136 | G16: 137.899 | H16: 186.33419 | I16: -0.47599889 | J16: 517.36527 | K16: 56.6 | L16: -256.8 | M16: 469.73297 | N16: 52 | O16: 66 | P16: 55 | Q16: 2122 | R16: 727 | S16: 153 | T16: 400 | U16: -1985 | V16: 0 | W16: 0 | X16: 0 | Y16: 0 | Z16: 0 | AA16: =Z16 | AB16: =AA16 | AC16: -6381 | AD16: 0 | AE16: -1110 | AF16: -4312 | AG16: -5868 | AH16: 0 | AI16: =AH16 | AJ16: =AI16 | AK16: =AJ16 | AL16: =AK16 | AM16: =AL16 | AN16: =AM16
A17: Property | B17: 0 | C17: 0 | D17: 0 | E17: 1286 | F17: 0 | G17: 0 | H17: 1837 | I17: 626 | J17: 1357 | K17: 1752 | L17: 595 | M17: 291 | N17: 187 | O17: 267 | P17: 44 | Q17: 0 | R17: 0 | S17: 0 | T17: 0 | U17: 0 | V17: 0 | W17: 0 | X17: 0 | Y17: 0 | Z17: 0 | AA17: 0 | AB17: 0 | AC17: =+AB17 | AD17: =+AC17 | AE17: =+AD17 | AF17: =+AE17 | AG17: =+AF17 | AH17: =+AG17 | AI17: =+AH17 | AJ17: =+AI17 | ... AN17: =+AM17
A18: Other jointly controlled entities | B18: 1100 | C18: 1195 | D18: 1433 | E18: 1653 | F18: 1847 | G18: 1972.6 | H18: 2097.8 | I18: 2732.2919 | J18: 2215.6 | K18: 2339 | L18: 2992 | M18: 3399 | N18: 3181 | O18: 2832 | P18: 2892 | Q18: 3024 | R18: 2624 | S18: 2675 | T18: 2080 | U18: 2929 | V18: 2405 | W18: 2671 | X18: 1562 | Y18: 1357 | Z18: 737 | AA18: 508 | AB18: 518 | AC18: 885 | AD18: 797 | AE18: -97 | AF18: 325 | AG18: 1147 | AH18: 845 | AI18: =Driver!AI38 | AJ18: =Driver!AJ38 | AK18: =Driver!AK38 | AL18: =Driver!AL38 | AM18: =Driver!AM38 | AN18: =Driver!AN38
A19: Electricity associates | B19: 0 | C19: 0 | D19: 0 | E19: 0 | F19: 0 | G19: 0 | H19: 15 | I19: 7 | J19: -895.36527 | K19: 14 | L19: 30 | M19: 102 | N19: 236 | O19: 140 | P19: 114 | Q19: 1 | R19: -27 | S19: -354 | T19: 813 | U19: 681 | V19: 579 | W19: 612 | X19: 796 | Y19: 888 | Z19: 904 | AA19: 950 | AB19: 1818 | AC19: 1828 | AD19: 1725 | AE19: 2071 | AF19: 2135 | AG19: 2049 | AH19: 1810 | AI19: =Driver!AI39 | AJ19: =Driver!AJ39 | AK19: =Driver!AK39 | AL19: =Driver!AL39 | AM19: =Driver!AM39 | AN19: =Driver!AN39
A20: EBIT | B20: =SUM(B15:B19) | C20: =SUM(C15:C19) | D20: =SUM(D15:D19) | E20: =SUM(E15:E19) | F20: =SUM(F15:F19) | G20: =SUM(G15:G19) | H20: =SUM(H15:H19) | I20: =SUM(I15:I19) | ... AH20: =SUM(AH15:AH19) | AI20: =AI22-AI21 | AJ20: =AJ22-AJ21 | AK20: =AK22-AK21 | AL20: =AL22-AL21 | AM20: =AM22-AM21 | AN20: =AN22-AN21
A21: Net finance costs | B21: -67 | C21: -48 | D21: -16 | E21: -48 | F21: -50 | G21: 565 | H21: 973 | I21: 612 | J21: -94 | K21: -158 | L21: -156 | M21: -640.22069 | N21: -983 | O21: -1489 | P21: -4624 | Q21: -4881 | R21: -4121 | S21: -3408 | T21: -4111 | U21: -5859 | V21: -6101 | W21: -6349 | X21: -4049 | Y21: -3936 | Z21: -2124 | AA21: =-2180+151 | AB21: =-2049+192 | AC21: =-1983+162 | AD21: =-1873+136 | AE21: =-1744+108 | AF21: =-2085+243 | AG21: =-2139+270 | AH21: =+-2254+235 | AI21: =Driver!AI106 | AJ21: =Driver!AJ106 | AK21: =Driver!AK106 | AL21: =Driver!AL106 | AM21: =Driver!AM106 | AN21: =Driver!AN106
A22: Pretax profits | B22: =B20+B21 | C22: =C20+C21 | D22: =D20+D21 | E22: =E20+E21 | F22: =F20+F21 | G22: =G20+G21 | H22: =H20+H21 | I22: =I20+I21 | ... AH22: =AH20+AH21 | AI22: =AI24-AI23 | AJ22: =AJ24-AJ23 | AK22: =AK24-AK23 | AL22: =AL24-AL23 | AM22: =AM24-AM23 | AN22: =AN24-AN23
A23: Tax | B23: -738 | C23: -856 | D23: -583 | E23: -726 | F23: -826 | G23: -892 | H23: -1509 | I23: -1483 | J23: -1378 | K23: -1189 | L23: -1293 | M23: -1712 | N23: -1815 | O23: 922 | P23: -683 | Q23: -837 | R23: -1349 | S23: -1665 | T23: -844 | U23: -1650 | V23: -1692 | W23: 232 | X23: -1268 | Y23: -3580 | Z23: -2855 | AA23: -2780 | AB23: -4014 | AC23: -2787 | AD23: -2993 | AE23: -1965 | AF23: -103 | AG23: -2973 | AH23: -2821 | AI23: =Driver!AI48 | AJ23: =Driver!AJ48 | AK23: =Driver!AK48 | AL23: =Driver!AL48 | AM23: =Driver!AM48 | AN23: =Driver!AN48
A24: Profit after tax | B24: =B22+B23 | C24: =C22+C23 | D24: =D22+D23 | E24: =E22+E23 | F24: =F22+F23 | G24: =G22+G23 | H24: =H22+H23 | I24: =I22+I23 | ... AH24: =AH22+AH23 | AI24: =AI27-AI25-AI26 | AJ24: =AJ27-AJ25-AJ26 | AK24: =AK27-AK25-AK26 | AL24: =AL27-AL25-AL26 | AM24: =AM27-AM25-AM26 | AN24: =AN27-AN25-AN26
A25: Minority interests | B25: 0 | C25: 0 | D25: 0 | E25: 0 | F25: 0 | G25: 0 | H25: 0 | I25: 0 | J25: 0 | K25: 0 | L25: 0 | M25: 0 | N25: 0 | O25: 1 | P25: -10 | Q25: -3 | R25: -11 | S25: 7 | T25: -3 | U25: -1 | V25: 20 | W25: -12 | X25: =-563 | Y25: =-846 | Z25: =-850 | AA25: -849 | AB25: -827 | AC25: -885 | AD25: -914 | AE25: -845 | AF25: -424 | AG25: -876 | AH25: -840 | AI25: =-SOC!AI40*30%+CN!AI17+India!AI18 | AJ25: =-SOC!AJ40*30%+CN!AJ17+India!AJ18 | AK25: =-SOC!AK40*30%+CN!AK17+India!AK18 | AL25: =-SOC!AL40*30%+CN!AL17+India!AL18 | AM25: =-SOC!AM40*30%+CN!AM17+India!AM18 | AN25: =-SOC!AN40*30%+CN!AN17+India!AN18
A26: Perpetual capital costs | B26: 0 | C26: 0 | D26: 0 | E26: 0 | F26: 0 | G26: 0 | H26: 0 | I26: 0 | J26: 0 | K26: 0 | L26: 0 | M26: 0 | N26: 0 | O26: 0 | P26: 0 | Q26: 0 | R26: 0 | S26: 0 | T26: 0 | U26: 0 | V26: 0 | W26: 0 | X26: -152 | Y26: -247 | Z26: -247 | AA26: -249 | AB26: -250 | AC26: -212 | AD26: -138 | AE26: -138 | AF26: -139 | AG26: -139 | AH26: -136 | AI26: =AH26 | AJ26: =AI26 | AK26: =AJ26 | AL26: =AK26 | AM26: =AL26 | AN26: =AM26
A27: Net profits (reported) | B27: =B24+B25+B26 | C27: =C24+C25+C26 | D27: =D24+D25+D26 | E27: =E24+E25+E26 | F27: =F24+F25+F26 | G27: =G24+G25+G26 | H27: =H24+H25+H26 | I27: =I24+I25+I26 | ... AH27: =AH24+AH25+AH26 | AI27: =AI31+SUM(AI28:AI30) | AJ27: =AJ31+SUM(AJ28:AJ30) | AK27: =AK31+SUM(AK28:AK30) | AL27: =AL31+SUM(AL28:AL30) | AM27: =AM31+SUM(AM28:AM30) | AN27: =AN31+SUM(AN28:AN30)
A28: Disposal or tax consolidation gains | N28: 0 | O28: 2004 | P28: =343+888-823+204 | Q28: =1030+1146-457-299-126 | R28: =432+127-108+225+389-24 | S28: =-1-16-346-15+171+153+39-131 | T28: 1345 | U28: 876 | V28: 105 | W28: 600 | X28: =1953 | Y28: 6619 | Z28: =643-146+83 | AA28: 0 | AB28: 0 | AC28: 0 | AD28: 0 | AE28: 0 | AF28: 0 | AG28: 0 | AH28: 0 | AI28: 0 | AJ28: 0 | AK28: 0 | AL28: 0 | AM28: 0 | AN28: 0
A29: Write-down of investments | J29: =-130-900 | N29: 0 | T29: -258 | U29: -2125 | V29: -409 | W29: -372 | X29: -158 | Y29: -243 | Z29: -174 | AA29: 0 | AB29: 0 | AC29: 0 | AD29: 0 | AE29: 0 | AF29: 0 | AG29: 0 | AH29: 0 | AI29: 0 | AJ29: 0 | AK29: 0 | AL29: 0 | AM29: 0 | AN29: 0
A30: Other one-offs | D30: 0 | E30: 1286 | H30: =2729.05205003452-1186 | I30: =521.84-2 | J30: 1132 | K30: 1468 | L30: 546 | M30: 240 | N30: 373 | O30: 267 | P30: 44 | T30: -19 | U30: 225 | V30: -790 | W30: -3475 | X30: -636 | Y30: -2239 | Z30: =377-Z28-Z29 | AA30: =369+573-AA29-AA28 | AB30: =18-450-AB29-AB28 | AC30: =-6381-83-AC29-AC28 | AD30: =-121-AD29-AD28 | AE30: =-1026-AE29-AE28 | AF30: =-3699-AF29-AF28 | AG30: =-5597-AG29-AG28 | AH30: =94-AH29-AH28 | AI30: 0 | AJ30: 0 | AK30: 0 | AL30: 0 | AM30: 0 | AN30: 0
A31: Net profits (recurring) | B31: =B27-SUM(B28:B30) | C31: =C27-SUM(C28:C30) | D31: =D27-SUM(D28:D30) | E31: =E27-SUM(E28:E30) | F31: =F27-SUM(F28:F30) | G31: =G27-SUM(G28:G30) | H31: =H27-SUM(H28:H30) | I31: =I27-SUM(I28:I30) | ... AH31: =AH27-SUM(AH28:AH30) | AI31: =Driver!AI58 | AJ31: =Driver!AJ58 | AK31: =Driver!AK58 | AL31: =Driver!AL58 | AM31: =Driver!AM58 | AN31: =Driver!AN58
A32: YoY | C32: =C31/B31-1 | D32: =D31/C31-1 | E32: =E31/D31-1 | F32: =F31/E31-1 | G32: =G31/F31-1 | H32: =H31/G31-1 | I32: =I31/H31-1 | J32: =J31/I31-1 | ... AN32: =AN31/AM31-1
AA33: =5914/AA31 | AB33: =7886/AB31 | AC33: =5474/AC31
A34: EPS (recurring) | B34: =B31/B53 | C34: =C31/C53 | D34: =D31/D53 | E34: =E31/E53 | F34: =F31/F53 | G34: =G31/G53 | H34: =H31/H53 | I34: =I31/I53 | J34: =J31/J53 | K34: =K31/K51 | L34: =L31/L51 | M34: =M31/M51 | N34: =N31/N51 | O34: =O31/O51 | P34: =P31/P51 | Q34: =Q31/Q51 | R34: =R31/R51 | ... AN34: =AN31/AN51
A35: EPS (reported) | B35: =B27/B53 | C35: =C27/C53 | D35: =D27/D53 | E35: =E27/E53 | F35: =F27/F53 | G35: =G27/G53 | H35: =H27/H53 | I35: =I27/I53 | J35: =J27/J53 | K35: =K27/K51 | L35: =L27/L51 | M35: =M27/M51 | N35: =N27/N51 | O35: =O27/O51 | P35: =P27/P51 | Q35: =Q27/Q51 | R35: =R27/R51 | ... AN35: =AN27/AN51
A37: Dividend
A38: Interim ordinary dividend | B38: 1095 | C38: 1294 | D38: 1553 | E38: 1792 | F38: 1911 | G38: 2369 | H38: 2673 | I38: 3582 | J38: 2497 | K38: 2605 | L38: 2746 | M38: 2962 | N38: 3251 | O38: 3468 | P38: 3612 | Q38: 3757 | R38: 3757 | S38: 3753 | T38: =1251*3 | U38: 3753 | V38: 3825 | W38: 4017 | X38: 4093 | Y38: 4169 | Z38: 4320 | AA38: 4472 | AB38: 4623 | AC38: 4775 | AD38: 4775 | AE38: 4775 | AF38: 4775 | AG38: 4775 | AH38: 4775 | AI38: =AH38/AH41*AI41 | AJ38: =AI38/AI41*AJ41 | AK38: =AJ38/AJ41*AK41 | AL38: =AK38/AK41*AL41 | AM38: =AL38/AL41*AM41 | AN38: =AM38/AM41*AN41
A39: Final ordinary dividend | B39: 630 | C39: 697 | D39: 736 | E39: 736 | F39: 876 | G39: 1145 | H39: 1175 | I39: 1041 | J39: 1040 | K39: 1059 | L39: 1228 | M39: 1565 | N39: 1758 | O39: 1999 | P39: 2144 | Q39: 2216 | R39: 2214 | S39: 2214 | T39: 2214 | U39: 2310 | V39: 2476 | W39: 2476 | X39: 2526 | Y39: 2653 | Z39: 2754 | AA39: 2880 | AB39: 3007 | AC39: 3007 | AD39: 3057 | AE39: 3057 | AF39: 3057 | AG39: 3057 | AH39: 3183 | AI39: =AI41-AI38 | AJ39: =AJ41-AJ38 | AK39: =AK41-AK38 | AL39: =AL41-AL38 | AM39: =AM41-AM38 | AN39: =AN41-AN38
A40: Special dividend | B40: 0 | C40: 0 | D40: 0 | E40: 697 | F40: 0 | G40: 0 | H40: =1293+245 | I40: 520 | J40: =562+562 | K40: 1469 | L40: 554 | M40: 241 | N40: 361 | O40: 265 | P40: 48 | Q40: 0 | R40: 0 | S40: 0 | T40: 0 | U40: 0 | V40: 0 | W40: 0 | X40: 0 | Y40: 0 | Z40: 0
A41: Total dividend | B41: =SUM(B38:B40) | C41: =SUM(C38:C40) | D41: =SUM(D38:D40) | E41: =SUM(E38:E40) | F41: =SUM(F38:F40) | G41: =SUM(G38:G40) | H41: =SUM(H38:H40) | I41: =SUM(I38:I40) | ... AH41: =SUM(AH38:AH40) | AI41: =AI48*AI51 | AJ41: =AJ48*AJ51 | AK41: =AK48*AK51 | AL41: =AL48*AL51 | AM41: =AM48*AM51 | AN41: =AN48*AN51
A42: Dividend payout ratio | B42: =B41/B31 | C42: =C41/C31 | D42: =D41/D31 | E42: =E41/E31 | F42: =F41/F31 | G42: =G41/G31 | H42: =H41/H31 | I42: =I41/I31 | ... AN42: =AN41/AN31
A44: DPS
...

Sheet Driver
A1: HK$ m | B1: =Final!B2 | C1: =Final!C2 | D1: =Final!D2 | E1: =Final!E2 | F1: =Final!F2 | G1: =Final!G2 | H1: =Final!H2 | I1: =Final!I2 | ... AN1: =Final!AN2
A2: Income Statements
A3: Revenue
A4: Hong Kong | B4: =SOC!B4 | C4: =SOC!C4 | D4: =SOC!D4 | E4: =SOC!E4 | F4: =SOC!F4 | G4: =SOC!G4 | H4: =SOC!H4 | I4: =SOC!I4 | ... AG4: =SOC!AG4 | AH4: ='HK Sales'!AH8 | AI4: ='HK Sales'!AI8 | AJ4: ='HK Sales'!AJ8 | AK4: ='HK Sales'!AK8 | AL4: ='HK Sales'!AL8 | AM4: ='HK Sales'!AM8 | AN4: ='HK Sales'!AN8
A5: Transfer from development fund | O5: -527 | P5: 202 | Q5: 353 | R5: -193 | S5: -143 | T5: -76 | U5: 586 | V5: -304 | W5: 641 | X5: -1020 | Y5: 181 | Z5: 260 | AA5: 98 | AB5: -322 | AC5: 714 | AD5: 660 | AE5: 1183 | AF5: 604 | AG5: -48 | AH5: 505 | AI5: =SOC!AI23 | AJ5: =SOC!AJ23 | AK5: =SOC!AK23 | AL5: =SOC!AL23 | AM5: =SOC!AM23 | AN5: =SOC!AN23
A6: Australia | B6: =Aus!B5 | C6: =Aus!C5 | D6: =Aus!D5 | E6: =Aus!E5 | F6: =Aus!F5 | G6: =Aus!G5 | H6: =Aus!H5 | I6: =Aus!I5 | ... AN6: =Aus!AN5
A7: China | B7: =CN!B4 | C7: =CN!C4 | D7: =CN!D4 | E7: =CN!E4 | F7: =CN!F4 | G7: =CN!G4 | H7: =CN!H4 | I7: =CN!I4 | ... AN7: =CN!AN4
A8: India | B8: =India!B5 | C8: =India!C5 | D8: =India!D5 | E8: =India!E5 | F8: =India!F5 | G8: =India!G5 | H8: =India!H5 | I8: =India!I5 | ... AN8: =India!AN5
A9: SEA and Taiwan | B9: =SEA!B5 | C9: =SEA!C5 | D9: =SEA!D5 | E9: =SEA!E5 | F9: =SEA!F5 | G9: =SEA!G5 | H9: =SEA!H5 | I9: =SEA!I5 | ... AN9: =SEA!AN5
A10: Others | B10: =B11-SUM(B4:B9) | C10: =C11-SUM(C4:C9) | D10: =D11-SUM(D4:D9) | E10: =E11-SUM(E4:E9) | F10: =F11-SUM(F4:F9) | G10: =G11-SUM(G4:G9) | H10: =H11-SUM(H4:H9) | I10: =I11-SUM(I4:I9) | ... AH10: =AH11-SUM(AH4:AH9) | AI10: =AH10 | AJ10: =AI10 | AK10: =AJ10 | AL10: =AK10 | AM10: =AL10 | AN10: =AM10
A11: Total revenue | B11: =Final!B7 | C11: =Final!C7 | D11: =Final!D7 | E11: =Final!E7 | F11: =Final!F7 | G11: =Final!G7 | H11: =Final!H7 | I11: =Final!I7 | ... AH11: =Final!AH7 | AI11: =SUM(AI4:AI10) | AJ11: =SUM(AJ4:AJ10) | AK11: =SUM(AK4:AK10) | AL11: =SUM(AL4:AL10) | AM11: =SUM(AM4:AM10) | AN11: =SUM(AN4:AN10)
A13: D&A
A14: Hong Kong | O14: =SOC!O10 | P14: =SOC!P10 | Q14: =SOC!Q10 | R14: =SOC!R10 | S14: =SOC!S10 | T14: =SOC!T10 | U14: =SOC!U10 | V14: =SOC!V10 | ... AN14: =SOC!AN10
A15: Australia | B15: =Aus!B15 | C15: =Aus!C15 | D15: =Aus!D15 | E15: =Aus!E15 | F15: =Aus!F15 | G15: =Aus!G15 | H15: =Aus!H15 | I15: =Aus!I15 | ... AN15: =Aus!AN15
A16: China | B16: =CN!B11 | C16: =CN!C11 | D16: =CN!D11 | E16: =CN!E11 | F16: =CN!F11 | G16: =CN!G11 | H16: =CN!H11 | I16: =CN!I11 | ... AN16: =CN!AN11
A17: India | B17: =India!B8 | C17: =India!C8 | D17: =India!D8 | E17: =India!E8 | F17: =India!F8 | G17: =India!G8 | H17: =India!H8 | I17: =India!I8 | ... AD17: =India!AD8 | AE17: -671 | AF17: -283 | AG17: 0 | AH17: 0 | AI17: =India!AI8 | AJ17: =India!AJ8 | AK17: =India!AK8 | AL17: =India!AL8 | AM17: =India!AM8 | AN17: =India!AN8
A18: SEA and Taiwan | B18: =SEA!B9 | C18: =SEA!C9 | D18: =SEA!D9 | E18: =SEA!E9 | F18: =SEA!F9 | G18: =SEA!G9 | H18: =SEA!H9 | I18: =SEA!I9 | ... AN18: =SEA!AN9
A19: Others | B19: =B20-SUM(B14:B18) | C19: =C20-SUM(C14:C18) | D19: =D20-SUM(D14:D18) | E19: =E20-SUM(E14:E18) | F19: =F20-SUM(F14:F18) | G19: =G20-SUM(G14:G18) | H19: =H20-SUM(H14:H18) | I19: =I20-SUM(I14:I18) | ... AH19: =AH20-SUM(AH14:AH18) | AI19: =AH19 | AJ19: =AI19 | AK19: =AJ19 | AL19: =AK19 | AM19: =AL19 | AN19: =AM19
A20: Total Depreciation | B20: =B26-B24 | C20: =C26-C24 | D20: =D26-D24 | E20: =E26-E24 | F20: =F26-F24 | G20: =G26-G24 | H20: =H26-H24 | I20: =I26-I24 | ... AH20: =AH26-AH24 | AI20: =SUM(AI14:AI19) | AJ20: =SUM(AJ14:AJ19) | AK20: =SUM(AK14:AK19) | AL20: =SUM(AL14:AL19) | AM20: =SUM(AM14:AM19) | AN20: =SUM(AN14:AN19)
A22: Australia | B22: =Aus!B14 | C22: =Aus!C14 | D22: =Aus!D14 | E22: =Aus!E14 | F22: =Aus!F14 | G22: =Aus!G14 | H22: =Aus!H14 | I22: =Aus!I14 | ... AN22: =Aus!AN14
A23: China | B23: =CN!B10 | C23: =CN!C10 | D23: =CN!D10 | E23: =CN!E10 | F23: =CN!F10 | G23: =CN!G10 | H23: =CN!H10 | I23: =CN!I10 | ... AN23: =CN!AN10
A24: Total Amortization | B24: =B22+B23 | C24: =C22+C23 | D24: =D22+D23 | E24: =E22+E23 | F24: =F22+F23 | G24: =G22+G23 | H24: =H22+H23 | I24: =I22+I23 | ... AN24: =AN22+AN23
A26: Total D&A | B26: =Final!B12 | C26: =Final!C12 | D26: =Final!D12 | E26: =Final!E12 | F26: =Final!F12 | G26: =Final!G12 | H26: =Final!H12 | I26: =Final!I12 | ... AH26: =Final!AH12 | AI26: =AI20+AI24 | AJ26: =AJ20+AJ24 | AK26: =AK20+AK24 | AL26: =AL20+AL24 | AM26: =AM20+AM24 | AN26: =AN20+AN24
A28: Operating Income before JCEs | B28: =Final!B15 | C28: =Final!C15 | D28: =Final!D15 | E28: =Final!E15 | F28: =Final!F15 | G28: =Final!G15 | H28: =Final!H15 | I28: =Final!I15 | ... AN28: =Final!AN15
A30: JCEs
A31: Hong Kong
A32: Australia | T32: =Aus!T9+Aus!T10 | U32: =Aus!U9+Aus!U10 | V32: =Aus!V9+Aus!V10 | W32: =Aus!W9+Aus!W10 | X32: =Aus!X9+Aus!X10 | Y32: =Aus!Y9+Aus!Y10 | Z32: =Aus!Z9+Aus!Z10 | AA32: =Aus!AA9+Aus!AA10 | ... AN32: =Aus!AN9+Aus!AN10
A33: China | T33: =CN!T6+CN!T7 | U33: =CN!U6+CN!U7 | V33: =CN!V6+CN!V7 | W33: =CN!W6+CN!W7 | X33: =CN!X6+CN!X7 | Y33: =CN!Y6+CN!Y7 | Z33: =CN!Z6+CN!Z7 | AA33: =CN!AA6+CN!AA7 | ... AN33: =CN!AN6+CN!AN7
A34: India | T34: 0 | U34: 0 | V34: 0 | W34: 0 | X34: 0 | Y34: 0 | Z34: 0 | AA34: 0 | AB34: 0 | AC34: 0 | AD34: 0 | AE34: 0 | AF34: 0 | AG34: 0 | AH34: 0 | AI34: 0 | AJ34: 0 | AK34: 0 | AL34: 0 | AM34: 0 | AN34: 0
A35: SEA and Taiwan | T35: =SEA!T7 | U35: =SEA!U7 | V35: =SEA!V7 | W35: =SEA!W7 | X35: =SEA!X7 | Y35: =SEA!Y7 | Z35: =SEA!Z7 | AA35: =SEA!AA7 | ... AN35: =SEA!AN7
A36: Others | T36: =T37-SUM(T32:T35) | U36: =U37-SUM(U32:U35) | V36: =V37-SUM(V32:V35) | W36: =W37-SUM(W32:W35) | X36: =X37-SUM(X32:X35) | Y36: =Y37-SUM(Y32:Y35) | Z36: =Z37-SUM(Z32:Z35) | AA36: =AA37-SUM(AA32:AA35) | ... AH36: =AH37-SUM(AH32:AH35) | AI36: =AH36 | AJ36: =AI36 | AK36: =AJ36 | AL36: =AK36 | AM36: =AL36 | AN36: =AM36
A37: Total earnings from JCEs | B37: =Final!B18+Final!B19 | C37: =Final!C18+Final!C19 | D37: =Final!D18+Final!D19 | E37: =Final!E18+Final!E19 | F37: =Final!F18+Final!F19 | G37: =Final!G18+Final!G19 | H37: =Final!H18+Final!H19 | I37: =Final!I18+Final!I19 | ... AG37: =Final!AG18+Final!AG19 | AH37: 2655 | AI37: =SUM(AI32:AI36) | AJ37: =SUM(AJ32:AJ36) | AK37: =SUM(AK32:AK36) | AL37: =SUM(AL32:AL36) | AM37: =SUM(AM32:AM36) | AN37: =SUM(AN32:AN36)
A38: Earnings from JV | B38: =Final!B18 | C38: =Final!C18 | D38: =Final!D18 | E38: =Final!E18 | F38: =Final!F18 | G38: =Final!G18 | H38: =Final!H18 | I38: =Final!I18 | ... AH38: =Final!AH18 | AI38: =AI37-AI39 | AJ38: =AJ37-AJ39 | AK38: =AK37-AK39 | AL38: =AL37-AL39 | AM38: =AM37-AM39 | AN38: =AN37-AN39
A39: Earnings from Associates | B39: =Final!B19 | C39: =Final!C19 | D39: =Final!D19 | E39: =Final!E19 | F39: =Final!F19 | G39: =Final!G19 | H39: =Final!H19 | I39: =Final!I19 | ... AH39: =Final!AH19 | AI39: =CN!AI7+Aus!AI10 | AJ39: =CN!AJ7+Aus!AJ10 | AK39: =CN!AK7+Aus!AK10 | AL39: =CN!AL7+Aus!AL10 | AM39: =CN!AM7+Aus!AM10 | AN39: =CN!AN7+Aus!AN10
A41: Taxation
A42: Hong Kong | B42: =SOC!B14 | C42: =SOC!C14 | D42: =SOC!D14 | E42: =SOC!E14 | F42: =SOC!F14 | G42: =SOC!G14 | H42: =SOC!H14 | I42: =SOC!I14 | ... AN42: =SOC!AN14
A43: Australia | B43: =Aus!B27 | C43: =Aus!C27 | D43: =Aus!D27 | E43: =Aus!E27 | F43: =Aus!F27 | G43: =Aus!G27 | H43: =Aus!H27 | I43: =Aus!I27 | ... AN43: =Aus!AN27
A44: China | B44: =CN!B16 | C44: =CN!C16 | D44: =CN!D16 | E44: =CN!E16 | F44: =CN!F16 | G44: =CN!G16 | H44: =CN!H16 | I44: =CN!I16 | ... AN44: =CN!AN16
A45: India | B45: =India!B17 | C45: =India!C17 | D45: =India!D17 | E45: =India!E17 | F45: =India!F17 | G45: =India!G17 | H45: =India!H17 | I45: =India!I17 | ... AN45: =India!AN17
A46: SEA and Taiwan | B46: =SEA!B17 | C46: =SEA!C17 | D46: =SEA!D17 | E46: =SEA!E17 | F46: =SEA!F17 | G46: =SEA!G17 | H46: =SEA!H17 | I46: =SEA!I17 | ... AN46: =SEA!AN17
...

Sheet SOC
A1: SoC Income statement
B2: 1992 | C2: 1993 | D2: 1994 | E2: 1995 | F2: 1996 | G2: 1997 | H2: 1998 | I2: 1999R | J2: 2000 | K2: 2001 | L2: 2002 | M2: =Final!M2 | N2: =Final!N2 | O2: =Final!O2 | P2: =Final!P2 | Q2: =Final!Q2 | R2: =Final!R2 | S2: =Final!S2 | T2: =Final!T2 | ... AN2: =Final!AN2
A4: SoC revenues | B4: 13229 | C4: 14573 | D4: 14903 | E4: 16758 | F4: 18295 | G4: 20638 | H4: 22547 | I4: 28642 | J4: 24224 | K4: 24806 | L4: 25844 | M4: 25739 | N4: 26773 | O4: 28836 | P4: 29091 | Q4: 29331 | R4: =23755+6631 | S4: 28437 | T4: 30016 | U4: 30928 | V4: 33944 | W4: 33184 | X4: 36092 | Y4: 38205 | Z4: 37223 | AA4: 39259 | AB4: =32023+9063 | AC4: 40633 | AD4: 41905 | AE4: 45379 | AF4: 51103 | AG4: 50455 | AH4: 50804 | AI4: ='HK Sales'!AI8 | AJ4: ='HK Sales'!AJ8 | AK4: ='HK Sales'!AK8 | AL4: ='HK Sales'!AL8 | AM4: ='HK Sales'!AM8 | AN4: ='HK Sales'!AN8
A6: Fuel costs | B6: -2922 | C6: -3064 | D6: -1923 | E6: -2085 | F6: -2226 | G6: -3045 | H6: -2801 | I6: -3600 | J6: -2912 | K6: -2897 | L6: -3268 | M6: -2901 | N6: -3482 | O6: -4153 | P6: -4363 | Q6: -4905 | R6: =-1744-5024 | S6: -7029 | T6: -7848 | U6: -8784 | V6: -10061 | W6: -9645 | X6: -10375 | Y6: -12682 | Z6: -10978 | AA6: -11901 | AB6: =-10021-3081 | AC6: -13150 | AD6: -13790 | AE6: -15667 | AF6: -21939 | AG6: -20974 | AH6: -19713 | AI6: ='SOC Accounts'!AI69 | AJ6: ='SOC Accounts'!AJ69 | AK6: ='SOC Accounts'!AK69 | AL6: ='SOC Accounts'!AL69 | AM6: ='SOC Accounts'!AM69 | AN6: ='SOC Accounts'!AN69
A7: Operating costs | B7: =-4471-B10 | C7: =-4788-C10 | D7: =-4360-D10 | E7: -2782 | F7: -2747 | G7: -2472 | H7: -2329 | I7: -3098 | J7: -2636 | K7: -2965 | L7: -2848 | M7: -2817 | N7: -3166 | O7: -3106 | P7: -3328 | Q7: -3342 | R7: =-811-2389 | S7: -3102 | T7: -3467 | U7: -3516 | V7: -3698 | W7: -3711 | X7: -3842 | Y7: -4068 | Z7: -4312 | AA7: -4405 | AB7: =-3385-1149 | AC7: -5036 | AD7: -5170 | AE7: -5186 | AF7: -5027 | AG7: -5336 | AH7: -5571 | AI7: ='SOC Accounts'!AI48 | AJ7: ='SOC Accounts'!AJ48 | AK7: ='SOC Accounts'!AK48 | AL7: ='SOC Accounts'!AL48 | AM7: ='SOC Accounts'!AM48 | AN7: ='SOC Accounts'!AN48
A8: Purchase of nuclear power | B8: 0 | C8: 0 | D8: -2841 | E8: -3255 | F8: -3771 | G8: -3683 | H8: -3645 | I8: -4835 | J8: -4587 | K8: -5013 | L8: -4976 | M8: -5134 | N8: -4763 | O8: -5029 | P8: -5040 | Q8: -4971 | R8: =-1088-3943 | S8: -5237 | T8: -5003 | U8: -4879 | V8: -4636 | W8: -4619 | X8: -4867 | Y8: -5203 | Z8: -5198 | AA8: -5380 | AB8: =-4564-979 | AC8: -5643 | AD8: -5582 | AE8: -5678 | AF8: -5822 | AG8: -5802 | AH8: -5800 | AI8: ='SOC Accounts'!AI45 | AJ8: ='SOC Accounts'!AJ45 | AK8: ='SOC Accounts'!AK45 | AL8: ='SOC Accounts'!AL45 | AM8: ='SOC Accounts'!AM45 | AN8: ='SOC Accounts'!AN45
A9: Operating interest | B9: 0 | C9: 0 | D9: 0 | E9: -371 | F9: -410 | G9: -951 | H9: -1131 | I9: -1473 | J9: -1097 | K9: -931 | L9: -617 | M9: -459 | N9: -415 | O9: -543 | P9: -718 | Q9: -739 | R9: =-142-395 | S9: -537 | T9: -677 | U9: -742 | V9: -783 | W9: -863 | X9: -834 | Y9: -940 | Z9: -997 | AA9: -994 | AB9: =-750-246 | AC9: -978 | AD9: -976 | AE9: -857 | AF9: -800 | AG9: -1154 | AH9: -1407 | AI9: =AH9+AH17-AI17 | AJ9: =AI9+AI17-AJ17 | AK9: =AJ9+AJ17-AK17 | AL9: =AK9+AK17-AL17 | AM9: =AL9+AL17-AM17 | AN9: =AM9+AM17-AN17
A10: Depreciation | B10: -1777 | C10: -1893 | D10: -1489 | E10: -1624 | F10: -1797 | G10: -2277 | H10: -2522 | I10: -3360 | J10: -3025 | K10: -3026 | L10: -3164 | M10: -3439 | N10: -3452 | O10: -3746 | P10: -4117 | Q10: -3699 | R10: =-771-2234 | S10: -3149 | T10: -3427 | U10: -3863 | V10: -4146 | W10: -4475 | X10: -3901 | Y10: -4143 | Z10: -4375 | AA10: -4706 | AB10: =-3778-1153 | AC10: -4753 | AD10: -5011 | AE10: -5434 | AF10: -5313 | AG10: -5380 | AH10: -5683 | AI10: =ROAFNA!AI49 | AJ10: =ROAFNA!AJ49 | AK10: =ROAFNA!AK49 | AL10: =ROAFNA!AL49 | AM10: =ROAFNA!AM49 | AN10: =ROAFNA!AN49
A11: Misc | B11: 0 | C11: 0 | D11: 0 | E11: -158 | F11: -279 | G11: =-238-317 | H11: =-23+1 | I11: =-18-91 | J11: -99 | K11: 1 | L11: 0 | M11: -494 | N11: -176 | O11: 0 | P11: =O11 | Q11: =P11 | R11: -60 | S11: -246 | T11: -224 | U11: -282 | V11: -229 | W11: -52 | X11: =10 | Y11: 57 | Z11: 109 | AA11: 56 | AB11: =88-219 | AC11: -188 | AD11: -141 | AE11: -111 | AF11: -73 | AG11: -120 | AH11: -80 | AI11: =AH11 | AJ11: =AI11 | AK11: =AJ11 | AL11: =AK11 | AM11: =AL11 | AN11: =AM11
A12: Total operating expenses | B12: =SUM(B6:B11) | C12: =SUM(C6:C11) | D12: =SUM(D6:D11) | E12: =SUM(E6:E11) | F12: =SUM(F6:F11) | G12: =SUM(G6:G11) | H12: =SUM(H6:H11) | I12: =SUM(I6:I11) | ... AN12: =SUM(AN6:AN11)
A13: Pretax profits | B13: =B4+B12 | C13: =C4+C12 | D13: =D4+D12 | E13: =E4+E12 | F13: =F4+F12 | G13: =G4+G12 | H13: =H4+H12 | I13: =I4+I12 | ... AN13: =AN4+AN12
A14: Taxation | B14: -962 | C14: -1110 | D14: -826 | E14: -1016 | F14: -1135 | G14: -1202 | H14: -1512 | I14: =-1341-378 | J14: -1418 | K14: -1138 | L14: -1478 | M14: -1652 | N14: -1967 | O14: -2102 | P14: -1878 | Q14: -1909 | R14: =-1514-338 | S14: -1554 | T14: -1597 | U14: -1528 | V14: -1772 | W14: -1649 | X14: -2048 | Y14: -1865 | Z14: -1895 | AA14: -1989 | AB14: =-1589-412 | AC14: -1853 | AD14: -1904 | AE14: -2100 | AF14: -1924 | AG14: -1933 | AH14: -2112 | AI14: =-AI13*AI15 | AJ14: =-AJ13*AJ15 | AK14: =-AK13*AK15 | AL14: =-AL13*AL15 | AM14: =-AM13*AM15 | AN14: =-AN13*AN15
A15: Tax rate (%) | B15: =-B14/B13 | C15: =-C14/C13 | D15: =-D14/D13 | E15: =-E14/E13 | F15: =-F14/F13 | G15: =-G14/G13 | H15: =-H14/H13 | I15: =-I14/I13 | ... AH15: =-AH14/AH13 | AI15: =AH15 | AJ15: =AI15 | AK15: =AJ15 | AL15: =AK15 | AM15: =AL15 | AN15: =AM15
A16: Profit after taxation | B16: =B13+B14 | C16: =C13+C14 | D16: =D13+D14 | E16: =E13+E14 | F16: =F13+F14 | G16: =G13+G14 | H16: =H13+H14 | I16: =I13+I14 | ... AN16: =AN13+AN14
A17: Interest on borrowed capital | B17: 455 | C17: 463 | D17: 511 | E17: 813 | F17: 1138 | G17: 1283 | H17: 1246 | I17: 1479 | J17: 1170 | K17: 1005 | L17: 818 | M17: 679 | N17: 679 | O17: 769 | P17: 754 | Q17: 728 | R17: =165+443 | S17: 625 | T17: 763 | U17: 841 | V17: 859 | W17: 887 | X17: 856 | Y17: 920 | Z17: 952 | AA17: 976 | AB17: =266+789 | AC17: 1100 | AD17: 1111 | AE17: 1018 | AF17: 1115 | AG17: 1539 | AH17: 1700 | AI17: =-ROAFNA!AI41 | AJ17: =-ROAFNA!AJ41 | AK17: =-ROAFNA!AK41 | AL17: =-ROAFNA!AL41 | AM17: =-ROAFNA!AM41 | AN17: =-ROAFNA!AN41
A18: Adjustment for performance (incentives)/penaties | S18: -41 | T18: -43 | U18: -45 | V18: -47 | W18: -48 | X18: -49 | Y18: -51 | Z18: -53 | AA18: -54 | AB18: =-16-89 | AC18: -392 | AD18: -416 | AE18: -438 | AF18: -448 | AG18: -642 | AH18: -481 | AI18: =+AH18 | AJ18: =+AI18 | AK18: =+AJ18 | AL18: =+AK18 | AM18: =+AL18 | AN18: =+AM18
A19: Increase in customer deposits | I19: =2+1 | J19: 10 | K19: 8 | L19: 1 | M19: 0 | N19: 0 | O19: 12 | P19: 35 | Q19: 33 | R19: 2 | S19: 0 | T19: 0 | U19: 0 | V19: =U19 | W19: =V19 | X19: =W19 | Y19: =X19 | Z19: =Y19 | AA19: 0 | AB19: 1 | AC19: 4 | AD19: 0 | AE19: =AD19 | AF19: 4 | AG19: 37 | AH19: 39 | AI19: 0 | AJ19: 0 | AK19: 0 | AL19: 0 | AM19: 0 | AN19: 0
A20: China sales | B20: -211 | C20: -246 | D20: -79 | E20: -78 | F20: -19 | G20: -22 | H20: =G20 | I20: =-21-4 | J20: -16 | K20: -69 | L20: -5 | M20: 367 | N20: 35 | O20: -188 | P20: -186 | Q20: -160 | R20: =-92-33 | S20: -115 | T20: -73 | U20: -62 | V20: -43 | W20: -64 | X20: -54 | Y20: -68 | Z20: -69 | AA20: -79 | AB20: -43 | AC20: 0 | AD20: =AC20 | AE20: =AD20 | AF20: =AE20 | AG20: 0 | AH20: =AG20 | AI20: =AH20 | AJ20: =AI20 | AK20: =AJ20 | AL20: =AK20 | AM20: =AL20 | AN20: =AM20
A21: SoC net income | B21: =SUM(B16:B20) | C21: =SUM(C16:C20) | D21: =SUM(D16:D20) | E21: =SUM(E16:E20) | F21: =SUM(F16:F20) | G21: =SUM(G16:G20) | H21: =SUM(H16:H20) | I21: =SUM(I16:I20) | ... AN21: =SUM(AN16:AN20)
A22: Charge for asset decommissioning | B22: 0 | C22: 0 | D22: 0 | E22: 0 | F22: 0 | G22: 0 | H22: 0 | I22: 0 | J22: 0 | K22: 0 | L22: 0 | M22: 0 | N22: 0 | O22: 0 | P22: 0 | Q22: 0 | R22: 0 | S22: 0 | T22: 0 | U22: 0 | V22: 0 | W22: 0 | X22: 0 | Y22: 0 | Z22: 0 | AA22: 0 | AB22: 0 | AC22: 0 | AD22: 0 | AE22: 0 | AF22: 0 | AG22: 0 | AH22: 0 | AI22: 0 | AJ22: 0 | AK22: 0 | AL22: 0 | AM22: 0 | AN22: 0
A23: Transfer from/(to) development fund | B23: =B25-B21-B22 | C23: =C25-C21-C22 | D23: =D25-D21-D22 | E23: =E25-E21-E22 | F23: =F25-F21-F22 | G23: =G25-G21-G22 | H23: =H25-H21-H22 | I23: =I25-I21-I22 | ... AH23: =AH25-AH21-AH22 | AI23: =MIN(AI25-AI21-AI22,('SOC Accounts'!AH21+'SOC Accounts'!AI20+'SOC Accounts'!AI19)) | AJ23: =MIN(AJ25-AJ21-AJ22,('SOC Accounts'!AI21+'SOC Accounts'!AJ20+'SOC Accounts'!AJ19)) | AK23: =MIN(AK25-AK21-AK22,('SOC Accounts'!AJ21+'SOC Accounts'!AK20+'SOC Accounts'!AK19)) | AL23: =MIN(AL25-AL21-AL22,('SOC Accounts'!AK21+'SOC Accounts'!AL20+'SOC Accounts'!AL19)) | AM23: =MIN(AM25-AM21-AM22,('SOC Accounts'!AL21+'SOC Accounts'!AM20+'SOC Accounts'!AM19)) | AN23: =MIN(AN25-AN21-AN22,('SOC Accounts'!AM21+'SOC Accounts'!AN20+'SOC Accounts'!AN19))
A24: Transfer from/(to) development fund (theoretical) | V24: =V25-V21-V22-V23 | W24: =W25-W21-W22-W23 | X24: =X25-X21-X22-X23 | Y24: =Y25-Y21-Y22-Y23 | Z24: =Z25-Z21-Z22-Z23 | AA24: =AA25-AA21-AA22-AA23 | AB24: =AB25-AB21-AB22-AB23 | AC24: 0 | AD24: =+AC24 | AE24: =+AD24 | AF24: =+AE24 | AG24: =+AF24 | AH24: =+AG24 | AI24: =+AH24 | AJ24: =+AI24 | AK24: =+AJ24 | ... AN24: =+AM24
A25: Permitted return | B25: =ROAFNA!B14 | C25: =ROAFNA!C14 | D25: =ROAFNA!D14 | E25: =ROAFNA!E14 | F25: =ROAFNA!F14 | G25: =ROAFNA!G14 | H25: =ROAFNA!H14 | I25: =ROAFNA!I14 | ... AN25: =ROAFNA!AN14
A26: Interest on borrowed capital | B26: =-B17 | C26: =-C17 | D26: =-D17 | E26: =-E17 | F26: =-F17 | G26: =-G17 | H26: =-H17 | I26: =-I17 | ... AN26: =-AN17
A27: Adjustment for performance incentives/penaties | S27: =-S18 | T27: =-T18 | U27: =-U18 | V27: =-V18 | W27: =-W18 | X27: =-X18 | Y27: =-Y18 | Z27: =-Z18 | ... AN27: =-AN18
A28: Interest on increase in customers deposits | B28: 0 | C28: 0 | D28: 0 | E28: 0 | F28: 0 | G28: 0 | H28: 0 | I28: -3 | J28: =-J19 | K28: =-K19 | L28: =-L19 | M28: =-M19 | N28: =-N19 | O28: =-O19 | P28: =-P19 | Q28: =-Q19 | ... AN28: =-AN19
A29: Transfer to special provision account | B29: 0 | C29: 0 | D29: 0 | E29: 0 | F29: 0 | G29: 0 | H29: 0 | I29: 0 | J29: 0 | K29: 0 | L29: 0 | M29: 0 | N29: 0 | O29: 0 | P29: 0 | Q29: 0 | R29: 0 | S29: 0 | T29: 0 | U29: 0 | V29: =U29 | W29: =V29 | X29: =W29 | Y29: =X29 | Z29: =Y29 | AA29: =Z29 | AB29: =AA29 | AC29: =AB29 | ... AN29: =AM29
A30: Transfer to rate reduction reserve | B30: -243 | C30: -283 | D30: -272 | E30: -215 | F30: -174 | G30: -134 | H30: -158 | I30: -290 | J30: -280 | K30: -305 | L30: -319 | M30: -287 | N30: -253 | O30: -274 | P30: -265 | Q30: -202 | R30: -132 | S30: -3 | T30: -3 | U30: -2 | V30: -2 | W30: -1 | X30: 8 | Y30: -2 | Z30: -2 | AA30: -4 | AB30: =-4-7 | AC30: -22 | AD30: -18 | AE30: -3 | AF30: -40 | AG30: -114 | AH30: -124 | AI30: =-'SOC Accounts'!AI32 | AJ30: =-'SOC Accounts'!AJ32 | AK30: =-'SOC Accounts'!AK32 | AL30: =-'SOC Accounts'!AL32 | AM30: =-'SOC Accounts'!AM32 | AN30: =-'SOC Accounts'!AN32
A31: Net return | B31: =SUM(B25:B30) | C31: =SUM(C25:C30) | D31: =SUM(D25:D30) | E31: =SUM(E25:E30) | F31: =SUM(F25:F30) | G31: =SUM(G25:G30) | H31: =SUM(H25:H30) | I31: =SUM(I25:I30) | J31: =SUM(J25:J30)+J32 | K31: =SUM(K25:K30) | L31: =SUM(L25:L30) | M31: =SUM(M25:M30) | N31: =SUM(N25:N30) | O31: =SUM(O25:O30) | P31: =SUM(P25:P30) | Q31: =SUM(Q25:Q30) | R31: =SUM(R25:R30) | ... W31: =SUM(W25:W30) | X31: =SUM(X26:X30)+MIN(X21,X25) | Y31: =SUM(Y26:Y30)+MIN(SUM(Y21:Y24),Y25) | Z31: =SUM(Z26:Z30)+MIN(SUM(Z21:Z24),Z25) | AA31: =SUM(AA26:AA30)+MIN(SUM(AA21:AA24),AA25) | AB31: =SUM(AB26:AB30)+MIN(SUM(AB21:AB24),AB25) | AC31: =SUM(AC26:AC30)+MIN(SUM(AC21:AC24),AC25) | AD31: =SUM(AD26:AD30)+MIN(SUM(AD21:AD24),AD25) | AE31: =SUM(AE26:AE30)+MIN(SUM(AE21:AE24),AE25) | AF31: =SUM(AF26:AF30)+MIN(SUM(AF21:AF24),AF25) | ... AN31: =SUM(AN26:AN30)+MIN(SUM(AN21:AN24),AN25)
A32: Contribution to CESF / EEF | AA32: -22 | AB32: =-16-48 | AC32: -195 | AD32: -201 | AE32: -208 | AF32: -218 | AG32: -230 | AH32: -238 | AI32: =AI18*AH32/AH18 | AJ32: =AJ18*AI32/AI18 | AK32: =AK18*AJ32/AJ18 | AL32: =AL18*AK32/AK18 | AM32: =AM18*AL32/AL18 | AN32: =AN18*AM32/AM18
A33: Net return | AA33: =SUM(AA31:AA32) | AB33: =SUM(AB31:AB32) | AC33: =SUM(AC31:AC32) | AD33: =SUM(AD31:AD32) | AE33: =SUM(AE31:AE32) | AF33: =SUM(AF31:AF32) | AG33: =SUM(AG31:AG32) | AH33: =SUM(AH31:AH32) | ... AN33: =SUM(AN31:AN32)
AC34: =AC33/AB33-1 | AD34: =AD33/AC33-1 | AE34: =AE33/AD33-1 | AF34: =AF33/AE33-1 | AG34: =AG33/AF33-1 | AH34: =AH33/AG33-1 | AI34: =AI33/AH33-1 | AJ34: =AJ33/AI33-1 | ... AN34: =AN33/AM33-1
A35: Profits split between CLP and CAPCO
A36: CLP Power HK portion (%) | B36: =B39/B$41 | C36: =C39/C$41 | D36: =D39/D$41 | E36: =E39/E$41 | F36: =F39/F$41 | G36: =G39/G$41 | H36: =H39/H$41 | I36: =I39/I$41 | ... AH36: =AH39/AH$41 | AI36: =AH36+0.005 | AJ36: =AI36+0.005 | AK36: =AJ36+0.005 | AL36: =AK36+0.005 | AM36: =AL36+0.005 | AN36: =AM36+0.005
A37: CAPCO portion (%) | B37: =B40/B$41 | C37: =C40/C$41 | D37: =D40/D$41 | E37: =E40/E$41 | F37: =F40/F$41 | G37: =G40/G$41 | H37: =H40/H$41 | I37: =I40/I$41 | ... O37: =O40/O$41 | P37: =1-P36 | Q37: =1-Q36 | R37: =1-R36 | S37: =1-S36 | T37: =1-T36 | U37: =1-U36 | V37: =1-V36 | W37: =1-W36 | ... AN37: =1-AN36
A39: CLP Power HK (T&D) | B39: 2048 | C39: 2320 | D39: 2629 | E39: 2973 | F39: 3265 | G39: 3514 | H39: 3712 | I39: =960+3803 | J39: 3955 | K39: 4188 | L39: 4517 | M39: 4895 | N39: 5363 | O39: 5626 | P39: 5878 | Q39: 6242 | R39: =1174+5041 | S39: 4894 | T39: 4985 | U39: 5139 | V39: 5425 | W39: 5744 | X39: 6070 | Y39: 6319 | Z39: 6547 | AA39: 6763 | AB39: =5149+1369 | AC39: 5582 | AD39: 5769 | AE39: 6078 | AF39: 6239 | AG39: 6351 | AH39: 6536 | AI39: =AI$33*AI36 | AJ39: =AJ$33*AJ36 | AK39: =AK$33*AK36 | AL39: =AL$33*AL36 | AM39: =AM$33*AM36 | AN39: =AN$33*AN36
A40: CAPCO (Generation) | B40: 1999 | C40: 2137 | D40: 2466 | E40: 2726 | F40: 2965 | G40: 3104 | H40: 3137 | I40: =3115+758 | J40: 2969 | K40: 3074 | L40: 3232 | M40: 3456 | N40: 3552 | O40: 3542 | P40: 3520 | Q40: 3515 | R40: =2710+618 | S40: 2674 | T40: 2860 | U40: 2999 | V40: 3074 | W40: 3054 | X40: 3080 | Y40: 3096 | Z40: 3110 | AA40: 3114 | AB40: =2367+654 | AC40: 2707 | AD40: 2824 | AE40: 2985 | AF40: 3177 | AG40: 3229 | AH40: 3115 | AI40: =AI$33*AI37 | AJ40: =AJ$33*AJ37 | AK40: =AK$33*AK37 | AL40: =AL$33*AL37 | AM40: =AM$33*AM37 | AN40: =AN$33*AN37
A41: Total net return | B41: =SUM(B39:B40) | C41: =SUM(C39:C40) | D41: =SUM(D39:D40) | E41: =SUM(E39:E40) | F41: =SUM(F39:F40) | G41: =SUM(G39:G40) | H41: =SUM(H39:H40) | I41: =SUM(I39:I40) | ... AN41: =SUM(AN39:AN40)
A43: CLP's portion in CAPCO | B43: =B45/B40 | C43: =C45/C40 | D43: =D45/D40 | E43: =E45/E40 | F43: =F45/F40 | G43: =G45/G40 | H43: =H45/H40 | I43: =I45/I40 | ... AH43: =AH45/AH40 | AI43: =AH43 | AJ43: =AI43 | AK43: =AJ43 | AL43: =AK43 | AM43: =AL43 | AN43: =AM43
A44: CLP's share in CLP Power HK | B44: =B39 | C44: =C39 | D44: =D39 | E44: =E39 | F44: =F39 | G44: =G39 | H44: =H39 | I44: =I39 | ... M44: =M39 | N44: 5363 | O44: 5626 | P44: =P39 | Q44: =Q39 | R44: =R39 | S44: =S39 | T44: =T39 | U44: =U39 | V44: =V39 | W44: =W39 | ... Z44: =Z39 | AA44: 6763 | AB44: =AB39 | AC44: 5582 | AD44: 5769 | AE44: 6078 | AF44: 6239 | AG44: 6351 | AH44: 6536 | AI44: =AI39 | AJ44: =AJ39 | AK44: =AK39 | AL44: =AL39 | AM44: =AM39 | AN44: =AN39
...

Sheet HK Sales
A1: CLP Scheme of Control Revenue | AQ1: Quarterly Sales
A2: Electricity Revenue: | B2: 1992 | C2: 1993 | D2: 1994 | E2: 1995 | F2: 1996 | G2: =Final!G2 | H2: =Final!H2 | I2: =Final!I2 | J2: =Final!J2 | K2: =Final!K2 | L2: =Final!L2 | M2: =Final!M2 | N2: =Final!N2 | ... AN2: =Final!AN2 | AR2: Q116 | AS2: Q117
A3: Gross electricity revenue (Basic tariff x GWh) | B3: =B36*B13/100 | C3: =C36*C13/100 | D3: =D36*D13/100 | E3: =E36*E13/100 | F3: =F36*F13/100 | G3: =G36*G13/100 | H3: =H36*H13/100 | I3: =I36*I13/100 | ... AN3: =AN36*AN13/100 | AQ3: Residential | AR3: =AS3+210 | AS3: =AS11*$AS$8
A4: Transfer from (to) fuel cost adjustment | B4: =+'SOC Accounts'!B5 | C4: =+'SOC Accounts'!C5 | D4: =+'SOC Accounts'!D5 | E4: =+'SOC Accounts'!E5 | F4: =+'SOC Accounts'!F5 | G4: =+'SOC Accounts'!G5 | H4: =+'SOC Accounts'!H5 | I4: =+'SOC Accounts'!I5 | ... AN4: =+'SOC Accounts'!AN5 | AQ4: Commercial | AR4: =AS4-23 | AS4: =AS12*$AS$8
A5: Export to China | B5: =+B6-B3-B4 | C5: =+C6-C3-C4 | D5: =+D6-D3-D4 | E5: =+E6-E3-E4 | F5: =+F6-F3-F4 | G5: =+G6-G3-G4 | H5: =+H6-H3-H4 | I5: =+I6-I3-I4 | ... AH5: =+AH6-AH3-AH4 | AI5: =AI29*AI37 | AJ5: =AJ29*AJ37 | AK5: =AK29*AK37 | AL5: =AL29*AL37 | AM5: =AM29*AM37 | AN5: =AN29*AN37 | AQ5: Infrastructure & Public Services | AR5: =AS5-66 | AS5: =AS13*$AS$8
A6: Sales of electricity | B6: =+#REF! | C6: =+#REF! | D6: =+#REF! | E6: =+#REF! | F6: =+F8-F7 | G6: =+G8-G7 | H6: =+H8-H7 | I6: =+I8-I7 | J6: 24163 | K6: 24725 | L6: 25770 | M6: 25677 | N6: 26661 | O6: 28750 | P6: 29004 | Q6: 29236 | R6: 30288 | S6: 28349 | T6: 29917 | U6: 30824 | V6: 33842 | W6: 33064 | X6: 35969 | Y6: 38087 | Z6: 37120 | AA6: 39161 | AB6: 40982 | AC6: 40473 | AD6: 41798 | AE6: 45222 | AF6: 50919 | AG6: 50288 | AH6: 50649 | AI6: =SUM(AI3:AI5) | AJ6: =SUM(AJ3:AJ5) | AK6: =SUM(AK3:AK5) | AL6: =SUM(AL3:AL5) | AM6: =SUM(AM3:AM5) | AN6: =SUM(AN3:AN5) | AQ6: Manufacturing | AR6: =AS6-3 | AS6: =AS14*$AS$8
A7: Sundry income | B7: 60 | C7: 26 | D7: 22 | E7: 25 | F7: 27 | G7: 36 | H7: 56 | I7: 92 | J7: =J8-J6 | K7: =K8-K6 | L7: =L8-L6 | M7: =M8-M6 | N7: =N8-N6 | O7: =O8-O6 | P7: =P8-P6 | Q7: =Q8-Q6 | ... AG7: =AG8-AG6 | AH7: =AG7 | AI7: =AH7 | AJ7: =AI7 | AK7: =AJ7 | AL7: =AK7 | AM7: =AL7 | AN7: =AM7
A8: Total SOC revenue | B8: =SOC!B4 | C8: =SOC!C4 | D8: =SOC!D4 | E8: =SOC!E4 | F8: =SOC!F4 | G8: =SOC!G4 | H8: =SOC!H4 | I8: =SOC!I4 | ... AG8: =SOC!AG4 | AH8: =+AH6+AH7 | AI8: =+AI6+AI7 | AJ8: =+AJ6+AJ7 | AK8: =+AK6+AK7 | AL8: =+AL6+AL7 | AM8: =+AM6+AM7 | AN8: =+AN6+AN7 | AQ8: Total | AR8: =SUM(AR3:AR7) | AS8: 6512
A9: YoY | C9: =C8/B8-1 | D9: =D8/C8-1 | E9: =E8/D8-1 | F9: =F8/E8-1 | G9: =G8/F8-1 | H9: =H8/G8-1 | I9: =4/5*I8/H8-1 | J9: =J8/(4/5*I8)-1 | K9: =K8/J8-1 | L9: =L8/K8-1 | M9: =M8/L8-1 | N9: =N8/M8-1 | O9: =O8/N8-1 | P9: =P8/O8-1 | Q9: =Q8/P8-1 | R9: =R8/Q8-1 | ... AN9: =AN8/AM8-1 | AQ9: China | AS9: 174
A11: Actual Tariffs at Year End (Cents per kWh) | AQ11: Residential | AR11: =AR3/$AR$8 | AS11: 0.24
AQ12: Commercial | AR12: =AR4/$AR$8 | AS12: 0.42
A13: Basic Tariff | B13: 63.81 | C13: 65.85 | D13: 71.96 | E13: 77.31 | F13: 82.42 | G13: 86.35 | H13: 89.09 | I13: 89.15 | J13: 88.57 | K13: 88.6 | L13: 88.5 | M13: 88.4 | N13: 88.1 | O13: 88.2 | P13: 88 | Q13: 88.1 | R13: 85.6 | S13: 77.5 | T13: 80.1 | U13: 80 | V13: 84.2 | W13: 84 | X13: 88.6 | Y13: 87.1 | Z13: 88.9 | AA13: 92.2 | AB13: =94.5*0.75+91*0.25 | AC13: 91 | AD13: 92.3 | AE13: 93.6 | AF13: 93.3 | AG13: 93.1 | AH13: 95.8 | AI13: =AH13*(1+AI14) | AJ13: =AI13*(1+AJ14) | AK13: =AJ13*(1+AK14) | AL13: =AK13*(1+AL14) | AM13: =AL13*(1+AM14) | AN13: =AM13*(1+AN14) | AQ13: Infrastructure & Public Services | AR13: =AR5/$AR$8 | AS13: 0.28
A14: YoY | C14: =(D13/C13)-1 | D14: =(E13/D13)-1 | E14: =(E13/D13)-1 | F14: =(F13/E13)-1 | G14: =(G13/F13)-1 | H14: =(H13/G13)-1 | I14: =(I13/H13)-1 | J14: =(J13/I13)-1 | K14: =(K13/J13)-1 | L14: =(L13/K13)-1 | ... AH14: =(AH13/AG13)-1 | AI14: 0.02 | AJ14: =AI14 | AK14: =AJ14 | AL14: =AK14 | AM14: =AL14 | AN14: =AM14 | AQ14: Manufacturing | AR14: =AR6/$AR$8 | AS14: 0.06
A15: Special rebates | D15: -1.93 | G15: -0.73 | H15: -1.82 | I15: -2.2 | J15: =I15 | K15: =J15 | L15: =K15 | M15: =L15 | N15: 0 | O15: =N15 | P15: -1.8 | Q15: -1.8 | R15: -1.6 | S15: 0 | T15: 0 | U15: 0 | V15: 0 | W15: 0 | X15: 0 | Y15: 0 | Z15: 0 | AA15: 0 | AB15: =AA15 | AC15: =AB15 | AD15: 0 | AE15: 0 | AF15: =AF22/AF36*100 | AG15: =AG22/AG36*100 | AH15: =AH22/AH36*100 | AI15: =AH15 | AJ15: =AI15 | AK15: =AJ15 | AL15: =AK15 | AM15: =AL15 | AN15: =AM15 | AQ15: Total | AR15: =SUM(AR11:AR14) | AS15: =SUM(AS11:AS14)
A16: Fuel Clause Charge/(Rebate) | B16: -3.36 | C16: -2.5 | D16: -3.79 | E16: -4.5 | F16: -4.5 | G16: -1.27 | H16: 0.99 | I16: 2.2 | J16: 2.2 | K16: =J16 | L16: 1.9 | M16: 1.9 | N16: -0.3 | O16: 0.2 | P16: 2 | Q16: =P16 | R16: 7.3 | S16: 11.8 | T16: 11.5 | U16: 14.1 | V16: 17.8 | W16: 22.4 | X16: 22.4 | Y16: =27-3.8 | Z16: 24.3 | AA16: 21 | AB16: =22*0.75+27.8*0.25 | AC16: 27.8 | AD16: 28.4 | AE16: 30.2 | AF16: 46.1 | AG16: 58.4 | AH16: 44.3 | AI16: =AH16 | AJ16: =+AI16 | AK16: =+AJ16 | AL16: =+AK16 | AM16: =+AL16 | AN16: =+AM16
A17: Rate Reduction Rebate | B17: -1.17 | C17: -1.6 | D17: -1.6 | E17: -0.96 | F17: -0.6 | G17: -0.6 | H17: -0.6 | I17: -0.6 | J17: -0.6 | K17: -0.6 | L17: -0.6 | M17: -0.6 | N17: -0.6 | O17: -1.1 | P17: =O17 | Q17: =P17 | R17: -0.8 | S17: -0.2 | T17: 0 | U17: 0 | V17: 0 | W17: 0 | X17: 0 | Y17: 0 | Z17: 0 | AA17: 0 | AB17: 0 | AC17: 0 | AD17: 0 | AE17: 0 | AF17: 0 | AG17: 0 | AH17: 0 | AI17: 0 | AJ17: 0 | AK17: 0 | AL17: 0 | AM17: 0 | AN17: 0 | AQ17: YoY
A18: Rent & Rates Special Rebate | V18: -3.3 | W18: -1.7 | X18: 0 | Y18: 0 | Z18: 0 | AA18: 0 | AB18: -1.1 | AC18: -0.1 | AD18: -1.2 | AE18: 0 | AF18: -1.3 | AG18: -0.4 | AH18: 0 | AI18: 0 | AJ18: 0 | AK18: 0 | AL18: 0 | AM18: 0 | AN18: 0 | AQ18: Residential | AS18: =AS3/AR3-1
A19: Net Tariff | B19: =B13+SUM(B15:B18) | C19: =C13+SUM(C15:C18) | D19: =D13+SUM(D15:D18) | E19: =E13+SUM(E15:E18) | F19: =F13+SUM(F15:F18) | G19: =G13+SUM(G15:G18) | H19: =H13+SUM(H15:H18) | I19: =I13+SUM(I15:I18) | ... AN19: =AN13+SUM(AN15:AN18) | AQ19: Commercial | AS19: =AS4/AR4-1
A20: YoY | C20: =(C19/B19)-1 | D20: =(D19/C19)-1 | E20: =(E19/D19)-1 | F20: =(F19/E19)-1 | G20: =(G19/F19)-1 | H20: =(H19/G19)-1 | I20: =(I19/H19)-1 | J20: =(J19/I19)-1 | ... AN20: =(AN19/AM19)-1 | AQ20: Infrastructure & Public Services | AS20: =AS5/AR5-1
AQ21: Manufacturing | AS21: =AS6/AR6-1
A22: Total value of special rebate | B22: =B15*B36/100 | C22: =C15*C36/100 | D22: =D15*D36/100 | E22: =E15*E36/100 | F22: =F15*F36/100 | G22: =G15*G36/100 | H22: =H15*H36/100 | I22: =I15*I36/100 | J22: =J15*J36/100-387 | K22: =K15*K36/100-340-609 | L22: =-(558+41+626) | M22: -910 | N22: =8-1-15 | O22: -13 | P22: -551 | Q22: -462 | R22: -494 | S22: 0 | T22: 0 | U22: =U15*U36/100 | V22: =V15*V36/100 | W22: =W15*W36/100 | X22: =X15*X36/100 | Y22: =Y15*Y36/100 | Z22: =Z15*Z36/100 | AA22: =AA15*AA36/100 | AB22: =AB15*AB36/100 | ... AE22: =AE15*AE36/100 | AF22: -715 | AG22: -271 | AH22: -20 | AI22: =AI15*AI36/100 | AJ22: =AJ15*AJ36/100 | AK22: =AK15*AK36/100 | AL22: =AL15*AL36/100 | AM22: =AM15*AM36/100 | AN22: =AN15*AN36/100 | AQ22: Total | AS22: =AS8/AR8-1
A23: Total value of rate reduction rebate | B23: =B17*B36/100 | C23: =C17*C36/100 | D23: =D17*D36/100 | E23: =E17*E36/100 | F23: =F17*F36/100 | G23: =G17*G36/100 | H23: =H17*H36/100 | I23: =I17*I36/100 | J23: =J17*J36/100 | K23: =K17*K36/100-99 | L23: =L17*L36/100-5 | M23: =M17*M36/100-5 | N23: =N17*N36/100-5 | O23: -334 | P23: -340 | Q23: =-94-339 | R23: =-246+1 | S23: =0-72 | T23: 0 | U23: =U17*U36/100 | V23: =V17*V36/100 | W23: =W17*W36/100 | X23: =X17*X36/100 | Y23: =Y17*Y36/100 | Z23: =Z17*Z36/100 | AA23: =AA17*AA36/100 | AB23: =AB17*AB36/100 | ... AN23: =AN17*AN36/100
A25: Check: tariff stablisation fund | B25: ='SOC Accounts'!B21 | C25: ='SOC Accounts'!C21 | D25: ='SOC Accounts'!D21 | E25: ='SOC Accounts'!E21 | F25: ='SOC Accounts'!F21 | G25: ='SOC Accounts'!G21 | H25: ='SOC Accounts'!H21 | I25: ='SOC Accounts'!I21 | ... AN25: ='SOC Accounts'!AN21
A26: Check: fuel clause account (neg is payable) | B26: ='SOC Accounts'!B7 | C26: ='SOC Accounts'!C7 | D26: ='SOC Accounts'!D7 | E26: ='SOC Accounts'!E7 | F26: ='SOC Accounts'!F7 | G26: ='SOC Accounts'!G7 | H26: ='SOC Accounts'!H7 | I26: ='SOC Accounts'!I7 | ... AN26: ='SOC Accounts'!AN7
A27: Check: rate reduction reserve | B27: ='SOC Accounts'!B34 | C27: ='SOC Accounts'!C34 | D27: ='SOC Accounts'!D34 | E27: ='SOC Accounts'!E34 | F27: ='SOC Accounts'!F34 | G27: ='SOC Accounts'!G34 | H27: ='SOC Accounts'!H34 | I27: ='SOC Accounts'!I34 | ... AN27: ='SOC Accounts'!AN34
A29: Implied export tariff/kWh | B29: =#REF!/B37 | C29: =#REF!/C37 | D29: =#REF!/D37 | E29: =#REF!/E37 | F29: =#REF!/F37 | G29: =#REF!/G37 | H29: =#REF!/H37 | I29: =#REF!/I37 | J29: =J5/J37 | K29: =K5/K37 | L29: =L5/L37 | M29: =M5/M37 | N29: =N5/N37 | O29: =O5/O37 | P29: =P5/P37 | Q29: =Q5/Q37 | ... AB29: =AB5/AB37 | AC29: 0 | AD29: =AC29 | AE29: =AD29 | AF29: =AE29 | AG29: =AF29 | AH29: =AG29 | AI29: =AH29 | AJ29: =AI29 | AK29: =AJ29 | ... AN29: =AM29
A31: Demand (Gwh)
A32: Commercial | B32: 6071 | C32: 6567 | D32: 7096 | E32: 7603 | F32: 8038 | G32: 8542 | H32: 9157 | I32: 11785 | J32: 10014 | K32: 10378 | L32: 10661 | M32: 10698 | N32: 11086 | O32: 11428 | P32: 11957 | Q32: 12144 | R32: 12312 | S32: 12488 | T32: 12642 | U32: 12670 | V32: 12917 | W32: 12935 | X32: 13099 | Y32: 13209 | Z32: 13234 | AA32: 13220 | AB32: 13425 | AC32: 13584 | AD32: 12878 | AE32: 13423 | AF32: 13233 | AG32: 13673 | AH32: 13882 | AI32: =AH32*(1+AI41) | AJ32: =AI32*(1+AJ41) | AK32: =AJ32*(1+AK41) | AL32: =AK32*(1+AL41) | AM32: =AL32*(1+AM41) | AN32: =AM32*(1+AN41)
A33: Domestic | B33: 4195 | C33: 4733 | D33: 5024 | E33: 5382 | F33: 5723 | G33: 5811 | H33: 6524 | I33: 7854 | J33: 6608 | K33: 6752 | L33: 6930 | M33: 7180 | N33: 7149 | O33: 7525 | P33: 7469 | Q33: 7724 | R33: 7890 | S33: 8331 | T33: 8457 | U33: 8594 | V33: 8900 | W33: 8658 | X33: 9450 | Y33: 9228 | Z33: 9394 | AA33: 9217 | AB33: 9191 | AC33: 9451 | AD33: 10298 | AE33: 10525 | AF33: 10113 | AG33: 9929 | AH33: 10204 | AI33: =AH33*(1+AI42) | AJ33: =AI33*(1+AJ42) | AK33: =AJ33*(1+AK42) | AL33: =AK33*(1+AL42) | AM33: =AL33*(1+AM42) | AN33: =AM33*(1+AN42)
A34: Industrial | B34: 5170 | C34: 4915 | D34: 4654 | E34: 4344 | F34: 4162 | G34: 3928 | H34: 3776 | I34: 4270 | J34: 3488 | K34: 3245 | L34: 3085 | M34: 2856 | N34: 2833 | O34: 2734 | P34: 2653 | Q34: 2418 | R34: 2202 | S34: 1938 | T34: 1952 | U34: 1886 | V34: 1890 | W34: 1832 | X34: 1791 | Y34: 1791 | Z34: 1751 | AA34: 1740 | AB34: 1704 | AC34: 1663 | AD34: 1616 | AE34: 1665 | AF34: 1615 | AG34: 1594 | AH34: 1573 | AI34: =AH34*(1+AI43) | AJ34: =AI34*(1+AJ43) | AK34: =AJ34*(1+AK43) | AL34: =AK34*(1+AL43) | AM34: =AL34*(1+AM43) | AN34: =AM34*(1+AN43)
A35: Government & others | B35: 3368 | C35: 3607 | D35: 3808 | E35: 4059 | F35: 4395 | G35: 4736 | H35: 5424 | I35: 7207 | J35: 6197 | K35: 6575 | L35: 7036 | M35: 7301 | N35: 7564 | O35: 7695 | P35: 7482 | Q35: 7676 | R35: 7661 | S35: 7813 | T35: 7878 | U35: 8018 | V35: 8288 | W35: 8358 | X35: 8585 | Y35: 8802 | Z35: 8858 | AA35: 8987 | AB35: 9342 | AC35: 9586 | AD35: 9171 | AE35: 9742 | AF35: 9863 | AG35: 10196 | AH35: 10466 | AI35: =AH35*(1+AI44) | AJ35: =AI35*(1+AJ44) | AK35: =AJ35*(1+AK44) | AL35: =AK35*(1+AL44) | AM35: =AL35*(1+AM44) | AN35: =AM35*(1+AN44)
A36: Total local | B36: =SUM(B32:B35) | C36: =SUM(C32:C35) | D36: =SUM(D32:D35) | E36: =SUM(E32:E35) | F36: =SUM(F32:F35) | G36: =SUM(G32:G35) | H36: =SUM(H32:H35) | I36: =SUM(I32:I35) | ... AN36: =SUM(AN32:AN35)
A37: China | B37: =B38-B36 | C37: 5777 | D37: 1714 | E37: 1728 | F37: 520 | G37: 557 | H37: 601 | I37: 781 | J37: 1181 | K37: 1581 | L37: 2175 | M37: 3008.025 | N37: 3087 | O37: 4497 | P37: 4528 | Q37: 4035 | R37: 3552 | S37: 3731 | T37: 2609 | U37: 2957 | V37: 1838 | W37: 1650 | X37: 1226 | Y37: 1187 | Z37: 1205 | AA37: 1341 | AB37: 556 | AC37: 0 | AD37: 0 | AE37: =AD37*(1+AE46) | AF37: =AE37*(1+AF46) | AG37: =AF37*(1+AG46) | AH37: =AG37*(1+AH46) | AI37: =AH37*(1+AI46) | AJ37: =AI37*(1+AJ46) | AK37: =AJ37*(1+AK46) | AL37: =AK37*(1+AL46) | ... AN37: =AM37*(1+AN46)
A38: Total local and China | B38: 23191 | C38: =SUM(C36:C37) | D38: =SUM(D36:D37) | E38: =SUM(E36:E37) | F38: =SUM(F36:F37) | G38: =SUM(G36:G37) | H38: =SUM(H36:H37) | I38: =SUM(I36:I37) | J38: =SUM(J36:J37) | ... AN38: =SUM(AN36:AN37)
A40: YOY Change (%)
A41: Commercial | B41: na | C41: =(C32/B32)-1 | D41: =(D32/C32)-1 | E41: =(E32/D32)-1 | F41: =(F32/E32)-1 | G41: =(G32/F32)-1 | H41: =(H32/G32)-1 | I41: =(I32/H32*4/5)-1 | J41: =(J32/I32*5/4)-1 | K41: =K32/J32-1 | L41: =L32/K32-1 | M41: =M32/L32-1 | N41: =N32/M32-1 | O41: =O32/N32-1 | P41: =P32/O32-1 | Q41: =Q32/P32-1 | R41: =R32/Q32-1 | ... AG41: =AG32/AF32-1 | AH41: =AG41 | AI41: =AH41 | AJ41: =AI41 | AK41: =AJ41 | AL41: =AK41 | AM41: =AL41 | AN41: =AM41
A42: Domestic | B42: na | C42: =(C33/B33)-1 | D42: =(D33/C33)-1 | E42: =(E33/D33)-1 | F42: =(F33/E33)-1 | G42: =(G33/F33)-1 | H42: =(H33/G33)-1 | I42: =(I33/H33*4/5)-1 | J42: =(J33/I33*5/4)-1 | K42: =K33/J33-1 | L42: =L33/K33-1 | M42: =M33/L33-1 | N42: =N33/M33-1 | O42: =O33/N33-1 | P42: =P33/O33-1 | Q42: =Q33/P33-1 | R42: =R33/Q33-1 | ... AG42: =AG33/AF33-1 | AH42: =AG42 | AI42: =AH42 | AJ42: =AI42 | AK42: =AJ42 | AL42: =AK42 | AM42: =AL42 | AN42: =AM42
