Workbook
Name __Hub2: #REF!
Name __Hub3: #REF!
Name __Hub4: #REF!
Name __xx028: #REF!
Name __xx030: #REF!
Name __xx031: #REF!
Name __xx032: #REF!
Name __xx033: #REF!
Name __xx034: #REF!
Name __xx035: #REF!
Name __xx036: #REF!
Name __xx037: #REF!
Name __xx038: #REF!
Name __xx039: #REF!
Name __xx040: #REF!
Name __xx041: #REF!
Name __xx042: #REF!
Name __xx043: #REF!
Name __xx044: #REF!
Name __xx045: #REF!
Name __xx046: #REF!
Name __xx047: #REF!
Name __xx050: #REF!
Name __xx051: #REF!
Name __xx052: #REF!
Name __xx053: #REF!
Name __xx054: #REF!
Name __xx055: #REF!
Name __xx056: #REF!
Name __xx057: #REF!
Name __xx058: #REF!
Name __xx059: #REF!
Name __xx060: #REF!
Name __xx061: #REF!
Name __xx062: #REF!
Name __xx063: #REF!
Name __xx064: #REF!
Name __xx100: #REF!
Name __xx101: #REF!
Name __xx200: #REF!
Name __xx201: #REF!
Name __xx300: #REF!
Name __xx301: #REF!
Name __xx302: #REF!
Name __xx400: #REF!
Name __xx600: #REF!
Name _Hub2: #REF!
Name _Hub3: #REF!
Name _Hub4: #REF!
Name _Model_Path: "\\Ubsprod.msad.ubs.net\groupshares\GLOBAL\IB_RESEARCH_HKG\TRANSPORT\Ian - ASEAN Airlines\Cathay Pacific\Cathay Pacific Model Live.xlsx"
Name _xx028: #REF!
Name _xx030: #REF!
Name _xx031: #REF!
Name _xx032: #REF!
Name _xx033: #REF!
Name _xx034: #REF!
Name _xx035: #REF!
Name _xx036: #REF!
Name _xx037: #REF!
Name _xx038: #REF!

Sheet VA-Disclaimer

Sheet Valuation
A1: Valuation of Cathay Pacific (293 HK)
A2: Source: Company Data, UBS estimates
A5: Date | B5: =MAX(SharePrice!$A:$A) | AK5: =YEAR(AK4)
A6: Year to December | B6: 2020 | C6: 2021 | D6: 2022 | E6: 2023 | F6: 2024 | G6: 2025 | H6: 2026 | I6: =H6+1 | J6: =I6+1 | K6: =J6+1 | M6: Year | N6: =+CXMODEL!C3 | O6: =+CXMODEL!D3 | P6: =+CXMODEL!E3 | Q6: =+CXMODEL!F3 | R6: =+CXMODEL!G3 | S6: =+CXMODEL!H3 | T6: =+CXMODEL!I3 | U6: =+CXMODEL!J3 | ... BD6: =+CXMODEL!AS3
A7: ROE (ex pref) | B7: =AU9 | C7: =AV9 | D7: =AW9 | E7: =AX9 | F7: =AY9 | G7: =AZ9 | H7: =BA9 | I7: =BB9 | ... K7: =BD9 | M7: Net profit | N7: =+CXMODEL!C159 | O7: =+CXMODEL!D159 | P7: =+CXMODEL!E159 | Q7: =+CXMODEL!F159 | R7: =+CXMODEL!G159 | S7: =+CXMODEL!H159 | T7: =+CXMODEL!I159 | U7: =+CXMODEL!J159 | ... BD7: =+CXMODEL!AS159
A8: 2011-19 average | B8: =AVERAGE(AL9:AT9) | M8: Period-end equity (ex pref) | N8: =+CXMODEL!C215-CXMODEL!C218 | O8: =+CXMODEL!D215-CXMODEL!D218 | P8: =+CXMODEL!E215-CXMODEL!E218 | Q8: =+CXMODEL!F215-CXMODEL!F218 | R8: =+CXMODEL!G215-CXMODEL!G218 | S8: =+CXMODEL!H215-CXMODEL!H218 | T8: =+CXMODEL!I215-CXMODEL!I218 | U8: =+CXMODEL!J215-CXMODEL!J218 | ... BD8: =+CXMODEL!AS215-CXMODEL!AS218
A9: 2026-29E average | B9: =AVERAGE(H7:K7) | M9: ROE (RHS) | O9: =O7/AVERAGE(O8,N8) | P9: =P7/AVERAGE(P8,O8) | Q9: =Q7/AVERAGE(Q8,P8) | R9: =R7/AVERAGE(R8,Q8) | S9: =S7/AVERAGE(S8,R8) | T9: =T7/AVERAGE(T8,S8) | U9: =U7/AVERAGE(U8,T8) | V9: =V7/AVERAGE(V8,U8) | ... BD9: =BD7/AVERAGE(BD8,BC8)
M10: Net debt | N10: =+CXMODEL!C213 | O10: =+CXMODEL!D213 | P10: =+CXMODEL!E213 | Q10: =+CXMODEL!F213 | R10: =+CXMODEL!G213 | S10: =+CXMODEL!H213 | T10: =+CXMODEL!I213 | U10: =+CXMODEL!J213 | ... BD10: =+CXMODEL!AS213
M11: Capitalised operating leases | N11: =+CXMODEL!C214 | O11: =+CXMODEL!D214 | P11: =+CXMODEL!E214 | Q11: =+CXMODEL!F214 | R11: =+CXMODEL!G214 | S11: =+CXMODEL!H214 | T11: =+CXMODEL!I214 | U11: =+CXMODEL!J214 | ... BD11: =+CXMODEL!AS214
M12: Net debt incl. capitalised leases | N12: =+N10+N11 | O12: =+O10+O11 | P12: =+P10+P11 | Q12: =+Q10+Q11 | R12: =+R10+R11 | S12: =+S10+S11 | T12: =+T10+T11 | U12: =+U10+U11 | ... BD12: =+BD10+BD11
A13: Sustainable ROE | B13: =AVERAGE(B8,B9) | M13: Net gearing (LHS) | N13: =N12/N8 | O13: =O12/O8 | P13: =P12/P8 | Q13: =Q12/Q8 | R13: =R12/R8 | S13: =S12/S8 | T13: =T12/T8 | U13: =U12/U8 | ... BD13: =BD12/BD8
A14: Risk-free rate | B14: 0.04
A15: Equity risk premium | B15: 0.05
A16: Beta | B16: =SharePrice!$I$3
A17: COE | B17: =B14+B15*B16
A18: g | B18: 0
A19: Target Price to book (x) | B19: =(B13-B18)/(B17-B18)
A21: BV per share (HK$) | B21: =+CXMODEL!AJ221 | C21: =+CXMODEL!AK221 | D21: =+CXMODEL!AL221 | E21: =+CXMODEL!AM221 | F21: =+CXMODEL!AN221 | G21: =+CXMODEL!AO221 | H21: =+CXMODEL!AP221 | I21: =+CXMODEL!AQ221 | ... K21: =+CXMODEL!AS221
A22: DPS (HK$) | B22: =CXMODEL!AJ168 | C22: =CXMODEL!AK168 | D22: =CXMODEL!AL168 | E22: =CXMODEL!AM168 | F22: =CXMODEL!AN168 | G22: =CXMODEL!AO168 | H22: =CXMODEL!AP168 | I22: =CXMODEL!AQ168 | ... K22: =CXMODEL!AS168
A23: Time weight of 2026E BVPS | B23: =(DATE(H$6,12,31)-B$5)/(DATE(I$6,12,31)-DATE(H$6,12,31))
A24: Time weight of 2027E BVPS | B24: =1-B23
A25: NTM BVPS (HK$/sh) | B25: =B23*H21+B24*I21
A27: Price Target | B27: =ROUND(B25*B19,1)
A29: RATINGS
A30: Spot price | B30: =INDEX(SharePrice!$B:$B,MATCH(B$5,SharePrice!$A:$A,0),1,1)
A32: Upside (Downside) | B32: =+B27/B30-1
A34: Add: Dividend yield (2026E) | B34: =H22/B30
A35: Less: Market return assumption | B35: 0.08
A37: Forecast excess return | B37: =B32+B34-B35
A38: Rating | B38: =IF(B37>6%, "BUY",IF(B37<-6%,"SELL","NEUTRAL"))
A40: Previous PT (26/6/2026) | B40: 16.9
A41: PT change % | B41: =B27/B40-1
A43: Implied by spot price | E43: =E$6 | F43: =F$6 | G43: =G$6 | H43: =H$6 | I43: =I$6 | J43: =J$6 | K43: =K$6
A44: P/B | E44: =+$B$30/E$21 | F44: =+$B$30/F$21 | G44: =+$B$30/G$21 | H44: =+$B$30/H$21 | I44: =+$B$30/I$21 | J44: =+$B$30/J$21 | K44: =+$B$30/K$21
A45: EV/EBITDA | E45: =(+($B$30*CXMODEL!$AJ$170)+$BA$10)/(CXMODEL!AM133+CXMODEL!AM129) | F45: =(+($B$30*CXMODEL!$AJ$170)+$BA$10)/(CXMODEL!AN133+CXMODEL!AN129) | G45: =(+($B$30*CXMODEL!$AJ$170)+$AZ$10)/(CXMODEL!AO133+CXMODEL!AO129) | H45: =(+($B$30*CXMODEL!$AJ$170)+$BA$10)/(CXMODEL!AP133+CXMODEL!AP129) | I45: =(+($B$30*CXMODEL!$AJ$170)+$BA$10)/(CXMODEL!AQ133+CXMODEL!AQ129) | J45: =(+($B$30*CXMODEL!$AJ$170)+$BA$10)/(CXMODEL!AR133+CXMODEL!AR129) | K45: =(+($B$30*CXMODEL!$AJ$170)+$BA$10)/(CXMODEL!AS133+CXMODEL!AS129)
A46: P/E | E46: =+$B$30/CXMODEL!AM$165 | F46: =+$B$30/CXMODEL!AN$165 | G46: =+$B$30/CXMODEL!AO$165 | H46: =+$B$30/CXMODEL!AP$165 | I46: =+$B$30/CXMODEL!AQ$165 | J46: =+$B$30/CXMODEL!AR$165 | K46: =+$B$30/CXMODEL!AS$165
A47: Div Yield | E47: =E22/$B$30 | F47: =F22/$B$30 | G47: =G22/$B$30 | H47: =H22/$B$30 | I47: =I22/$B$30 | J47: =J22/$B$30 | K47: =K22/$B$30
A48: Implied by target PT | E48: =E$6 | F48: =F$6 | G48: =G$6 | H48: =H$6 | I48: =I$6 | J48: =J$6 | K48: =K$6
A49: P/B | E49: =+$B$27/E$21 | F49: =+$B$27/F$21 | G49: =+$B$27/G$21 | H49: =+$B$27/H$21 | I49: =+$B$27/I$21 | J49: =+$B$27/J$21 | K49: =+$B$27/K$21
A50: EV/EBITDA | E50: =(+($B$27*CXMODEL!$AJ$170)+$BA$10)/(CXMODEL!AM133+CXMODEL!AM129) | F50: =(+($B$27*CXMODEL!$AJ$170)+$BA$10)/(CXMODEL!AN133+CXMODEL!AN129) | G50: =(+($B$27*CXMODEL!$AJ$170)+$AZ$10)/(CXMODEL!AO133+CXMODEL!AO129) | H50: =(+($B$27*CXMODEL!$AJ$170)+$BA$10)/(CXMODEL!AP133+CXMODEL!AP129) | I50: =(+($B$27*CXMODEL!$AJ$170)+$BA$10)/(CXMODEL!AQ133+CXMODEL!AQ129) | J50: =(+($B$27*CXMODEL!$AJ$170)+$BA$10)/(CXMODEL!AR133+CXMODEL!AR129) | K50: =(+($B$27*CXMODEL!$AJ$170)+$BA$10)/(CXMODEL!AS133+CXMODEL!AS129)
...

Sheet CXMODEL
B1: Cathay Pacific
A2: Range names | AX2: FY96 Annual Split | BB2: FY97 Annual Split | BF2: FY98 Annual Split | BJ2: FY99 Annual Split | BN2: FY00 Annual Split | BR2: FY01 Annual Split | BV2: FY02 Annual Split | BZ2: FY03 Annual Split | CD2: FY04 Annual Split | CH2: FY05 Annual Split | CL2: FY06 Annual Split | CP2: FY07 Annual Split | CS2: Restated | CU2: FY08 Annual Split | CY2: FY09 Annual Split | DC2: FY10 Annual Split | DG2: FY11 Annual Split | DK2: FY12 Annual Split | DO2: FY13 Annual Split | DS2: FY14 Annual Split | DW2: FY15 Annual Split | EA2: FY16 Annual Split | EE2: FY17 Annual Split | EI2: FY18 Annual Split | EM2: FY19 Annual Split | EQ2: FY20 Annual Split | EU2: FY21 Annual Split | EY2: FY22 Annual Split | FC2: FY23 Annual Split | FG2: FY24 Annual Split | FK2: FY26 Annual Split | FO2: FY26 Annual Split
A3: date | B3: Year to December | C3: 1987A | D3: 1988A | E3: 1989A | F3: 1990A | G3: 1991A | H3: 1992A | I3: 1993A | J3: 1994A | K3: 1995A | L3: 1996A | M3: 1997A | N3: 1998A | O3: 1999A | P3: 2000A | Q3: 2001A | R3: 2002A | S3: 2003A | T3: 2004A | U3: 2005A | V3: 2006A | W3: 2007A | X3: 2008A | Y3: 2009A | Z3: 2010A | AA3: 2011A | AB3: 2012A | AC3: 2013A | AD3: 2014A | AE3: 2015A | AF3: 2016A | AG3: 2017A | AH3: 2018A | AI3: 2019A | AJ3: 2020A | AK3: 2021A | AL3: 2022A | AM3: 2023A | AN3: 2024A | AO3: 2025E | AP3: 2026E | AQ3: 2027E | AR3: 2028E | AS3: 2029E | AT3: 2030E | AV3: 1H1996 | AW3: 2H1996 | AX3: FY1996 | AZ3: 1H1997 | BA3: 2H1997 | BB3: FY1997 | BD3: 1H1998 | BE3: 2H1998 | BF3: FY1998 | BH3: 1H1999 | BI3: 2H1999 | BJ3: FY1999 | BL3: 1H2000 | BM3: 2H2000 | BN3: FY2000 | BP3: 1H2001A | BQ3: 2H2001A | BR3: FY2001A | BT3: 1H2002A | BU3: 2H2002A | BV3: FY2002A | BX3: 1H2003A | BY3: 2H2003A | BZ3: FY2003A | CB3: 1H2004A | CC3: 2H2004A | CD3: FY2004A | CF3: 1H2005A | CG3: 2H2005A | CH3: FY2005A | CJ3: 1H2006A | CK3: 2H2006A | CL3: FY2006A | CN3: 1H2007A | CO3: 2H2007A | CP3: FY2007A | CR3: 1H2008A | CS3: 1H2008A | CT3: 2H2008E | CU3: FY2008E | CW3: 1H2009A | CX3: 2H2009A | CY3: FY2009A | DA3: 1H2010A | DB3: 2H2010A | DC3: FY2010A | DE3: 1H2011A | DF3: 2H2011A | DG3: FY2011A | DI3: 1H2012A | DJ3: 2H2012A | DK3: FY2012E | DM3: 1H2013A | DN3: 2H2013A | DO3: FY2013A | DQ3: 1H2014A | DR3: 2H2014A | DS3: FY2014A | DU3: 1H2015A | DV3: 2H2015A | DW3: FY2015A | DY3: 1H2016A | DZ3: 2H2016A | EA3: FY2016A | EC3: 1H2017A | ED3: 2H2017A | EE3: FY2017A | EG3: 1H2018A | EH3: 2H2018A | EI3: =AH3 | EK3: 1H2019A | EL3: 2H2019A | EM3: =AI3 | EO3: 1H2020A | EP3: 2H2020A | EQ3: =AJ3 | ES3: 1H2021A | ET3: 2H2021A | EU3: =AK3 | EW3: 1H2022A | EX3: 2H2022A | EY3: =AL3 | FA3: 1H2023A | FB3: 2H2023A | FC3: =AM3 | FE3: 1H2024A | FF3: 2H2024A | FG3: =AN3 | FI3: 1H2025A | FJ3: 2H2025A | FK3: =AO3 | FM3: 1H2026A | FN3: 2H2026E | FO3: =AP3
A4: atk | B4: atk | C4: 3751 | D4: 4353 | E4: 4753 | F4: 5429 | G4: 5621 | H4: 6466 | I4: 7212 | J4: 8052 | K4: 8946 | L4: 10018 | M4: 10399 | N4: 10857 | O4: 10867 | P4: 11630.254 | Q4: 12335.052 | R4: 12820.27 | S4: 13355 | T4: 15794 | U4: 17751.456 | V4: 19684 | W4: 23077.462 | X4: 24409.874 | Y4: 22249 | Z4: 24461 | AA4: 26383.685 | AB4: 26249.947 | AC4: 26259.191 | AD4: 28440 | AE4: 30047.974 | AF4: 30462.325 | AG4: 31438.522 | AH4: 32387.156 | AI4: 33077.043 | AJ4: 14620 | AK4: 11354 | AL4: 10100 | AM4: 21225 | AN4: 24836 | AO4: =+AO52+AO22*0.09 | AP4: =+AP52+AP22*0.09 | AQ4: =+AQ52+AQ22*0.09 | AR4: =+AR52+AR22*0.09 | AS4: =+AS52+AS22*0.09 | AT4: =+AT52+AT22*0.09 | AV4: 4752 | AW4: =AX4-AV4 | AX4: =L4 | AZ4: 5074 | BA4: =BB4-AZ4 | BB4: =M4 | BD4: 5208 | BE4: =BF4-BD4 | BF4: =N4 | BH4: 5267 | BI4: =BJ4-BH4 | BJ4: =O4 | BL4: 5482.507 | BM4: =BN4-BL4 | BN4: =P4 | BP4: 5936 | BQ4: =BR4-BP4 | BR4: =Q4 | BT4: 5750 | BU4: =BV4-BT4 | BV4: =R4 | BX4: 6086.99 | BY4: =BZ4-BX4 | BZ4: =S4 | CB4: 7493.4 | CC4: =CD4-CB4 | CD4: =T4 | CF4: 8446 | CG4: =CH4-CF4 | CH4: =U4 | CJ4: 9125.674 | CK4: =CL4-CJ4 | CL4: =V4 | CN4: 10975 | CO4: =CP4-CN4 | CP4: =W4 | CR4: 12080.723 | CS4: 12080.723 | CT4: =CU4-CR4 | CU4: =X4 | CW4: 11034.701 | CX4: =CY4-CW4 | CY4: =Y4 | CZ4: =1-8.7 | DA4: 11435.63 | DB4: =+DC4-DA4 | DC4: =Z4 | DE4: 12846.427 | DF4: =+DG4-DE4 | DG4: =AA4 | DI4: 12943.769 | DJ4: =+DK4-DI4 | DK4: =AB4 | DM4: 12520.226 | DN4: =+DO4-DM4 | DO4: =AC4 | DQ4: 13544.749 | DR4: =+DS4-DQ4 | DS4: =AD4 | DU4: 14598 | DV4: =+DW4-DU4 | DW4: =AE4 | DY4: 14928.859 | DZ4: =+EA4-DY4 | EA4: =AF4 | EC4: 15189.63 | ED4: =+EE4-EC4 | EE4: =AG4 | EG4: 15746.849 | EH4: =+EI4-EG4 | EI4: =AH4 | EK4: 16317.62 | EL4: =+EM4-EK4 | EM4: =AI4 | EO4: 8594.749 | EP4: =+EQ4-EO4 | EQ4: =AJ4 | ES4: 4454 | ET4: =+EU4-ES4 | EU4: =AK4 | EW4: 3094 | EX4: =+EY4-EW4 | EY4: =AL4 | FA4: 9628 | FB4: =+FC4-FA4 | FC4: =AM4 | FE4: 11822 | FF4: =+FG4-FE4 | FG4: =AN4 | FI4: 13699 | FJ4: =+FK4-FI4 | FK4: =AO4 | FM4: 14739 | FN4: =+FN52+FN22*0.09 | FO4: =AP4
A5: capacity growth | B5: Change in overall capacity (ATK) | D5: =D4/C4-1 | E5: =E4/D4-1 | F5: =F4/E4-1 | G5: =G4/F4-1 | H5: =H4/G4-1 | I5: =I4/H4-1 | J5: =J4/I4-1 | K5: =K4/J4-1 | L5: =0.1198 | M5: =M4/L4-1 | N5: =N4/M4-1 | O5: =O4/N4-1 | P5: =P4/O4-1 | Q5: =Q4/P4-1 | R5: =R4/Q4-1 | S5: =S4/R4-1 | T5: =T4/S4-1 | ... AK5: =AK4/AJ4-1 | AL5: =+AL4/AK4-1 | AM5: =+AM4/AL4-1 | AN5: =+AN4/AM4-1 | AO5: =+AO4/AN4-1 | AP5: =+AP4/AO4-1 | AQ5: =+AQ4/AP4-1 | AR5: =+AR4/AQ4-1 | AS5: =+AS4/AR4-1 | AT5: =+AT4/AS4-1 | AX5: =L5 | AZ5: =AZ4/AV4-1 | BA5: =BA4/AW4-1 | BB5: =M5 | BD5: =BD4/AZ4-1 | BE5: =BE4/BA4-1 | BF5: =N5 | BH5: =BH4/BD4-1 | BI5: =BI4/BE4-1 | BJ5: =O5 | BL5: =BL4/BH4-1 | BM5: =BM4/BI4-1 | BN5: =P5 | BP5: =BP4/BL4-1 | BQ5: =BQ4/BM4-1 | BR5: =Q5 | BT5: =BT4/BP4-1 | BU5: =BU4/BQ4-1 | BV5: =R5 | BX5: =BX4/BT4-1 | BY5: =BY4/BU4-1 | BZ5: =S5 | CB5: =CB4/BX4-1 | CC5: =CC4/BY4-1 | CD5: =T5 | CF5: =CF4/CB4-1 | CG5: =CG4/CC4-1 | CH5: =U5 | CJ5: =CJ4/CF4-1 | CK5: =CK4/CG4-1 | CL5: =V5 | CN5: =CN4/CJ4-1 | CO5: =CO4/CK4-1 | CP5: =W5 | CR5: =CR4/CN4-1 | CS5: =CS4/CN4-1 | CT5: =CT4/CO4-1 | CU5: =X5 | CW5: =CW4/CS4-1 | CX5: =CX4/CT4-1 | CY5: =Y5 | DA5: =DA4/CW4-1 | DB5: =DB4/CX4-1 | DC5: =Z5 | DE5: =DE4/DA4-1 | DF5: =DF4/DB4-1 | DG5: =AA5 | DI5: =+DI4/DE4-1 | DJ5: =DJ4/DF4-1 | DK5: =AB5 | DM5: =+DM4/DI4-1 | DN5: =DN4/DJ4-1 | DO5: =AC5 | DQ5: =+DQ4/DM4-1 | DR5: =+DR4/DN4-1 | DS5: =AD5 | DU5: =+DU4/DQ4-1 | DV5: =+DV4/DR4-1 | DW5: =AE5 | DY5: =+DY4/DU4-1 | DZ5: =+DZ4/DV4-1 | EA5: =AF5 | EC5: =+EC4/DY4-1 | ED5: =+ED4/DZ4-1 | EE5: =AG5 | EG5: =+EG4/EC4-1 | EH5: =+EH4/ED4-1 | EI5: =AH5 | EK5: =+EK4/EG4-1 | EL5: =+EL4/EH4-1 | EM5: =AI5 | EO5: =+EO4/EK4-1 | EP5: =+EP4/EL4-1 | EQ5: =+EQ4/EM4-1 | ES5: =+ES4/EO4-1 | ET5: =+ET4/EP4-1 | EU5: =+EU4/EQ4-1 | EW5: =+EW4/ES4-1 | EX5: =+EX4/ET4-1 | EY5: =+EY4/EU4-1 | FA5: =+FA4/EW4-1 | FB5: =+FB4/EX4-1 | FC5: =+FC4/EY4-1 | FE5: =+FE4/FA4-1 | FF5: =+FF4/FB4-1 | FG5: =+FG4/FC4-1 | FI5: =+FI4/FE4-1 | FJ5: =+FJ4/FF4-1 | FK5: =+FK4/FG4-1 | FM5: =+FM4/FI4-1 | FN5: =+FN4/FJ4-1 | FO5: =+FO4/FK4-1
B7: Overall ask | C7: =+C22+C37 | D7: =+D22+D37 | E7: =+E22+E37 | F7: =+F22+F37 | G7: =+G22+G37 | H7: =+H22+H37 | I7: =+I22+I37 | J7: =+J22+J37 | ... AT7: =+AT22+AT37 | BD7: =+BD22+BD37 | BE7: =+BE22+BE37 | BF7: =+BF22+BF37 | BH7: =+BH22+BH37 | BI7: =+BI22+BI37 | BJ7: =+BJ22+BJ37 | BL7: =+BL22+BL37 | BM7: =+BM22+BM37 | BN7: =+BN22+BN37 | BP7: =+BP22+BP37 | BQ7: =+BQ22+BQ37 | BR7: =+BR22+BR37 | BT7: =+BT22+BT37 | BU7: =+BU22+BU37 | BV7: =+BV22+BV37 | BX7: =+BX22+BX37 | BY7: =+BY22+BY37 | BZ7: =+BZ22+BZ37 | CB7: =+CB22+CB37 | CC7: =+CC22+CC37 | CD7: =+CD22+CD37 | CF7: =+CF22+CF37 | CG7: =+CG22+CG37 | CH7: =+CH22+CH37 | CJ7: =+CJ22+CJ37 | CK7: =+CK22+CK37 | CL7: =+CL22+CL37 | CN7: =+CN22+CN37 | CO7: =+CO22+CO37 | CP7: =+CP22+CP37 | CR7: =+CR22+CR37 | CS7: =+CS22+CS37 | CT7: =+CT22+CT37 | CU7: =+CU22+CU37 | CW7: =+CW22+CW37 | CX7: =+CX22+CX37 | CY7: =+CY22+CY37 | DA7: =+DA22+DA37 | DB7: =+DB22+DB37 | DC7: =+DC22+DC37 | DE7: =+DE22+DE37 | DF7: =+DF22+DF37 | DG7: =+DG22+DG37 | DI7: =+DI22+DI37 | DJ7: =+DJ22+DJ37 | DK7: =+DK22+DK37 | DM7: =+DM22+DM37 | DN7: =+DN22+DN37 | DO7: =+DO22+DO37 | DQ7: =+DQ22+DQ37 | DR7: =+DR22+DR37 | DS7: =+DS22+DS37 | DU7: =+DU22+DU37 | DV7: =+DV22+DV37 | DW7: =+DW22+DW37 | DY7: =+DY22+DY37 | DZ7: =+DZ22+DZ37 | EA7: =+EA22+EA37 | EC7: =+EC22+EC37 | ED7: =+ED22+ED37 | EE7: =+EE22+EE37 | EG7: =+EG22+EG37 | EH7: =+EH22+EH37 | EI7: =+EI22+EI37 | EK7: =+EK22+EK37 | EL7: =+EL22+EL37 | EM7: =+EM22+EM37 | EO7: =+EO22+EO37 | EP7: =+EP22+EP37 | EQ7: =+EQ22+EQ37 | ES7: =+ES22+ES37 | ET7: =+ET22+ET37 | EU7: =+EU22+EU37 | EW7: =+EW22+EW37 | EX7: =+EX22+EX37 | EY7: =+EY22+EY37 | FA7: =+FA22+FA37 | FB7: =+FB22+FB37 | FC7: =+FC22+FC37 | FE7: =+FE22+FE37 | FF7: =+FF22+FF37 | FG7: =+FG22+FG37 | FI7: =+FI22+FI37 | FJ7: =+FJ22+FJ37 | FK7: =+FK22+FK37 | FM7: =+FM22+FM37 | FN7: =+FN22+FN37 | FO7: =+FO22+FO37
B8: YoY change in overall capacity (ASK) | D8: =D7/C7-1 | E8: =E7/D7-1 | F8: =F7/E7-1 | G8: =G7/F7-1 | H8: =H7/G7-1 | I8: =I7/H7-1 | J8: =J7/I7-1 | K8: =K7/J7-1 | ... AT8: =AT7/AS7-1 | BH8: =BH7/BD7-1 | BI8: =BI7/BE7-1 | BJ8: =BJ7/BF7-1 | BL8: =BL7/BH7-1 | BM8: =BM7/BI7-1 | BN8: =BN7/BJ7-1 | BP8: =BP7/BL7-1 | BQ8: =BQ7/BM7-1 | BR8: =BR7/BN7-1 | BT8: =BT7/BP7-1 | BU8: =BU7/BQ7-1 | BV8: =BV7/BR7-1 | BX8: =BX7/BT7-1 | BY8: =BY7/BU7-1 | BZ8: =BZ7/BV7-1 | CB8: =CB7/BX7-1 | CC8: =CC7/BY7-1 | CD8: =CD7/BZ7-1 | CF8: =CF7/CB7-1 | CG8: =CG7/CC7-1 | CH8: =CH7/CD7-1 | CJ8: =CJ7/CF7-1 | CK8: =CK7/CG7-1 | CL8: =CL7/CH7-1 | CN8: =CN7/CJ7-1 | CO8: =CO7/CK7-1 | CP8: =CP7/CL7-1 | CR8: =CR7/CN7-1 | CS8: =CS7/CN7-1 | CT8: =CT7/CO7-1 | CU8: =CU7/CP7-1 | CW8: =CW7/CS7-1 | CX8: =CX7/CT7-1 | CY8: =CY7/CU7-1 | DA8: =DA7/CW7-1 | DB8: =DB7/CX7-1 | DC8: =DC7/CY7-1 | DE8: =DE7/DA7-1 | DF8: =DF7/DB7-1 | DG8: =DG7/DC7-1 | DI8: =DI7/DE7-1 | DJ8: =DJ7/DF7-1 | DK8: =DK7/DG7-1 | DM8: =DM7/DI7-1 | DN8: =DN7/DJ7-1 | DO8: =DO7/DK7-1 | DQ8: =DQ7/DM7-1 | DR8: =DR7/DN7-1 | DS8: =DS7/DO7-1 | DU8: =DU7/DQ7-1 | DV8: =DV7/DR7-1 | DW8: =DW7/DS7-1 | DY8: =DY7/DU7-1 | DZ8: =DZ7/DV7-1 | EA8: =EA7/DW7-1 | EC8: =EC7/DY7-1 | ED8: =ED7/DZ7-1 | EE8: =EE7/EA7-1 | EG8: =EG7/EC7-1 | EH8: =EH7/ED7-1 | EI8: =EI7/EE7-1 | EK8: =EK7/EG7-1 | EL8: =EL7/EH7-1 | EM8: =EM7/EI7-1 | EO8: =EO7/EK7-1 | EP8: =EP7/EL7-1 | EQ8: =EQ7/EM7-1 | ES8: =ES7/EO7-1 | ET8: =ET7/EP7-1 | EU8: =EU7/EQ7-1 | EW8: =EW7/ES7-1 | EX8: =EX7/ET7-1 | EY8: =EY7/EU7-1 | FA8: =FA7/EW7-1 | FB8: =FB7/EX7-1 | FC8: =FC7/EY7-1 | FE8: =FE7/FA7-1 | FF8: =FF7/FB7-1 | FG8: =FG7/FC7-1 | FI8: =FI7/FE7-1 | FJ8: =FJ7/FF7-1 | FK8: =FK7/FG7-1 | FM8: =FM7/FI7-1 | FN8: =FN7/FJ7-1 | FO8: =FO7/FK7-1
B9: Overall rpk | C9: =+C24+C39 | D9: =+D24+D39 | E9: =+E24+E39 | F9: =+F24+F39 | G9: =+G24+G39 | H9: =+H24+H39 | I9: =+I24+I39 | J9: =+J24+J39 | ... AT9: =+AT24+AT39 | BD9: =+BD24+BD39 | BE9: =+BE24+BE39 | BF9: =+BF24+BF39 | BH9: =+BH24+BH39 | BI9: =+BI24+BI39 | BJ9: =+BJ24+BJ39 | BL9: =+BL24+BL39 | BM9: =+BM24+BM39 | BN9: =+BN24+BN39 | BP9: =+BP24+BP39 | BQ9: =+BQ24+BQ39 | BR9: =+BR24+BR39 | BT9: =+BT24+BT39 | BU9: =+BU24+BU39 | BV9: =+BV24+BV39 | BX9: =+BX24+BX39 | BY9: =+BY24+BY39 | BZ9: =+BZ24+BZ39 | CB9: =+CB24+CB39 | CC9: =+CC24+CC39 | CD9: =+CD24+CD39 | CF9: =+CF24+CF39 | CG9: =+CG24+CG39 | CH9: =+CH24+CH39 | CJ9: =+CJ24+CJ39 | CK9: =+CK24+CK39 | CL9: =+CL24+CL39 | CN9: =+CN24+CN39 | CO9: =+CO24+CO39 | CP9: =+CP24+CP39 | CR9: =+CR24+CR39 | CS9: =+CS24+CS39 | CT9: =+CT24+CT39 | CU9: =+CU24+CU39 | CW9: =+CW24+CW39 | CX9: =+CX24+CX39 | CY9: =+CY24+CY39 | DA9: =+DA24+DA39 | DB9: =+DB24+DB39 | DC9: =+DC24+DC39 | DE9: =+DE24+DE39 | DF9: =+DF24+DF39 | DG9: =+DG24+DG39 | DI9: =+DI24+DI39 | DJ9: =+DJ24+DJ39 | DK9: =+DK24+DK39 | DM9: =+DM24+DM39 | DN9: =+DN24+DN39 | DO9: =+DO24+DO39 | DQ9: =+DQ24+DQ39 | DR9: =+DR24+DR39 | DS9: =+DS24+DS39 | DU9: =+DU24+DU39 | DV9: =+DV24+DV39 | DW9: =+DW24+DW39 | DY9: =+DY24+DY39 | DZ9: =+DZ24+DZ39 | EA9: =+EA24+EA39 | EC9: =+EC24+EC39 | ED9: =+ED24+ED39 | EE9: =+EE24+EE39 | EG9: =+EG24+EG39 | EH9: =+EH24+EH39 | EI9: =+EI24+EI39 | EK9: =+EK24+EK39 | EL9: =+EL24+EL39 | EM9: =+EM24+EM39 | EO9: =+EO24+EO39 | EP9: =+EP24+EP39 | EQ9: =+EQ24+EQ39 | ES9: =+ES24+ES39 | ET9: =+ET24+ET39 | EU9: =+EU24+EU39 | EW9: =+EW24+EW39 | EX9: =+EX24+EX39 | EY9: =+EY24+EY39 | FA9: =+FA24+FA39 | FB9: =+FB24+FB39 | FC9: =+FC24+FC39 | FE9: =+FE24+FE39 | FF9: =+FF24+FF39 | FG9: =+FG24+FG39 | FI9: =+FI24+FI39 | FJ9: =+FJ24+FJ39 | FK9: =+FK24+FK39 | FM9: =+FM24+FM39 | FN9: =+FN24+FN39 | FO9: =+FO24+FO39
B10: YoY change in passenger traffic (RPK) | D10: =D9/C9-1 | E10: =E9/D9-1 | F10: =F9/E9-1 | G10: =G9/F9-1 | H10: =H9/G9-1 | I10: =I9/H9-1 | J10: =J9/I9-1 | K10: =K9/J9-1 | ... AT10: =AT9/AS9-1 | BH10: =BH9/BD9-1 | BI10: =BI9/BE9-1 | BJ10: =BJ9/BF9-1 | BL10: =BL9/BH9-1 | BM10: =BM9/BI9-1 | BN10: =BN9/BJ9-1 | BP10: =BP9/BL9-1 | BQ10: =BQ9/BM9-1 | BR10: =BR9/BN9-1 | BT10: =BT9/BP9-1 | BU10: =BU9/BQ9-1 | BV10: =BV9/BR9-1 | BX10: =BX9/BT9-1 | BY10: =BY9/BU9-1 | BZ10: =BZ9/BV9-1 | CB10: =CB9/BX9-1 | CC10: =CC9/BY9-1 | CD10: =CD9/BZ9-1 | CF10: =CF9/CB9-1 | CG10: =CG9/CC9-1 | CH10: =CH9/CD9-1 | CJ10: =CJ9/CF9-1 | CK10: =CK9/CG9-1 | CL10: =CL9/CH9-1 | CN10: =CN9/CJ9-1 | CO10: =CO9/CK9-1 | CP10: =CP9/CL9-1 | CR10: =CR9/CN9-1 | CS10: =CS9/CN9-1 | CT10: =CT9/CO9-1 | CU10: =CU9/CP9-1 | CW10: =CW9/CS9-1 | CX10: =CX9/CT9-1 | CY10: =CY9/CU9-1 | DA10: =DA9/CW9-1 | DB10: =DB9/CX9-1 | DC10: =DC9/CY9-1 | DE10: =DE9/DA9-1 | DF10: =DF9/DB9-1 | DG10: =DG9/DC9-1 | DI10: =DI9/DE9-1 | DJ10: =DJ9/DF9-1 | DK10: =DK9/DG9-1 | DM10: =DM9/DI9-1 | DN10: =DN9/DJ9-1 | DO10: =DO9/DK9-1 | DQ10: =DQ9/DM9-1 | DR10: =DR9/DN9-1 | DS10: =DS9/DO9-1 | DU10: =DU9/DQ9-1 | DV10: =DV9/DR9-1 | DW10: =DW9/DS9-1 | DY10: =DY9/DU9-1 | DZ10: =DZ9/DV9-1 | EA10: =EA9/DW9-1 | EC10: =EC9/DY9-1 | ED10: =ED9/DZ9-1 | EE10: =EE9/EA9-1 | EG10: =EG9/EC9-1 | EH10: =EH9/ED9-1 | EI10: =EI9/EE9-1 | EK10: =EK9/EG9-1 | EL10: =EL9/EH9-1 | EM10: =EM9/EI9-1 | EO10: =EO9/EK9-1 | EP10: =EP9/EL9-1 | EQ10: =EQ9/EM9-1 | ES10: =ES9/EO9-1 | ET10: =ET9/EP9-1 | EU10: =EU9/EQ9-1 | EW10: =EW9/ES9-1 | EX10: =EX9/ET9-1 | EY10: =EY9/EU9-1 | FA10: =FA9/EW9-1 | FB10: =FB9/EX9-1 | FC10: =FC9/EY9-1 | FE10: =FE9/FA9-1 | FF10: =FF9/FB9-1 | FG10: =FG9/FC9-1 | FI10: =FI9/FE9-1 | FJ10: =FJ9/FF9-1 | FK10: =FK9/FG9-1 | FM10: =FM9/FI9-1 | FN10: =FN9/FJ9-1 | FO10: =FO9/FK9-1
B11: Overall Passenger nos (000s) | C11: =+C26+C41 | D11: =+D26+D41 | E11: =+E26+E41 | F11: =+F26+F41 | G11: =+G26+G41 | H11: =+H26+H41 | I11: =+I26+I41 | J11: =+J26+J41 | ... AT11: =+AT26+AT41 | BF11: =+BF26+BF41 | BH11: =+BH26+BH41 | BI11: =+BI26+BI41 | BJ11: =+BJ26+BJ41 | BL11: =+BL26+BL41 | BM11: =+BM26+BM41 | BN11: =+BN26+BN41 | BP11: =+BP26+BP41 | BQ11: =+BQ26+BQ41 | BR11: =+BR26+BR41 | BT11: =+BT26+BT41 | BU11: =+BU26+BU41 | BV11: =+BV26+BV41 | BX11: =+BX26+BX41 | BY11: =+BY26+BY41 | BZ11: =+BZ26+BZ41 | CB11: =+CB26+CB41 | CC11: =+CC26+CC41 | CD11: =+CD26+CD41 | CF11: =+CF26+CF41 | CG11: =+CG26+CG41 | CH11: =+CH26+CH41 | CJ11: =+CJ26+CJ41 | CK11: =+CK26+CK41 | CL11: =+CL26+CL41 | CN11: =+CN26+CN41 | CO11: =+CO26+CO41 | CP11: =+CP26+CP41 | CR11: =+CR26+CR41 | CS11: =+CS26+CS41 | CT11: =+CT26+CT41 | CU11: =+CU26+CU41 | CW11: =+CW26+CW41 | CX11: =+CX26+CX41 | CY11: =+CY26+CY41 | DA11: =+DA26+DA41 | DB11: =+DB26+DB41 | DC11: =+DC26+DC41 | DE11: =+DE26+DE41 | DF11: =+DF26+DF41 | DG11: =+DG26+DG41 | DI11: =+DI26+DI41 | DJ11: =+DJ26+DJ41 | DK11: =+DK26+DK41 | DM11: =+DM26+DM41 | DN11: =+DN26+DN41 | DO11: =+DO26+DO41 | DQ11: =+DQ26+DQ41 | DR11: =+DR26+DR41 | DS11: =+DS26+DS41 | DU11: =+DU26+DU41 | DV11: =+DV26+DV41 | DW11: =+DW26+DW41 | DY11: =+DY26+DY41 | DZ11: =+DZ26+DZ41 | EA11: =+EA26+EA41 | EC11: =+EC26+EC41 | ED11: =+ED26+ED41 | EE11: =+EE26+EE41 | EG11: =+EG26+EG41 | EH11: =+EH26+EH41 | EI11: =+EI26+EI41 | EK11: =+EK26+EK41 | EL11: =+EL26+EL41 | EM11: =+EM26+EM41 | EO11: =+EO26+EO41 | EP11: =+EP26+EP41 | EQ11: =+EQ26+EQ41 | ES11: =+ES26+ES41 | ET11: =+ET26+ET41 | EU11: =+EU26+EU41 | EW11: =+EW26+EW41 | EX11: =+EX26+EX41 | EY11: =+EY26+EY41 | FA11: =+FA26+FA41 | FB11: =+FB26+FB41 | FC11: =+FC26+FC41 | FE11: =+FE26+FE41 | FF11: =+FF26+FF41 | FG11: =+FG26+FG41 | FI11: =+FI26+FI41 | FJ11: =+FJ26+FJ41 | FK11: =+FK26+FK41 | FM11: =+FM26+FM41 | FN11: =+FN26+FN41 | FO11: =+FO26+FO41
B12: Overall Trip length (kms) | C12: =C9/C11*1000 | D12: =D9/D11*1000 | E12: =E9/E11*1000 | F12: =F9/F11*1000 | G12: =G9/G11*1000 | H12: =H9/H11*1000 | I12: =I9/I11*1000 | J12: =J9/J11*1000 | ... AT12: =AT9/AT11*1000 | BF12: =BF9/BF11*1000 | BH12: =BH9/BH11*1000 | BI12: =BI9/BI11*1000 | BJ12: =BJ9/BJ11*1000 | BL12: =BL9/BL11*1000 | BM12: =BM9/BM11*1000 | BN12: =BN9/BN11*1000 | BP12: =BP9/BP11*1000 | BQ12: =BQ9/BQ11*1000 | BR12: =BR9/BR11*1000 | BT12: =BT9/BT11*1000 | BU12: =BU9/BU11*1000 | BV12: =BV9/BV11*1000 | BX12: =BX9/BX11*1000 | BY12: =BY9/BY11*1000 | BZ12: =BZ9/BZ11*1000 | CB12: =CB9/CB11*1000 | CC12: =CC9/CC11*1000 | CD12: =CD9/CD11*1000 | CF12: =CF9/CF11*1000 | CG12: =CG9/CG11*1000 | CH12: =CH9/CH11*1000 | CJ12: =CJ9/CJ11*1000 | CK12: =CK9/CK11*1000 | CL12: =CL9/CL11*1000 | CN12: =CN9/CN11*1000 | CO12: =CO9/CO11*1000 | CP12: =CP9/CP11*1000 | CR12: =CR9/CR11*1000 | CS12: =CS9/CS11*1000 | CT12: =CT9/CT11*1000 | CU12: =CU9/CU11*1000 | CW12: =CW9/CW11*1000 | CX12: =CX9/CX11*1000 | CY12: =CY9/CY11*1000 | DA12: =DA9/DA11*1000 | DB12: =DB9/DB11*1000 | DC12: =DC9/DC11*1000 | DE12: =DE9/DE11*1000 | DF12: =DF9/DF11*1000 | DG12: =DG9/DG11*1000 | DI12: =DI9/DI11*1000 | DJ12: =DJ9/DJ11*1000 | DK12: =DK9/DK11*1000 | DM12: =DM9/DM11*1000 | DN12: =DN9/DN11*1000 | DO12: =DO9/DO11*1000 | DQ12: =DQ9/DQ11*1000 | DR12: =DR9/DR11*1000 | DS12: =DS9/DS11*1000 | DU12: =DU9/DU11*1000 | DV12: =DV9/DV11*1000 | DW12: =DW9/DW11*1000 | DY12: =DY9/DY11*1000 | DZ12: =DZ9/DZ11*1000 | EA12: =EA9/EA11*1000 | EC12: =EC9/EC11*1000 | ED12: =ED9/ED11*1000 | EE12: =EE9/EE11*1000 | EG12: =EG9/EG11*1000 | EH12: =EH9/EH11*1000 | EI12: =EI9/EI11*1000 | EK12: =EK9/EK11*1000 | EL12: =EL9/EL11*1000 | EM12: =EM9/EM11*1000 | EO12: =EO9/EO11*1000 | EP12: =EP9/EP11*1000 | EQ12: =EQ9/EQ11*1000 | ES12: =ES9/ES11*1000 | ET12: =ET9/ET11*1000 | EU12: =EU9/EU11*1000 | EW12: =EW9/EW11*1000 | EX12: =EX9/EX11*1000 | EY12: =EY9/EY11*1000 | FA12: =FA9/FA11*1000 | FB12: =FB9/FB11*1000 | FC12: =FC9/FC11*1000 | FE12: =FE9/FE11*1000 | FF12: =FF9/FF11*1000 | FG12: =FG9/FG11*1000 | FI12: =FI9/FI11*1000 | FJ12: =FJ9/FJ11*1000 | FK12: =FK9/FK11*1000 | FM12: =FM9/FM11*1000 | FN12: =FN9/FN11*1000 | FO12: =FO9/FO11*1000
B13: Overall Passenger load factor | C13: =C9/C7 | D13: =D9/D7 | E13: =E9/E7 | F13: =F9/F7 | G13: =G9/G7 | H13: =H9/H7 | I13: =I9/I7 | J13: =J9/J7 | ... AT13: =AT9/AT7 | BD13: =BD9/BD7 | BE13: =BE9/BE7 | BF13: =BF9/BF7 | BH13: =BH9/BH7 | BI13: =BI9/BI7 | BJ13: =BJ9/BJ7 | BL13: =BL9/BL7 | BM13: =BM9/BM7 | BN13: =BN9/BN7 | BP13: =BP9/BP7 | BQ13: =BQ9/BQ7 | BR13: =BR9/BR7 | BT13: =BT9/BT7 | BU13: =BU9/BU7 | BV13: =BV9/BV7 | BX13: =BX9/BX7 | BY13: =BY9/BY7 | BZ13: =BZ9/BZ7 | CB13: =CB9/CB7 | CC13: =CC9/CC7 | CD13: =CD9/CD7 | CF13: =CF9/CF7 | CG13: =CG9/CG7 | CH13: =CH9/CH7 | CJ13: =CJ9/CJ7 | CK13: =CK9/CK7 | CL13: =CL9/CL7 | CN13: =CN9/CN7 | CO13: =CO9/CO7 | CP13: =CP9/CP7 | CR13: =CR9/CR7 | CS13: =CS9/CS7 | CT13: =CT9/CT7 | CU13: =CU9/CU7 | CW13: =CW9/CW7 | CX13: =CX9/CX7 | CY13: =CY9/CY7 | DA13: =DA9/DA7 | DB13: =DB9/DB7 | DC13: =DC9/DC7 | DE13: =DE9/DE7 | DF13: =DF9/DF7 | DG13: =DG9/DG7 | DI13: =DI9/DI7 | DJ13: =DJ9/DJ7 | DK13: =DK9/DK7 | DM13: =DM9/DM7 | DN13: =DN9/DN7 | DO13: =DO9/DO7 | DQ13: =DQ9/DQ7 | DR13: =DR9/DR7 | DS13: =DS9/DS7 | DU13: =DU9/DU7 | DV13: =DV9/DV7 | DW13: =DW9/DW7 | DY13: =DY9/DY7 | DZ13: =DZ9/DZ7 | EA13: =EA9/EA7 | EC13: =EC9/EC7 | ED13: =ED9/ED7 | EE13: =EE9/EE7 | EG13: =EG9/EG7 | EH13: =EH9/EH7 | EI13: =EI9/EI7 | EK13: =EK9/EK7 | EL13: =EL9/EL7 | EM13: =EM9/EM7 | EO13: =EO9/EO7 | EP13: =EP9/EP7 | EQ13: =EQ9/EQ7 | ES13: =ES9/ES7 | ET13: =ET9/ET7 | EU13: =EU9/EU7 | EW13: =EW9/EW7 | EX13: =EX9/EX7 | EY13: =EY9/EY7 | FA13: =FA9/FA7 | FB13: =FB9/FB7 | FC13: =FC9/FC7 | FE13: =FE9/FE7 | FF13: =FF9/FF7 | FG13: =FG9/FG7 | FI13: =FI9/FI7 | FJ13: =FJ9/FJ7 | FK13: =FK9/FK7 | FM13: =FM9/FM7 | FN13: =FN9/FN7 | FO13: =FO9/FO7
B14: Overall pax yield | C14: =C20/C9 | D14: =D20/D9 | E14: =E20/E9 | F14: =F20/F9 | G14: =G20/G9 | H14: =H20/H9 | I14: =I20/I9 | J14: =J20/J9 | ... AT14: =AT20/AT9 | BD14: =BD20/BD9 | BE14: =BE20/BE9 | BF14: =BF20/BF9 | BH14: =BH20/BH9 | BI14: =BI20/BI9 | BJ14: =BJ20/BJ9 | BL14: =BL20/BL9 | BM14: =BM20/BM9 | BN14: =BN20/BN9 | BP14: =BP20/BP9 | BQ14: =BQ20/BQ9 | BR14: =BR20/BR9 | BT14: =BT20/BT9 | BU14: =BU20/BU9 | BV14: =BV20/BV9 | BX14: =BX20/BX9 | BY14: =BY20/BY9 | BZ14: =BZ20/BZ9 | CB14: =CB20/CB9 | CC14: =CC20/CC9 | CD14: =CD20/CD9 | CF14: =CF20/CF9 | CG14: =CG20/CG9 | CH14: =CH20/CH9 | CJ14: =CJ20/CJ9 | CK14: =CK20/CK9 | CL14: =CL20/CL9 | CN14: =CN20/CN9 | CO14: =CO20/CO9 | CP14: =CP20/CP9 | CR14: =CR20/CR9 | CS14: =CS20/CS9 | CT14: =CT20/CT9 | CU14: =CU20/CU9 | CW14: =CW20/CW9 | CX14: =CX20/CX9 | CY14: =CY20/CY9 | DA14: =DA20/DA9 | DB14: =DB20/DB9 | DC14: =DC20/DC9 | DE14: =DE20/DE9 | DF14: =DF20/DF9 | DG14: =DG20/DG9 | DI14: =DI20/DI9 | DJ14: =DJ20/DJ9 | DK14: =DK20/DK9 | DM14: =DM20/DM9 | DN14: =DN20/DN9 | DO14: =DO20/DO9 | DQ14: =DQ20/DQ9 | DR14: =DR20/DR9 | DS14: =DS20/DS9 | DU14: =DU20/DU9 | DV14: =DV20/DV9 | DW14: =DW20/DW9 | DY14: =DY20/DY9 | DZ14: =DZ20/DZ9 | EA14: =EA20/EA9 | EC14: =EC20/EC9 | ED14: =ED20/ED9 | EE14: =EE20/EE9 | EG14: =EG20/EG9 | EH14: =EH20/EH9 | EI14: =EI20/EI9 | EK14: =EK20/EK9 | EL14: =EL20/EL9 | EM14: =EM20/EM9 | EO14: =EO20/EO9 | EP14: =EP20/EP9 | EQ14: =EQ20/EQ9 | ES14: =ES20/ES9 | ET14: =ET20/ET9 | EU14: =EU20/EU9 | EW14: =EW20/EW9 | EX14: =EX20/EX9 | EY14: =EY20/EY9 | FA14: =FA20/FA9 | FB14: =FB20/FB9 | FC14: =FC20/FC9 | FE14: =FE20/FE9 | FF14: =FF20/FF9 | FG14: =FG20/FG9 | FI14: =FI20/FI9 | FJ14: =FJ20/FJ9 | FK14: =FK20/FK9 | FM14: =FM20/FM9 | FN14: =FN20/FN9 | FO14: =FO20/FO9
B15: YoY change in passenger yield | D15: =D14/C14-1 | E15: =E14/D14-1 | F15: =F14/E14-1 | G15: =G14/F14-1 | H15: =H14/G14-1 | I15: =I14/H14-1 | J15: =J14/I14-1 | K15: =K14/J14-1 | ... AT15: =AT14/AS14-1 | BH15: =BH14/BD14-1 | BI15: =BI14/BE14-1 | BJ15: =BJ14/BF14-1 | BL15: =BL14/BH14-1 | BM15: =BM14/BI14-1 | BN15: =BN14/BJ14-1 | BP15: =BP14/BL14-1 | BQ15: =BQ14/BM14-1 | BR15: =BR14/BN14-1 | BT15: =BT14/BP14-1 | BU15: =BU14/BQ14-1 | BV15: =BV14/BR14-1 | BX15: =BX14/BT14-1 | BY15: =BY14/BU14-1 | BZ15: =BZ14/BV14-1 | CB15: =CB14/BX14-1 | CC15: =CC14/BY14-1 | CD15: =CD14/BZ14-1 | CF15: =CF14/CB14-1 | CG15: =CG14/CC14-1 | CH15: =CH14/CD14-1 | CJ15: =CJ14/CF14-1 | CK15: =CK14/CG14-1 | CL15: =CL14/CH14-1 | CN15: =CN14/CJ14-1 | CO15: =CO14/CK14-1 | CP15: =CP14/CL14-1 | CR15: =CR14/CN14-1 | CS15: =CS14/CN14-1 | CT15: =CT14/CO14-1 | CU15: =CU14/CP14-1 | CW15: =CW14/CS14-1 | CX15: =CX14/CT14-1 | CY15: =CY14/CU14-1 | DA15: =DA14/CW14-1 | DB15: =DB14/CX14-1 | DC15: =DC14/CY14-1 | DE15: =DE14/DA14-1 | DF15: =DF14/DB14-1 | DG15: =DG14/DC14-1 | DI15: =DI14/DE14-1 | DJ15: =DJ14/DF14-1 | DK15: =DK14/DG14-1 | DM15: =DM14/DI14-1 | DN15: =DN14/DJ14-1 | DO15: =DO14/DK14-1 | DQ15: =DQ14/DM14-1 | DR15: =DR14/DN14-1 | DS15: =DS14/DO14-1 | DU15: =DU14/DQ14-1 | DV15: =DV14/DR14-1 | DW15: =DW14/DS14-1 | DY15: =DY14/DU14-1 | DZ15: =DZ14/DV14-1 | EA15: =EA14/DW14-1 | EC15: =EC14/DY14-1 | ED15: =ED14/DZ14-1 | EE15: =EE14/EA14-1 | EG15: =EG14/EC14-1 | EH15: =EH14/ED14-1 | EI15: =EI14/EE14-1 | EK15: =EK14/EG14-1 | EL15: =EL14/EH14-1 | EM15: =EM14/EI14-1 | EO15: =EO14/EK14-1 | EP15: =EP14/EL14-1 | EQ15: =EQ14/EM14-1 | ES15: =ES14/EO14-1 | ET15: =ET14/EP14-1 | EU15: =EU14/EQ14-1 | EW15: =EW14/ES14-1 | EX15: =EX14/ET14-1 | EY15: =EY14/EU14-1 | FA15: =FA14/EW14-1 | FB15: =FB14/EX14-1 | FC15: =FC14/EY14-1 | FE15: =FE14/FA14-1 | FF15: =FF14/FB14-1 | FG15: =FG14/FC14-1 | FI15: =FI14/FE14-1 | FJ15: =FJ14/FF14-1 | FK15: =FK14/FG14-1 | FM15: =FM14/FI14-1 | FN15: =FN14/FJ14-1 | FO15: =FO14/FK14-1
B16: Overall unit revenue (RASK) | C16: =C20/C7 | D16: =D20/D7 | E16: =E20/E7 | F16: =F20/F7 | G16: =G20/G7 | H16: =H20/H7 | I16: =I20/I7 | J16: =J20/J7 | ... AT16: =AT20/AT7 | BD16: =BD20/BD7 | BE16: =BE20/BE7 | BF16: =BF20/BF7 | BH16: =BH20/BH7 | BI16: =BI20/BI7 | BJ16: =BJ20/BJ7 | BL16: =BL20/BL7 | BM16: =BM20/BM7 | BN16: =BN20/BN7 | BP16: =BP20/BP7 | BQ16: =BQ20/BQ7 | BR16: =BR20/BR7 | BT16: =BT20/BT7 | BU16: =BU20/BU7 | BV16: =BV20/BV7 | BX16: =BX20/BX7 | BY16: =BY20/BY7 | BZ16: =BZ20/BZ7 | CB16: =CB20/CB7 | CC16: =CC20/CC7 | CD16: =CD20/CD7 | CF16: =CF20/CF7 | CG16: =CG20/CG7 | CH16: =CH20/CH7 | CJ16: =CJ20/CJ7 | CK16: =CK20/CK7 | CL16: =CL20/CL7 | CN16: =CN20/CN7 | CO16: =CO20/CO7 | CP16: =CP20/CP7 | CR16: =CR20/CR7 | CS16: =CS20/CS7 | CT16: =CT20/CT7 | CU16: =CU20/CU7 | CW16: =CW20/CW7 | CX16: =CX20/CX7 | CY16: =CY20/CY7 | DA16: =DA20/DA7 | DB16: =DB20/DB7 | DC16: =DC20/DC7 | DE16: =DE20/DE7 | DF16: =DF20/DF7 | DG16: =DG20/DG7 | DI16: =DI20/DI7 | DJ16: =DJ20/DJ7 | DK16: =DK20/DK7 | DM16: =DM20/DM7 | DN16: =DN20/DN7 | DO16: =DO20/DO7 | DQ16: =DQ20/DQ7 | DR16: =DR20/DR7 | DS16: =DS20/DS7 | DU16: =DU20/DU7 | DV16: =DV20/DV7 | DW16: =DW20/DW7 | DY16: =DY20/DY7 | DZ16: =DZ20/DZ7 | EA16: =EA20/EA7 | EC16: =EC20/EC7 | ED16: =ED20/ED7 | EE16: =EE20/EE7 | EG16: =EG20/EG7 | EH16: =EH20/EH7 | EI16: =EI20/EI7 | EK16: =EK20/EK7 | EL16: =EL20/EL7 | EM16: =EM20/EM7 | EO16: =EO20/EO7 | EP16: =EP20/EP7 | EQ16: =EQ20/EQ7 | ES16: =ES20/ES7 | ET16: =ET20/ET7 | EU16: =EU20/EU7 | EW16: =EW20/EW7 | EX16: =EX20/EX7 | EY16: =EY20/EY7 | FA16: =FA20/FA7 | FB16: =FB20/FB7 | FC16: =FC20/FC7 | FE16: =FE20/FE7 | FF16: =FF20/FF7 | FG16: =FG20/FG7 | FI16: =FI20/FI7 | FJ16: =FJ20/FJ7 | FK16: =FK20/FK7 | FM16: =FM20/FM7 | FN16: =FN20/FN7 | FO16: =FO20/FO7
B17: YoY change in RASK | D17: =D16/C16-1 | E17: =E16/D16-1 | F17: =F16/E16-1 | G17: =G16/F16-1 | H17: =H16/G16-1 | I17: =I16/H16-1 | J17: =J16/I16-1 | K17: =K16/J16-1 | ... AT17: =AT16/AS16-1 | BH17: =BH16/BD16-1 | BI17: =BI16/BE16-1 | BJ17: =BJ16/BF16-1 | BL17: =BL16/BH16-1 | BM17: =BM16/BI16-1 | BN17: =BN16/BJ16-1 | BP17: =BP16/BL16-1 | BQ17: =BQ16/BM16-1 | BR17: =BR16/BN16-1 | BT17: =BT16/BP16-1 | BU17: =BU16/BQ16-1 | BV17: =BV16/BR16-1 | BX17: =BX16/BT16-1 | BY17: =BY16/BU16-1 | BZ17: =BZ16/BV16-1 | CB17: =CB16/BX16-1 | CC17: =CC16/BY16-1 | CD17: =CD16/BZ16-1 | CF17: =CF16/CB16-1 | CG17: =CG16/CC16-1 | CH17: =CH16/CD16-1 | CJ17: =CJ16/CF16-1 | CK17: =CK16/CG16-1 | CL17: =CL16/CH16-1 | CN17: =CN16/CJ16-1 | CO17: =CO16/CK16-1 | CP17: =CP16/CL16-1 | CR17: =CR16/CN16-1 | CS17: =CS16/CN16-1 | CT17: =CT16/CO16-1 | CU17: =CU16/CP16-1 | CW17: =CW16/CS16-1 | CX17: =CX16/CT16-1 | CY17: =CY16/CU16-1 | DA17: =DA16/CW16-1 | DB17: =DB16/CX16-1 | DC17: =DC16/CY16-1 | DE17: =DE16/DA16-1 | DF17: =DF16/DB16-1 | DG17: =DG16/DC16-1 | DI17: =DI16/DE16-1 | DJ17: =DJ16/DF16-1 | DK17: =DK16/DG16-1 | DM17: =DM16/DI16-1 | DN17: =DN16/DJ16-1 | DO17: =DO16/DK16-1 | DQ17: =DQ16/DM16-1 | DR17: =DR16/DN16-1 | DS17: =DS16/DO16-1 | DU17: =DU16/DQ16-1 | DV17: =DV16/DR16-1 | DW17: =DW16/DS16-1 | DY17: =DY16/DU16-1 | DZ17: =DZ16/DV16-1 | EA17: =EA16/DW16-1 | EC17: =EC16/DY16-1 | ED17: =ED16/DZ16-1 | EE17: =EE16/EA16-1 | EG17: =EG16/EC16-1 | EH17: =EH16/ED16-1 | EI17: =EI16/EE16-1 | EK17: =EK16/EG16-1 | EL17: =EL16/EH16-1 | EM17: =EM16/EI16-1 | EO17: =EO16/EK16-1 | EP17: =EP16/EL16-1 | EQ17: =EQ16/EM16-1 | ES17: =ES16/EO16-1 | ET17: =ET16/EP16-1 | EU17: =EU16/EQ16-1 | EW17: =EW16/ES16-1 | EX17: =EX16/ET16-1 | EY17: =EY16/EU16-1 | FA17: =FA16/EW16-1 | FB17: =FB16/EX16-1 | FC17: =FC16/EY16-1 | FE17: =FE16/FA16-1 | FF17: =FF16/FB16-1 | FG17: =FG16/FC16-1 | FI17: =FI16/FE16-1 | FJ17: =FJ16/FF16-1 | FK17: =FK16/FG16-1 | FM17: =FM16/FI16-1 | FN17: =FN16/FJ16-1 | FO17: =FO16/FK16-1
B18: Average airfare ticket price | C18: =+C20/C11*1000 | D18: =+D20/D11*1000 | E18: =+E20/E11*1000 | F18: =+F20/F11*1000 | G18: =+G20/G11*1000 | H18: =+H20/H11*1000 | I18: =+I20/I11*1000 | J18: =+J20/J11*1000 | ... AT18: =+AT20/AT11*1000 | BH18: =+BH20/BH11*1000 | BI18: =+BI20/BI11*1000 | BJ18: =+BJ20/BJ11*1000 | BL18: =+BL20/BL11*1000 | BM18: =+BM20/BM11*1000 | BN18: =+BN20/BN11*1000 | BP18: =+BP20/BP11*1000 | BQ18: =+BQ20/BQ11*1000 | BR18: =+BR20/BR11*1000 | BT18: =+BT20/BT11*1000 | BU18: =+BU20/BU11*1000 | BV18: =+BV20/BV11*1000 | BX18: =+BX20/BX11*1000 | BY18: =+BY20/BY11*1000 | BZ18: =+BZ20/BZ11*1000 | CB18: =+CB20/CB11*1000 | CC18: =+CC20/CC11*1000 | CD18: =+CD20/CD11*1000 | CF18: =+CF20/CF11*1000 | CG18: =+CG20/CG11*1000 | CH18: =+CH20/CH11*1000 | CJ18: =+CJ20/CJ11*1000 | CK18: =+CK20/CK11*1000 | CL18: =+CL20/CL11*1000 | CN18: =+CN20/CN11*1000 | CO18: =+CO20/CO11*1000 | CP18: =+CP20/CP11*1000 | CR18: =+CR20/CR11*1000 | CS18: =+CS20/CS11*1000 | CT18: =+CT20/CT11*1000 | CU18: =+CU20/CU11*1000 | CW18: =+CW20/CW11*1000 | CX18: =+CX20/CX11*1000 | CY18: =+CY20/CY11*1000 | DA18: =+DA20/DA11*1000 | DB18: =+DB20/DB11*1000 | DC18: =+DC20/DC11*1000 | DE18: =+DE20/DE11*1000 | DF18: =+DF20/DF11*1000 | DG18: =+DG20/DG11*1000 | DI18: =+DI20/DI11*1000 | DJ18: =+DJ20/DJ11*1000 | DK18: =+DK20/DK11*1000 | DM18: =+DM20/DM11*1000 | DN18: =+DN20/DN11*1000 | DO18: =+DO20/DO11*1000 | DQ18: =+DQ20/DQ11*1000 | DR18: =+DR20/DR11*1000 | DS18: =+DS20/DS11*1000 | DU18: =+DU20/DU11*1000 | DV18: =+DV20/DV11*1000 | DW18: =+DW20/DW11*1000 | DY18: =+DY20/DY11*1000 | DZ18: =+DZ20/DZ11*1000 | EA18: =+EA20/EA11*1000 | EC18: =+EC20/EC11*1000 | ED18: =+ED20/ED11*1000 | EE18: =+EE20/EE11*1000 | EG18: =+EG20/EG11*1000 | EH18: =+EH20/EH11*1000 | EI18: =+EI20/EI11*1000 | EK18: =+EK20/EK11*1000 | EL18: =+EL20/EL11*1000 | EM18: =+EM20/EM11*1000 | EO18: =+EO20/EO11*1000 | EP18: =+EP20/EP11*1000 | EQ18: =+EQ20/EQ11*1000 | ES18: =+ES20/ES11*1000 | ET18: =+ET20/ET11*1000 | EU18: =+EU20/EU11*1000 | EW18: =+EW20/EW11*1000 | EX18: =+EX20/EX11*1000 | EY18: =+EY20/EY11*1000 | FA18: =+FA20/FA11*1000 | FB18: =+FB20/FB11*1000 | FC18: =+FC20/FC11*1000 | FE18: =+FE20/FE11*1000 | FF18: =+FF20/FF11*1000 | FG18: =+FG20/FG11*1000 | FI18: =+FI20/FI11*1000 | FJ18: =+FJ20/FJ11*1000 | FK18: =+FK20/FK11*1000 | FM18: =+FM20/FM11*1000 | FN18: =+FN20/FN11*1000 | FO18: =+FO20/FO11*1000
B19: YoY change in average airfare ticket price | D19: =D18/C18-1 | E19: =E18/D18-1 | F19: =F18/E18-1 | G19: =G18/F18-1 | H19: =H18/G18-1 | I19: =I18/H18-1 | J19: =J18/I18-1 | K19: =K18/J18-1 | ... AT19: =AT18/AS18-1 | BL19: =BL18/BH18-1 | BM19: =BM18/BI18-1 | BN19: =BN18/BJ18-1 | BP19: =BP18/BL18-1 | BQ19: =BQ18/BM18-1 | BR19: =BR18/BN18-1 | BT19: =BT18/BP18-1 | BU19: =BU18/BQ18-1 | BV19: =BV18/BR18-1 | BX19: =BX18/BT18-1 | BY19: =BY18/BU18-1 | BZ19: =BZ18/BV18-1 | CB19: =CB18/BX18-1 | CC19: =CC18/BY18-1 | CD19: =CD18/BZ18-1 | CF19: =CF18/CB18-1 | CG19: =CG18/CC18-1 | CH19: =CH18/CD18-1 | CJ19: =CJ18/CF18-1 | CK19: =CK18/CG18-1 | CL19: =CL18/CH18-1 | CN19: =CN18/CJ18-1 | CO19: =CO18/CK18-1 | CP19: =CP18/CL18-1 | CR19: =CR18/CN18-1 | CS19: =CS18/CN18-1 | CT19: =CT18/CO18-1 | CU19: =CU18/CP18-1 | CW19: =CW18/CS18-1 | CX19: =CX18/CT18-1 | CY19: =CY18/CU18-1 | DA19: =DA18/CW18-1 | DB19: =DB18/CX18-1 | DC19: =DC18/CY18-1 | DE19: =DE18/DA18-1 | DF19: =DF18/DB18-1 | DG19: =DG18/DC18-1 | DI19: =DI18/DE18-1 | DJ19: =DJ18/DF18-1 | DK19: =DK18/DG18-1 | DM19: =DM18/DI18-1 | DN19: =DN18/DJ18-1 | DO19: =DO18/DK18-1 | DQ19: =DQ18/DM18-1 | DR19: =DR18/DN18-1 | DS19: =DS18/DO18-1 | DU19: =DU18/DQ18-1 | DV19: =DV18/DR18-1 | DW19: =DW18/DS18-1 | DY19: =DY18/DU18-1 | DZ19: =DZ18/DV18-1 | EA19: =EA18/DW18-1 | EC19: =EC18/DY18-1 | ED19: =ED18/DZ18-1 | EE19: =EE18/EA18-1 | EG19: =EG18/EC18-1 | EH19: =EH18/ED18-1 | EI19: =EI18/EE18-1 | EK19: =EK18/EG18-1 | EL19: =EL18/EH18-1 | EM19: =EM18/EI18-1 | EO19: =EO18/EK18-1 | EP19: =EP18/EL18-1 | EQ19: =EQ18/EM18-1 | ES19: =ES18/EO18-1 | ET19: =ET18/EP18-1 | EU19: =EU18/EQ18-1 | EW19: =EW18/ES18-1 | EX19: =EX18/ET18-1 | EY19: =EY18/EU18-1 | FA19: =FA18/EW18-1 | FB19: =FB18/EX18-1 | FC19: =FC18/EY18-1 | FE19: =FE18/FA18-1 | FF19: =FF18/FB18-1 | FG19: =FG18/FC18-1 | FI19: =FI18/FE18-1 | FJ19: =FJ18/FF18-1 | FK19: =FK18/FG18-1 | FM19: =FM18/FI18-1 | FN19: =FN18/FJ18-1 | FO19: =FO18/FK18-1
B20: Overall Passenger Revenue | C20: =+C35+C50 | D20: =+D35+D50 | E20: =+E35+E50 | F20: =+F35+F50 | G20: =+G35+G50 | H20: =+H35+H50 | I20: =+I35+I50 | J20: =+J35+J50 | ... AT20: =+AT35+AT50 | BD20: =+BD35+BD50 | BE20: =+BE35+BE50 | BF20: =+BF35+BF50 | BH20: =+BH35+BH50 | BI20: =+BI35+BI50 | BJ20: =+BJ35+BJ50 | BL20: =+BL35+BL50 | BM20: =+BM35+BM50 | BN20: =+BN35+BN50 | BP20: =+BP35+BP50 | BQ20: =+BQ35+BQ50 | BR20: =+BR35+BR50 | BT20: =+BT35+BT50 | BU20: =+BU35+BU50 | BV20: =+BV35+BV50 | BX20: =+BX35+BX50 | BY20: =+BY35+BY50 | BZ20: =+BZ35+BZ50 | CB20: =+CB35+CB50 | CC20: =+CC35+CC50 | CD20: =+CD35+CD50 | CF20: =+CF35+CF50 | CG20: =+CG35+CG50 | CH20: =+CH35+CH50 | CJ20: =+CJ35+CJ50 | CK20: =+CK35+CK50 | CL20: =+CL35+CL50 | CN20: =+CN35+CN50 | CO20: =+CO35+CO50 | CP20: =+CP35+CP50 | CR20: =+CR35+CR50 | CS20: =+CS35+CS50 | CT20: =+CT35+CT50 | CU20: =+CU35+CU50 | CW20: =+CW35+CW50 | CX20: =+CX35+CX50 | CY20: =+CY35+CY50 | DA20: =+DA35+DA50 | DB20: =+DB35+DB50 | DC20: =+DC35+DC50 | DE20: =+DE35+DE50 | DF20: =+DF35+DF50 | DG20: =+DG35+DG50 | DI20: =+DI35+DI50 | DJ20: =+DJ35+DJ50 | DK20: =+DK35+DK50 | DM20: =+DM35+DM50 | DN20: =+DN35+DN50 | DO20: =+DO35+DO50 | DQ20: =+DQ35+DQ50 | DR20: =+DR35+DR50 | DS20: =+DS35+DS50 | DU20: =+DU35+DU50 | DV20: =+DV35+DV50 | DW20: =+DW35+DW50 | DY20: =+DY35+DY50 | DZ20: =+DZ35+DZ50 | EA20: =+EA35+EA50 | EC20: =+EC35+EC50 | ED20: =+ED35+ED50 | EE20: =+EE35+EE50 | EG20: =+EG35+EG50 | EH20: =+EH35+EH50 | EI20: =+EI35+EI50 | EK20: =+EK35+EK50 | EL20: =+EL35+EL50 | EM20: =+EM35+EM50 | EO20: =+EO35+EO50 | EP20: =+EP35+EP50 | EQ20: =+EQ35+EQ50 | ES20: =+ES35+ES50 | ET20: =+ET35+ET50 | EU20: =+EU35+EU50 | EW20: =+EW35+EW50 | EX20: =+EX35+EX50 | EY20: =+EY35+EY50 | FA20: =+FA35+FA50 | FB20: =+FB35+FB50 | FC20: =+FC35+FC50 | FE20: =+FE35+FE50 | FF20: =+FF35+FF50 | FG20: =+FG35+FG50 | FI20: =+FI35+FI50 | FJ20: =+FJ35+FJ50 | FK20: =+FK35+FK50 | FM20: =+FM35+FM50 | FN20: =+FN35+FN50 | FO20: =+FO35+FO50
A22: ask | B22: FSC's ask | C22: 23455 | D22: 26038 | E22: 28477 | F22: 32214 | G22: 33186 | H22: 37428 | I22: 41552 | J22: 45892 | K22: 49334 | L22: 54306 | M22: 57104 | N22: 60295 | O22: 58114 | P22: 61908.551 | Q22: 62790.254 | R22: 63050.052 | S22: 59280.17 | T22: 74062.4 | U22: 82766.395 | V22: 91769 | W22: 102461.79 | X22: 115478.34 | Y22: 111167 | Z22: 115748 | AA22: 126340.02 | AB22: 129594.86 | AC22: 127215.38 | AD22: 134711 | AE22: 142680.58 | AF22: 146085.48 | AG22: 150138.11 | AH22: 155362.02 | AI22: 163243.91 | AJ22: 34609 | AK22: 13228 | AL22: 20056 | AM22: 85607 | AN22: 111789 | AO22: =SUM(FI22:FJ22) | AP22: =SUM(FM22:FN22) | AQ22: =+AP22*(1+AQ23) | AR22: =+AQ22*(1+AR23) | AS22: =+AR22*(1+AS23) | AT22: =+AS22*(1+AT23) | AX22: =L22 | AZ22: 28172 | BA22: =BB22-AZ22 | BB22: =M22 | BD22: 28928 | BE22: =BF22-BD22 | BF22: =N22 | BH22: 28801 | BI22: =BJ22-BH22 | BJ22: =O22 | BL22: 29839.107 | BM22: =BN22-BL22 | BN22: =P22 | BP22: 32419 | BQ22: =BR22-BP22 | BR22: =Q22 | BT22: 29537.302 | BU22: =BV22-BT22 | BV22: =R22 | BX22: 26831.5 | BY22: =BZ22-BX22 | BZ22: =S22 | CB22: 35249.9 | CC22: =CD22-CB22 | CD22: =T22 | CF22: 39535 | CG22: =CH22-CF22 | CH22: =U22 | CJ22: 43813.693 | CK22: =CL22-CJ22 | CL22: =V22 | CN22: 49836 | CO22: =CP22-CN22 | CP22: =W22 | CR22: 56949.234 | CS22: 56949.234 | CT22: =CU22-CR22 | CU22: =X22 | CW22: 55749.52 | CX22: =CY22-CW22 | CY22: =Y22 | DA22: 55680.314 | DB22: =+DC22-DA22 | DC22: =Z22 | DE22: 61135.663 | DF22: =+DG22-DE22 | DG22: =AA22 | DI22: 65350.956 | DJ22: =+DK22-DI22 | DK22: =AB22 | DM22: 62186.792 | DN22: =+DO22-DM22 | DO22: =AC22 | DQ22: 65474.415 | DR22: =DS22-DQ22 | DS22: =AD22 | DU22: 69689.145 | DV22: =DW22-DU22 | DW22: =AE22 | DY22: 72646.509 | DZ22: =EA22-DY22 | EA22: =AF22 | EC22: 73444.073 | ED22: =EE22-EC22 | EE22: =AG22 | EG22: 75770.382 | EH22: =EI22-EG22 | EI22: =AH22 | EK22: 80814.422 | EL22: =EM22-EK22 | EM22: =AI22 | EO22: =SUMIFS(Monthly!$10:$10,Monthly!$8:$8,">="&DATE(MID(EO$3,3,4),1,1),Monthly!$8:$8,"<="&DATE(MID(EO$3,3,4),6,30)) | EP22: =EQ22-EO22 | EQ22: =AJ22 | ES22: =SUMIFS(Monthly!$10:$10,Monthly!$8:$8,">="&DATE(MID(ES$3,3,4),1,1),Monthly!$8:$8,"<="&DATE(MID(ES$3,3,4),6,30)) | ET22: =EU22-ES22 | EU22: =AK22 | EW22: =SUMIFS(Monthly!$10:$10,Monthly!$8:$8,">="&DATE(MID(EW$3,3,4),1,1),Monthly!$8:$8,"<="&DATE(MID(EW$3,3,4),6,30)) | EX22: =+EY22-EW22 | EY22: =AL22 | FA22: =SUMIFS(Monthly!$10:$10,Monthly!$8:$8,">="&DATE(MID(FA$3,3,4),1,1),Monthly!$8:$8,"<="&DATE(MID(FA$3,3,4),6,30)) | FB22: =+FC22-FA22 | FC22: =AM22 | FE22: =SUMIFS(Monthly!$10:$10,Monthly!$8:$8,">="&DATE(MID(FE$3,3,4),1,1),Monthly!$8:$8,"<="&DATE(MID(FE$3,3,4),6,30)) | FF22: =+FG22-FE22 | FG22: =AN22 | FI22: =SUMIFS(Monthly!$10:$10,Monthly!$8:$8,">="&DATE(MID(FI$3,3,4),1,1),Monthly!$8:$8,"<="&DATE(MID(FI$3,3,4),6,30)) | FJ22: =+FK22-FI22 | FK22: =AO22 | FM22: =SUMIFS(Monthly!$10:$10,Monthly!$8:$8,">="&DATE(MID(FM$3,3,4),1,1),Monthly!$8:$8,"<="&DATE(MID(FM$3,3,4),6,30)) | FN22: =FJ22*(1+FN23) | FO22: =AP22
B23: YoY change in overall capacity (ASK) | D23: =D22/C22-1 | E23: =E22/D22-1 | F23: =F22/E22-1 | G23: =G22/F22-1 | H23: =H22/G22-1 | I23: =I22/H22-1 | J23: =J22/I22-1 | K23: =K22/J22-1 | ... AP23: =AP22/AO22-1 | AQ23: 0.05 | AR23: 0.05 | AS23: 0.05 | AT23: 0.05 | BB23: =BB22/AX22-1 | BD23: =BD22/AZ22-1 | BE23: =BE22/BA22-1 | BF23: =BF22/BB22-1 | BH23: =BH22/BD22-1 | BI23: =BI22/BE22-1 | BJ23: =BJ22/BF22-1 | BL23: =BL22/BH22-1 | BM23: =BM22/BI22-1 | BN23: =BN22/BJ22-1 | BP23: =BP22/BL22-1 | BQ23: =BQ22/BM22-1 | BR23: =BR22/BN22-1 | BT23: =BT22/BP22-1 | BU23: =BU22/BQ22-1 | BV23: =BV22/BR22-1 | BX23: =BX22/BT22-1 | BY23: =BY22/BU22-1 | BZ23: =BZ22/BV22-1 | CB23: =CB22/BX22-1 | CC23: =CC22/BY22-1 | CD23: =CD22/BZ22-1 | CF23: =CF22/CB22-1 | CG23: =CG22/CC22-1 | CH23: =CH22/CD22-1 | CJ23: =CJ22/CF22-1 | CK23: =CK22/CG22-1 | CL23: =CL22/CH22-1 | CN23: =CN22/CJ22-1 | CO23: =CO22/CK22-1 | CP23: =CP22/CL22-1 | CR23: =CR22/CN22-1 | CS23: =CS22/CN22-1 | CT23: =CT22/CO22-1 | CU23: =CU22/CP22-1 | CW23: =CW22/CS22-1 | CX23: =CX22/CT22-1 | CY23: =CY22/CU22-1 | DA23: =DA22/CW22-1 | DB23: =DB22/CX22-1 | DC23: =DC22/CY22-1 | DE23: =DE22/DA22-1 | DF23: =DF22/DB22-1 | DG23: =DG22/DC22-1 | DI23: =DI22/DE22-1 | DJ23: =DJ22/DF22-1 | DK23: =DK22/DG22-1 | DM23: =DM22/DI22-1 | DN23: =DN22/DJ22-1 | DO23: =DO22/DK22-1 | DQ23: =DQ22/DM22-1 | DR23: =DR22/DN22-1 | DS23: =DS22/DO22-1 | DU23: =DU22/DQ22-1 | DV23: =DV22/DR22-1 | DW23: =DW22/DS22-1 | DY23: =DY22/DU22-1 | DZ23: =DZ22/DV22-1 | EA23: =EA22/DW22-1 | EC23: =EC22/DY22-1 | ED23: =ED22/DZ22-1 | EE23: =EE22/EA22-1 | EG23: =EG22/EC22-1 | EH23: =EH22/ED22-1 | EI23: =EI22/EE22-1 | EK23: =+EK22/EG22-1 | EL23: =+EL22/EH22-1 | EM23: =AI23 | EO23: =+EO22/EK22-1 | EP23: =+EP22/EL22-1 | EQ23: =+EQ22/EM22-1 | ES23: =+ES22/EO22-1 | ET23: =+ET22/EP22-1 | EU23: =+EU22/EQ22-1 | EW23: =+EW22/ES22-1 | EX23: =+EX22/ET22-1 | EY23: =+EY22/EU22-1 | FA23: =+FA22/EW22-1 | FB23: =+FB22/EX22-1 | FC23: =+FC22/EY22-1 | FE23: =+FE22/FA22-1 | FF23: =+FF22/FB22-1 | FG23: =+FG22/FC22-1 | FI23: =+FI22/FE22-1 | FJ23: =+FJ22/FF22-1 | FK23: =+FK22/FG22-1 | FM23: =+FM22/FI22-1 | FN23: 0.09 | FO23: =+FO22/FK22-1
A24: rpk | B24: FSC's rpk | C24: 17262 | D24: 20069 | E24: 22088 | F24: 24461 | G24: 24433 | H24: 27527 | I24: 29097 | J24: 32727 | K24: 35341 | L24: 40185 | M24: 38962 | N24: 40679.125 | O24: 41502 | P24: 47152.792 | Q24: 44792.224 | R24: 49041.021 | S24: 42773.752 | T24: 57282.3 | U24: 65109.775 | V24: 72939 | W24: 81800.757 | X24: 90975.081 | Y24: 89440.308 | Z24: 96587.691 | AA24: 101535.43 | AB24: 103836.84 | AC24: 104570.79 | AD24: =AD22*0.833 | AE24: 122330.03 | AF24: 123477.75 | AG24: 126662.83 | AH24: 130629.74 | AI24: 134396.83 | AJ24: 20079 | AK24: 4120 | AL24: 14764 | AM24: 73342 | AN24: 93016 | AO24: =SUM(FI24:FJ24) | AP24: =SUM(FM24:FN24) | AQ24: =AQ28*AQ22 | AR24: =AR28*AR22 | AS24: =AS28*AS22 | AT24: =AT28*AT22 | AV24: =AX24-AW24 | AW24: 21428 | AX24: =L24 | AZ24: 20044.46 | BA24: =BB24-AZ24 | BB24: =M24 | BD24: =BD22*0.663 | BE24: =BF24-BD24 | BF24: =N24 | BH24: 19325.471 | BI24: =BJ24-BH24 | BJ24: =O24 | BL24: 22579.468 | BM24: =BN24-BL24 | BN24: =P24 | BP24: 23295 | BQ24: =BR24-BP24 | BR24: =Q24 | BT24: 23071.905 | BU24: =BV24-BT24 | BV24: =R24 | BX24: 17276.5 | BY24: =BZ24-BX24 | BZ24: =S24 | CB24: 26834.6 | CC24: =CD24-CB24 | CD24: =T24 | CF24: =CF22*0.781 | CG24: =CH24-CF24 | CH24: =U24 | CJ24: =CJ22*0.791 | CK24: =CL24-CJ24 | CL24: =V24 | CN24: 38938.113 | CO24: =CP24-CN24 | CP24: =W24 | CR24: 45579.621 | CS24: 45579.621 | CT24: =CU24-CR24 | CU24: =X24 | CW24: 43757.949 | CX24: =CY24-CW24 | CY24: =Y24 | DA24: 46783.64 | DB24: =+DC24-DA24 | DC24: =Z24 | DE24: 48476.621 | DF24: =+DG24-DE24 | DG24: =AA24 | DI24: 52348.668 | DJ24: =+DK24-DI24 | DK24: =AB24 | DM24: 50543.063 | DN24: =+DO24-DM24 | DO24: =AC24 | DQ24: 54713.1 | DR24: =+DS24-DQ24 | DS24: =AD24 | DU24: 59835.42 | DV24: =+DW24-DU24 | DW24: =AE24 | DY24: 61367.549 | DZ24: =+EA24-DY24 | EA24: =AF24 | EC24: 62241.855 | ED24: =+EE24-EC24 | EE24: =AG24 | EG24: 63809.914 | EH24: =+EI24-EG24 | EI24: =AH24 | EK24: 68078.448 | EL24: =+EM24-EK24 | EM24: =AI24 | EO24: =SUMIFS(Monthly!$46:$46,Monthly!$8:$8,">="&DATE(MID(EO$3,3,4),1,1),Monthly!$8:$8,"<="&DATE(MID(EO$3,3,4),6,30)) | EP24: =+EQ24-EO24 | EQ24: =AJ24 | ES24: =SUMIFS(Monthly!$46:$46,Monthly!$8:$8,">="&DATE(MID(ES$3,3,4),1,1),Monthly!$8:$8,"<="&DATE(MID(ES$3,3,4),6,30)) | ET24: =+EU24-ES24 | EU24: =AK24 | EW24: =SUMIFS(Monthly!$46:$46,Monthly!$8:$8,">="&DATE(MID(EW$3,3,4),1,1),Monthly!$8:$8,"<="&DATE(MID(EW$3,3,4),6,30)) | EX24: =+EY24-EW24 | EY24: =AL24 | FA24: =SUMIFS(Monthly!$46:$46,Monthly!$8:$8,">="&DATE(MID(FA$3,3,4),1,1),Monthly!$8:$8,"<="&DATE(MID(FA$3,3,4),6,30)) | FB24: =+FC24-FA24 | FC24: =AM24 | FE24: =SUMIFS(Monthly!$46:$46,Monthly!$8:$8,">="&DATE(MID(FE$3,3,4),1,1),Monthly!$8:$8,"<="&DATE(MID(FE$3,3,4),6,30)) | FF24: =+FG24-FE24 | FG24: =AN24 | FI24: 56651 | FJ24: =+FK24-FI24 | FK24: =AO24 | FM24: =SUMIFS(Monthly!$46:$46,Monthly!$8:$8,">="&DATE(MID(FM$3,3,4),1,1),Monthly!$8:$8,"<="&DATE(MID(FM$3,3,4),6,30)) | FN24: =FN22*FN28 | FO24: =AP24
A25: pax traffic growth | B25: YoY change in passenger traffic (RPK) | D25: =D24/C24-1 | E25: =E24/D24-1 | F25: =F24/E24-1 | G25: =G24/F24-1 | H25: =H24/G24-1 | I25: =I24/H24-1 | J25: =J24/I24-1 | K25: =K24/J24-1 | L25: =0.137 | M25: -0.031 | N25: =N24/M24-1 | O25: 0.027 | P25: =P24/O24-1 | Q25: =Q24/P24-1 | R25: =R24/Q24-1 | S25: =S24/R24-1 | T25: =T24/S24-1 | U25: =U24/T24-1 | V25: =V24/U24-1 | W25: =W24/V24-1 | ... AK25: =AK24/AJ24-1 | AL25: =+AL24/AK24-1 | AM25: =+AM24/AL24-1 | AN25: =+AN24/AM24-1 | AO25: =+AO24/AN24-1 | AP25: =+AP24/AO24-1 | AQ25: =+AQ24/AP24-1 | AR25: =+AR24/AQ24-1 | AS25: =+AS24/AR24-1 | AT25: =+AT24/AS24-1 | AX25: =L25 | BB25: =M25 | BD25: =BD24/AZ24-1 | BE25: =BE24/BA24-1 | BF25: =N25 | BH25: =BH24/BD24-1 | BI25: =BI24/BE24-1 | BJ25: =O25 | BL25: =BL24/BH24-1 | BM25: =BM24/BI24-1 | BN25: =P25 | BP25: =BP24/BL24-1 | BQ25: =BQ24/BM24-1 | BR25: =Q25 | BT25: =BT24/BP24-1 | BU25: =BU24/BQ24-1 | BV25: =R25 | BX25: =BX24/BT24-1 | BY25: =BY24/BU24-1 | BZ25: =S25 | CB25: =CB24/BX24-1 | CC25: =CC24/BY24-1 | CD25: =T25 | CF25: =CF24/CB24-1 | CG25: =CG24/CC24-1 | CH25: =U25 | CJ25: =CJ24/CF24-1 | CK25: =CK24/CG24-1 | CL25: =V25 | CN25: =CN24/CJ24-1 | CO25: =CO24/CK24-1 | CP25: =W25 | CR25: =CR24/CN24-1 | CS25: =CS24/CN24-1 | CT25: =CT24/CO24-1 | CU25: =X25 | CW25: =CW24/CS24-1 | CX25: =CX24/CT24-1 | CY25: =Y25 | DA25: =DA24/CW24-1 | DB25: =DB24/CX24-1 | DC25: =Z25 | DE25: =DE24/DA24-1 | DF25: =DF24/DB24-1 | DG25: =AA25 | DI25: =+DI24/DE24-1 | DJ25: =DJ24/DF24-1 | DK25: =AB25 | DM25: =+DM24/DI24-1 | DN25: =DN24/DJ24-1 | DO25: =AC25 | DQ25: =+DQ24/DM24-1 | DR25: =+DR24/DN24-1 | DS25: =AD25 | DU25: =+DU24/DQ24-1 | DV25: =+DV24/DR24-1 | DW25: =AE25 | DY25: =+DY24/DU24-1 | DZ25: =+DZ24/DV24-1 | EA25: =AF25 | EC25: =+EC24/DY24-1 | ED25: =+ED24/DZ24-1 | EE25: =AG25 | EG25: =+EG24/EC24-1 | EH25: =+EH24/ED24-1 | EI25: =AH25 | EK25: =+EK24/EG24-1 | EL25: =+EL24/EH24-1 | EM25: =AI25 | EO25: =+EO24/EK24-1 | EP25: =+EP24/EL24-1 | EQ25: =+EQ24/EM24-1 | ES25: =+ES24/EO24-1 | ET25: =+ET24/EP24-1 | EU25: =+EU24/EQ24-1 | EW25: =+EW24/ES24-1 | EX25: =+EX24/ET24-1 | EY25: =+EY24/EU24-1 | FA25: =+FA24/EW24-1 | FB25: =+FB24/EX24-1 | FC25: =+FC24/EY24-1 | FE25: =+FE24/FA24-1 | FF25: =+FF24/FB24-1 | FG25: =+FG24/FC24-1 | FI25: =+FI24/FE24-1 | FJ25: =+FJ24/FF24-1 | FK25: =+FK24/FG24-1 | FM25: =+FM24/FI24-1 | FN25: =+FN24/FJ24-1 | FO25: =+FO24/FK24-1
A26: passenger | B26: FSC's Passenger nos (000s) | C26: 5086 | D26: 6193 | E26: 7058 | F26: 7731 | G26: 7391 | H26: 8363 | I26: 8867 | J26: 9750 | K26: 10381 | L26: 10985 | M26: 10018 | N26: 10299 | O26: 10516 | P26: 11864.37 | Q26: 11268.778 | R26: 12321.256 | S26: 10058.995 | T26: 13664 | U26: 15438.243 | V26: 18097 | W26: 23253.427 | X26: 24959.429 | Y26: 24558 | Z26: 26796.249 | AA26: 27581.331 | AB26: 28960.689 | AC26: 29919.576 | AD26: 31600 | AE26: 34064.859 | AF26: 34322.693 | AG26: 34819.871 | AH26: 35468.218 | AI26: 35233.131 | AJ26: 4631 | AK26: 717 | AL26: 2804 | AM26: 17985 | AN26: 22827 | AO26: =SUM(FI26:FJ26) | AP26: =SUM(FM26:FN26) | AQ26: =AQ24/AQ27*1000 | AR26: =AR24/AR27*1000 | AS26: =AS24/AS27*1000 | AT26: =AT24/AT27*1000 | AX26: =L26 | BB26: =M26 | BE26: =BF26-BD26 | BF26: =N26 | BH26: 4919.6 | BI26: =BJ26-BH26 | BJ26: =O26 | BL26: 5757.208 | BM26: =BN26-BL26 | BN26: =P26 | BP26: 5890.989 | BQ26: =BR26-BP26 | BR26: =Q26 | BT26: 5932.699 | BU26: =BV26-BT26 | BV26: =R26 | BX26: 4018.624 | BY26: =BZ26-BX26 | BZ26: =S26 | CB26: 6404.3 | CC26: =CD26-CB26 | CD26: =T26 | CF26: 7333 | CG26: =CH26-CF26 | CH26: =U26 | CJ26: 8144.335 | CK26: =CL26-CJ26 | CL26: =V26 | CN26: 10960 | CO26: =CP26-CN26 | CP26: =W26 | CR26: 12462.541 | CS26: 12462.541 | CT26: =CU26-CR26 | CU26: =X26 | CW26: 11938.15 | CX26: =CY26-CW26 | CY26: =Y26 | DA26: 12953.548 | DB26: =+DC26-DA26 | DC26: =Z26 | DE26: 13175.861 | DF26: =+DG26-DE26 | DG26: =AA26 | DI26: 14311.778 | DJ26: =+DK26-DI26 | DK26: =AB26 | DM26: 14497.032 | DN26: =+DO26-DM26 | DO26: =AC26 | DQ26: 15436.937 | DR26: =DS26-DQ26 | DS26: =AD26 | DU26: 16800.331 | DV26: =DW26-DU26 | DW26: =AE26 | DY26: 17248.591 | DZ26: =EA26-DY26 | EA26: =AF26 | EC26: 17162.995 | ED26: =EE26-EC26 | EE26: =AG26 | EG26: 17484.704 | EH26: =EI26-EG26 | EI26: =AH26 | EK26: 18261.05 | EL26: =EM26-EK26 | EM26: =AI26 | EO26: 4389 | EP26: =EQ26-EO26 | EQ26: =AJ26 | ES26: 157 | ET26: =EU26-ES26 | EU26: =AK26 | EW26: 335 | EX26: =+EY26-EW26 | EY26: =AL26 | FA26: 7816 | FB26: =+FC26-FA26 | FC26: =AM26 | FE26: 10660 | FF26: =+FG26-FE26 | FG26: =AN26 | FI26: 13627 | FJ26: =+FK26-FI26 | FK26: =AO26 | FM26: 16006 | FN26: =FN24/FN27*1000 | FO26: =AP26
B27: FSC's Trip length (kms) | C27: =C24/C26*1000 | D27: =D24/D26*1000 | E27: =E24/E26*1000 | F27: =F24/F26*1000 | G27: =G24/G26*1000 | H27: =H24/H26*1000 | I27: =I24/I26*1000 | J27: =J24/J26*1000 | ... AP27: =AP24/AP26*1000 | AQ27: =AP27 | AR27: =AQ27 | AS27: =AR27 | AT27: =AS27 | AX27: =L27 | BB27: =M27 | BE27: =BE24/BE26*1000 | BF27: =N27 | BH27: =BH24/BH26*1000 | BI27: =BI24/BI26*1000 | BJ27: =O27 | BL27: =BL24/BL26*1000 | BM27: =BM24/BM26*1000 | BN27: =P27 | BP27: =BP24/BP26*1000 | BQ27: =BQ24/BQ26*1000 | BR27: =Q27 | BT27: =BT24/BT26*1000 | BU27: =BU24/BU26*1000 | BV27: =R27 | BX27: =BX24/BX26*1000 | BY27: =BY24/BY26*1000 | BZ27: =S27 | CB27: =CB24/CB26*1000 | CC27: =CC24/CC26*1000 | CD27: =T27 | CF27: =CF24/CF26*1000 | CG27: =CG24/CG26*1000 | CH27: =U27 | CJ27: =CJ24/CJ26*1000 | CK27: =CK24/CK26*1000 | CL27: =V27 | CN27: =CN24/CN26*1000 | CO27: =CO24/CO26*1000 | CP27: =W27 | CR27: =CR24/CR26*1000 | CS27: =CS24/CS26*1000 | CT27: =CT24/CT26*1000 | CU27: =X27 | CW27: =CW24/CW26*1000 | CX27: =CX24/CX26*1000 | CY27: =Y27 | DA27: =DA24/DA26*1000 | DB27: =DB24/DB26*1000 | DC27: =Z27 | DE27: =DE24/DE26*1000 | DF27: =DF24/DF26*1000 | DG27: =AA27 | DI27: =DI24/DI26*1000 | DJ27: =DJ24/DJ26*1000 | DK27: =AB27 | DM27: =DM24/DM26*1000 | DN27: =DN24/DN26*1000 | DO27: =AC27 | DQ27: =DQ24/DQ26*1000 | DR27: =DR24/DR26*1000 | DS27: =AD27 | DU27: =DU24/DU26*1000 | DV27: =DV24/DV26*1000 | DW27: =AE27 | DY27: =DY24/DY26*1000 | DZ27: =DZ24/DZ26*1000 | EA27: =AF27 | EC27: =EC24/EC26*1000 | ED27: =ED24/ED26*1000 | EE27: =AG27 | EG27: =EG24/EG26*1000 | EH27: =EH24/EH26*1000 | EI27: =AH27 | EK27: =EK24/EK26*1000 | EL27: =EL24/EL26*1000 | EM27: =AI27 | EO27: =EO24/EO26*1000 | EP27: =EP24/EP26*1000 | EQ27: =AJ27 | ES27: =ES24/ES26*1000 | ET27: =ET24/ET26*1000 | EU27: =AK27 | EW27: =EW24/EW26*1000 | EX27: =EX24/EX26*1000 | EY27: =AL27 | FA27: =FA24/FA26*1000 | FB27: =FB24/FB26*1000 | FC27: =AM27 | FE27: =FE24/FE26*1000 | FF27: =FF24/FF26*1000 | FG27: =AN27 | FI27: =FI24/FI26*1000 | FJ27: =FJ24/FJ26*1000 | FK27: =AO27 | FM27: =FM24/FM26*1000 | FN27: =FK27 | FO27: =AP27
A28: load factor | B28: FSC's Passenger load factor | C28: =C24/C22 | D28: =D24/D22 | E28: =E24/E22 | F28: =F24/F22 | G28: =G24/G22 | H28: =H24/H22 | I28: =I24/I22 | J28: =J24/J22 | ... AP28: =AP24/AP22 | AQ28: =AP28 | AR28: =AQ28 | AS28: =AR28 | AT28: =AS28 | AX28: =L28 | AZ28: =AZ24/AZ22 | BA28: =BA24/BA22 | BB28: =M28 | BD28: =BD24/BD22 | BE28: =BE24/BE22 | BF28: =N28 | BH28: =BH24/BH22 | BI28: =BI24/BI22 | BJ28: =O28 | BL28: =BL24/BL22 | BM28: =BM24/BM22 | BN28: =P28 | BP28: =BP24/BP22 | BQ28: =BQ24/BQ22 | BR28: =Q28 | BT28: =BT24/BT22 | BU28: =BU24/BU22 | BV28: =R28 | BX28: =BX24/BX22 | BY28: =BY24/BY22 | BZ28: =S28 | CB28: =CB24/CB22 | CC28: =CC24/CC22 | CD28: =T28 | CF28: =CF24/CF22 | CG28: =CG24/CG22 | CH28: =U28 | CJ28: =CJ24/CJ22 | CK28: =CK24/CK22 | CL28: =V28 | CN28: =CN24/CN22 | CO28: =CO24/CO22 | CP28: =W28 | CR28: =CR24/CR22 | CS28: =CS24/CS22 | CT28: =CT24/CT22 | CU28: =X28 | CW28: =CW24/CW22 | CX28: =CX24/CX22 | CY28: =Y28 | DA28: =DA24/DA22 | DB28: =DB24/DB22 | DC28: =Z28 | DE28: =DE24/DE22 | DF28: =DF24/DF22 | DG28: =AA28 | DI28: =DI24/DI22 | DJ28: =DJ24/DJ22 | DK28: =AB28 | DM28: =DM24/DM22 | DN28: =DN24/DN22 | DO28: =AC28 | DQ28: =DQ24/DQ22 | DR28: =DR24/DR22 | DS28: =AD28 | DU28: =DU24/DU22 | DV28: =DV24/DV22 | DW28: =AE28 | DY28: =DY24/DY22 | DZ28: =DZ24/DZ22 | EA28: =AF28 | EC28: =EC24/EC22 | ED28: =ED24/ED22 | EE28: =AG28 | EG28: =EG24/EG22 | EH28: =EH24/EH22 | EI28: =AH28 | EK28: =EK24/EK22 | EL28: =EL24/EL22 | EM28: =AI28 | EO28: =EO24/EO22 | EP28: =EP24/EP22 | EQ28: =EQ24/EQ22 | ES28: =ES24/ES22 | ET28: =ET24/ET22 | EU28: =EU24/EU22 | EW28: =EW24/EW22 | EX28: =EX24/EX22 | EY28: =EY24/EY22 | FA28: =FA24/FA22 | FB28: =FB24/FB22 | FC28: =FC24/FC22 | FE28: =FE24/FE22 | FF28: =FF24/FF22 | FG28: =FG24/FG22 | FI28: =FI24/FI22 | FJ28: =FJ24/FJ22 | FK28: =FK24/FK22 | FM28: =FM24/FM22 | FN28: =FJ28 | FO28: =FO24/FO22
B29: FSC's pax yield | C29: =C112/C24 | D29: =D112/D24 | E29: =E112/E24 | F29: =F112/F24 | G29: =G112/G24 | H29: =H112/H24 | I29: =I112/I24 | J29: =J112/J24 | ... AH29: =AH112/AH24 | AI29: =AI35/AI24 | AJ29: =AJ35/AJ24 | AK29: =AK35/AK24 | AL29: =AL35/AL24 | AM29: =AM35/AM24 | AN29: =AN35/AN24 | AO29: =AO35/AO24 | AP29: =AP35/AP24 | AQ29: =+AP29*(1+AQ30) | AR29: =+AQ29*(1+AR30) | AS29: =+AR29*(1+AS30) | AT29: =+AS29*(1+AT30) | AV29: =AV35/AV24 | AW29: =AW35/AW24 | AX29: =L29 | AZ29: =AZ35/AZ24 | BA29: =BA35/BA24 | BB29: =M29 | BD29: =BD35/BD24 | BE29: =BE35/BE24 | BF29: =N29 | BH29: =BH35/BH24 | BI29: =BI35/BI24 | BJ29: =O29 | BL29: =BL35/BL24 | BM29: =BM35/BM24 | BN29: =P29 | BP29: =BP35/BP24 | BQ29: =BQ35/BQ24 | BR29: =Q29 | BT29: =BT35/BT24 | BU29: =BU35/BU24 | BV29: =R29 | BX29: =BX35/BX24 | BY29: =BY35/BY24 | BZ29: =S29 | CB29: =CB35/CB24 | CC29: =CC35/CC24 | CD29: =T29 | CF29: =CF35/CF24 | CG29: =CG35/CG24 | CH29: =U29 | CJ29: =CJ35/CJ24 | CK29: =CK35/CK24 | CL29: =V29 | CN29: =CN35/CN24 | CO29: =CO35/CO24 | CP29: =W29 | CR29: =CR35/CR24 | CS29: =CS35/CS24 | CT29: =CT35/CT24 | CU29: =X29 | CW29: =CW35/CW24 | CX29: =CX35/CX24 | CY29: =Y29 | DA29: =DA35/DA24 | DB29: =DB35/DB24 | DC29: =Z29 | DE29: =DE35/DE24 | DF29: =DF35/DF24 | DG29: =AA29 | DI29: =DI35/DI24 | DJ29: =DJ35/DJ24 | DK29: =AB29 | DM29: =DM35/DM24 | DN29: =DN35/DN24 | DO29: =AC29 | DQ29: =DQ35/DQ24 | DR29: =DR35/DR24 | DS29: =AD29 | DU29: =DU35/DU24 | DV29: =DV35/DV24 | DW29: =AE29 | DY29: =DY35/DY24 | DZ29: =DZ35/DZ24 | EA29: =AF29 | EC29: =EC35/EC24 | ED29: =ED35/ED24 | EE29: =AG29 | EG29: =EG35/EG24 | EH29: =EH35/EH24 | EI29: =AH29 | EK29: =EK35/EK24 | EL29: =EL35/EL24 | EM29: =AI29 | EO29: 0.555 | EP29: =EP35/EP24 | EQ29: =AJ29 | ES29: 0.945 | ET29: =ET35/ET24 | EU29: =AK29 | EW29: 1.143 | EX29: =EX35/EX24 | EY29: =AL29 | FA29: 0.774 | FB29: =FB35/FB24 | FC29: =AM29 | FE29: 0.689 | FF29: =FF35/FF24 | FG29: =AN29 | FI29: 0.604 | FJ29: =FJ35/FJ24 | FK29: =AO29 | FM29: 0.661 | FN29: =FJ29*(1+FN30) | FO29: =AP29
